Workbook
Name Scenario: Assumptions!$B$3

Sheet Cover
B3: WHOOP Inc.
A4: ARPU Simplification: Option B ($305 anchor) — bottom-up justified. See ARPU tab justification block. | B4: Private Company Valuation
B5: Investment Committee Memo — Supporting Model
B8: Company: | C8: WHOOP Inc.
B9: Ticker: | C9: Private (Pre-IPO)
B10: Last Round: | C10: Series G — $575M at $10.1B post-money (Mar 31, 2026)
B11: Model Date: | C11: April 16, 2026
B12: Analyst: | C12: Landon Brice
B13: Fiscal Year: | C13: Calendar Year (Jan-Dec)
B14: Currency: | C14: USD ($M unless noted)
B17: Valuation Methods:
B18: 1. Intrinsic DCF (scenario-based + real options)
B19: 2. Trading Comps (three-bucket framework)
B20: 3. Precedent Transactions
B21: 4. Last-Round Implied ($10.1B)
B22: 5. Implied IPO Trading Range (back-solved)
B25: Color Convention:
B26: Hard-coded input
B27: Formula / calculation
B28: Cross-sheet link
B29: Needs verification / FLAGGED_GAP
B32: Source Files:
B33: Valuation Summary (live, scenario-driven)
B34: Active Scenario | C34: =Assumptions!$B$3 -> Base
B36: Base DCF — Enterprise Value | C36: =DCF!C32 -> 7308.752
B37: + Cash | C37: =DCF!C37 -> 1008.2226
B38: − Debt | C38: =DCF!C36 -> -10
B39: = Equity Value | C39: =DCF!C38 -> 8306.9745
B40: Per Share (FD) | C40: =DCF!C40 -> 20.260914
B42: Real Options (Expected) | C42: =DCF!C46 -> 704.48043
B43: Total Equity + Options | C43: =DCF!C51 -> 9011.455
B45: Series G Mark | C45: =DCF!C52 -> 10100
B46: Base DCF vs Series G | C46: =DCF!C53 -> -0.17752727
B47: DCF + Options vs Series G | C47: =DCF!C54 -> -0.10777673
B48: Football Field (multi-method synthesis)
B49: Weighted Average EV | C49: ='Football Field'!D16*1000 -> 7306.5144
B50: Per Share (FD) | C50: ='Football Field'!G16 -> 19.503694
B51: vs Series G | C51: ='Football Field'!D18 -> -0.22353726
B53: Model Integrity (Checks tab)
B54: Passing | C54: =Checks!B17 -> 10
...

Sheet Assumptions
A1: WHOOP — Master Assumptions
A3: Scenario: | B3: Base | C3: Select Bear / Base / Bull — drives Active column F throughout the model. Other tabs reference Active values only.
A5: ID | B5: Assumption | C5: Bear | D5: Base | E5: Bull | F5: Active | G5: Tier | H5: Status | I5: Notes
A7: Section 1: Revenue & Growth
A8: R3a | B8: 2025 Beginning Members (M) | C8: 1.5 | D8: 1.3 | E8: 1.1 | F8: =IF($B$3="Bear",C8,IF($B$3="Bull",E8,D8)) -> 1.3 | G8: Tier 3 | H8: High | I8: Back-solved to reconcile avg×ARPU ≈ $650M base. Bear slower decel; bull faster acquisition.
A9: R3b | B9: 2025 Ending Members (M) | C9: 2.3 | D9: 2.5 | E9: 2.7 | F9: =IF($B$3="Bear",C9,IF($B$3="Bull",E9,D9)) -> 2.5 | G9: Tier 1 | H9: Critical | I9: Series G press release: 2.5M+ paying members
A10: R3 | B10: 2025 Average Members (M) — DERIVED | C10: =(C8+C9)/2 -> 1.9 | D10: =(D8+D9)/2 -> 1.9 | E10: =(E8+E9)/2 -> 1.9 | F10: =IF($B$3="Bear",C10,IF($B$3="Bull",E10,D10)) -> 1.9 | G10: Derived | H10: Critical | I10: Per methodology: ARPU applies to AVERAGE members during period, NOT year-end.
A11: R4 | B11: 2025 Blended ARPU ($/yr) | C11: 270 | D11: 305 | E11: 340 | F11: =IF($B$3="Bear",C11,IF($B$3="Bull",E11,D11)) -> 305 | G11: Tier 3 | H11: Critical | I11: Updated to Option B (bottom-up justified): consumer ~80% × $278 + Unite ~20% × $260 ≈ $274; with mature attach assumptions ≈ $307. Anchor 305 (Base). See ARPU tab justification block.
A12: R1 | B12: 2025 Recognized Revenue ($M) — DERIVED | C12: =C10*C11 -> 513 | D12: =D10*D11 -> 579.5 | E12: =E10*E11 -> 646 | F12: =IF($B$3="Bear",C12,IF($B$3="Bull",E12,D12)) -> 579.5 | G12: Derived | H12: Critical | I12: DERIVED: Avg Members × Blended ARPU. Target ~$650M base. Methodology consistency check: must reconcile within ±5%.
A13: R2 | B13: 2025 Bookings Run-Rate ($M) | C13: 1100 | D13: 1100 | E13: 1100 | F13: =IF($B$3="Bear",C13,IF($B$3="Bull",E13,D13)) -> 1100 | G13: Tier 1 | H13: Locked | I13: Series G press release; CEO statement (Dec 2025 exit rate × 12)
A14: R5 | B14: Subscription Revenue % | C14: 0.8 | D14: 0.85 | E14: 0.88 | F14: =IF($B$3="Bear",C14,IF($B$3="Bull",E14,D14)) -> 0.85 | G14: Tier 2 | H14: High | I14: Sacra/BMCT: ~80-88% range
A15: R6 | B15: 2025 YoY Subscription Growth | C15: 1.03 | D15: 1.03 | E15: 1.03 | F15: =IF($B$3="Bear",C15,IF($B$3="Bull",E15,D15)) -> 1.03 | G15: Tier 1 | H15: Locked | I15: Series G press release: 103%
A16: R7 | B16: Phase 1 Revenue Growth (2026-27) | C16: 0.5 | D16: 0.7 | E16: 0.9 | F16: =IF($B$3="Bear",C16,IF($B$3="Bull",E16,D16)) -> 0.7 | G16: Tier 3 | H16: Critical | I16: Peer trajectories; Series G deployment & WHOOP 5.0 cycle
A17: R8 | B17: Phase 2 Revenue Growth (2028-30) | C17: 0.15 | D17: 0.25 | E17: 0.4 | F17: =IF($B$3="Bear",C17,IF($B$3="Bull",E17,D17)) -> 0.25 | G17: Tier 3 | H17: Critical | I17: Deceleration shape: Dexcom (bull) / Netflix (base) / Peloton (bear)
A18: R9 | B18: Phase 3 Revenue Growth (2031-33) | C18: 0.05 | D18: 0.12 | E18: 0.2 | F18: =IF($B$3="Bear",C18,IF($B$3="Bull",E18,D18)) -> 0.12 | G18: Tier 3 | H18: High | I18: TAM ceiling; healthcare attach resolution
A19: R10a | B19: Year-1 Cohort Annual Churn | C19: 0.3 | D19: 0.22 | E19: 0.15 | F19: =IF($B$3="Bear",C19,IF($B$3="Bull",E19,D19)) -> 0.22 | G19: Tier 3 | H19: Critical | I19: Highest churn ("try and quit"). Will drive Members tab cohort engine.
A20: R10b | B20: Year-2 Cohort Annual Churn | C20: 0.18 | D20: 0.14 | E20: 0.1 | F20: =IF($B$3="Bear",C20,IF($B$3="Bull",E20,D20)) -> 0.14 | G20: Tier 3 | H20: Critical | I20: Stabilizing cohort
A21: R10c | B21: Year-3+ Cohort Annual Churn | C21: 0.12 | D21: 0.08 | E21: 0.05 | F21: =IF($B$3="Bear",C21,IF($B$3="Bull",E21,D21)) -> 0.08 | G21: Tier 3 | H21: Critical | I21: Retained core; very sticky power users
A22: R11
A23: R12 | B23: B2B Unite Revenue % | C23: 0.12 | D23: 0.18 | E23: 0.25 | F23: =IF($B$3="Bear",C23,IF($B$3="Bull",E23,D23)) -> 0.18 | G23: Tier 2 | H23: Medium | I23: Sacra/BMCT: ~20% recurring revenue; growing rapidly
A24: R14 | B24: Advanced Labs Attach Rate | C24: 0.03 | D24: 0.1 | E24: 0.25 | F24: =IF($B$3="Bear",C24,IF($B$3="Bull",E24,D24)) -> 0.1 | G24: Tier 3 | H24: Critical | I24: BUCKET-3 THESIS VARIABLE. Bear/Base/Bull per methodology Sec 3. Single most important ARPU assumption — swings $80/member.
A25: R15 | B25: Labs Avg Test Price ($) | C25: 250 | D25: 300 | E25: 350 | F25: =IF($B$3="Bear",C25,IF($B$3="Bull",E25,D25)) -> 300 | G25: Tier 3 | H25: High | I25: WHOOP Advanced Labs site: $199-$599. Methodology base: $300.
A26: R16 | B26: Annual Price Inflation | C26: 0.02 | D26: 0.03 | E26: 0.04 | F26: =IF($B$3="Bear",C26,IF($B$3="Bull",E26,D26)) -> 0.03 | G26: Tier 3 | H26: Medium | I26: CPI + premium brand pricing power
A27: R18 | B27: 2026 Gross Adds (M) | C27: 1.5 | D27: 1.9 | E27: 2.3 | F27: =IF($B$3="Bear",C27,IF($B$3="Bull",E27,D27)) -> 1.9 | G27: Tier 3 | H27: Critical | I27: Methodology priors: 1.8-2.0M base. Members tab will use this; per-year gross adds modeled there. CAC × this = S&M consistency check.
A28: R19 | B28: Deferred Revenue Adjustment (% of bookings) | C28: -0.1 | D28: -0.08 | E28: -0.05 | F28: =IF($B$3="Bear",C28,IF($B$3="Bull",E28,D28)) -> -0.08 | G28: Tier 3 | H28: Medium | I28: Drag during growth (recognized < booked); ASC 606. Approaches 0 at steady state.
A30: Section 2: Cost Structure & Margins
A31: C1 | B31: Hardware BOM per Device ($) | C31: 100 | D31: 80 | E31: 60 | F31: =IF($B$3="Bear",C31,IF($B$3="Bull",E31,D31)) -> 80 | G31: Tier 3 | H31: Critical | I31: Est. $50-80 at scale; 2016 BOM was $250-300 per Contrary Research
A32: C2 | B32: Loaded Hardware Cost per Acquisition ($) | C32: 150 | D32: 120 | E32: 90 | F32: =IF($B$3="Bear",C32,IF($B$3="Bull",E32,D32)) -> 120 | G32: Tier 3 | H32: Critical | I32: C1 + assembly, ship, warranty, returns. Drives unit economics.
A33: C4 | B33: Subscription Delivery Cost (% of sub rev) | C33: 0.15 | D33: 0.1 | E33: 0.08 | F33: =IF($B$3="Bear",C33,IF($B$3="Bull",E33,D33)) -> 0.1 | G33: Tier 3 | H33: High | I33: Infra + support; AWS/GCP benchmarks; declining at scale
A34: C5 | B34: Subscription Gross Margin (standalone) | C34: 0.72 | D34: 0.78 | E34: 0.83 | F34: =IF($B$3="Bear",C34,IF($B$3="Bull",E34,D34)) -> 0.78 | G34: Tier 3 | H34: Critical | I34: Peer: pure SaaS ~80%, Dexcom ~64% (incl consumables). WHOOP higher quality recurring.
A35: C6 | B35: Hardware Gross Margin (standalone) | C35: -0.1 | D35: -0.02 | E35: 0.05 | F35: =IF($B$3="Bear",C35,IF($B$3="Bull",E35,D35)) -> -0.02 | G35: Tier 3 | H35: Critical | I35: Subsidized at acquisition; Peloton HW GM trajectory: -18% to +14%
A36: C7a | B36: Blended GM Phase 1 (2026-27) | C36: 0.56 | D36: 0.6 | E36: 0.64 | F36: =IF($B$3="Bear",C36,IF($B$3="Bull",E36,D36)) -> 0.6 | G36: Tier 3 | H36: High | I36: Phase 1 blended GM (legacy decomposed framework, pre-collapse to C7d). No longer drives the model post-ARPU simplification — retained for reference only.
A37: C7b | B37: Blended GM Phase 2 (2028-30) | C37: 0.63 | D37: a | E37: 0.72 | F37: =IF($B$3="Bear",C37,IF($B$3="Bull",E37,D37)) -> a | G37: Tier 3 | H37: High | I37: Margin expansion as growth decelerates
A38: C7c | B38: Blended GM Terminal | C38: 0.72 | D38: 0.76 | E38: 0.8 | F38: =IF($B$3="Bear",C38,IF($B$3="Bull",E38,D38)) -> 0.76 | G38: Tier 3 | H38: High | I38: Peer terminal: Dexcom 60%, Spotify 32%; software-heavy mix at scale
A39: C8a | B39: R&D % of Revenue (current) | C39: 0.25 | D39: 0.22 | E39: 0.2 | F39: =IF($B$3="Bear",C39,IF($B$3="Bull",E39,D39)) -> 0.22 | G39: Tier 3 | H39: High | I39: Peers: Dexcom 13%, Garmin 16%, growth SaaS 20-30%
A40: C8b | B40: R&D % of Revenue (terminal) | C40: 0.12 | D40: 0.15 | E40: 0.18 | F40: =IF($B$3="Bear",C40,IF($B$3="Bull",E40,D40)) -> 0.15 | G40: Tier 3 | H40: Medium | I40: Peer steady-state
A41: C9 | B41: S&M % of Revenue (current) | C41: 0.35 | D41: 0.3 | E41: 0.25 | F41: =IF($B$3="Bear",C41,IF($B$3="Bull",E41,D41)) -> 0.3 | G41: Tier 3 | H41: Critical | I41: Peloton peak 28.4% FY22, current 16.9% FY25. Bear = stuck high.
A42: C9a | B42: Paid CAC per Gross Add ($) | C42: 220 | D42: 175 | E42: 130 | F42: =IF($B$3="Bear",C42,IF($B$3="Bull",E42,D42)) -> 175 | G42: Tier 3 | H42: Critical | I42: 30-50% of first-year ARPU. S&M consistency check on Checks tab.
A43: C9b | B43: Athlete/Brand Spend ($M/yr) | C43: 100 | D43: 60 | E43: 30 | F43: =IF($B$3="Bear",C43,IF($B$3="Bull",E43,D43)) -> 60 | G43: Tier 3 | H43: High | I43: Press, endorsement deals; non-paid S&M floor
A44: C9t | B44: S&M % of Revenue (terminal) | C44: 0.2 | D44: 0.17 | E44: 0.15 | F44: =IF($B$3="Bear",C44,IF($B$3="Bull",E44,D44)) -> 0.17 | G44: Tier 3 | H44: High | I44: Peer steady-state: Garmin SG&A 14-19%
...

Sheet Assumptions Audit
A1: Assumptions Tab — Cleanup Audit
A2: Cross-sheet reference scan of every Assumptions row. Categories: WIRED (used downstream), INTERNAL (consumed only by other Assumptions cells), ORPHAN (defined but unreferenced anywhere), ARCHIVED (deprecated section per A126 header). Action column = recommendation.
A4: Summary by section
A5: Section | B5: Total Rows | C5: Wired | D5: Internal Only | E5: Orphan | F5: Notes
A6: Sec 1: Revenue & Growth (rows 8-28) | B6: 19 | C6: 6 | D6: 3 | E6: 10 | F6: Wired: F8, F9, F11, F12, F19, F20, F21. Phase growth & churn rates not used by Members/Revenue Build.
A7: Sec 2: Cost Structure (rows 31-53) | B7: 21 | C7: 8 | D7: 0 | E7: 13 | F7: Wired: F32, F39, F40, F41, F45, F46, F47, F48, F52, F53. Tier-by-tier GM (C7a/b/c) replaced by collapsed C7d_start/end (rows 151-152).
A8: Sec 3: Cap Structure (rows 55-67) | B8: 12 | C8: 4 | D8: 0 | E8: 8 | F8: Wired: F55 (FD shares), F62 (debt), F63 (cash), F67 (cash yield). Cap table detail (LP, ratchets, founder %, DLOM) unused.
A9: Sec 4: WACC (rows 69-74) | B9: 6 | C9: 6 | D9: 0 | E9: 0 | F9: All wired. Sensitivity grids reference C/D/E directly for bottom-up build (intentional).
A10: Sec 5: Terminal Value (rows 77-81) | B10: 5 | C10: 2 | D10: 0 | E10: 3 | F10: Wired: F78 (exit mult), F80 (terminal growth). Method label, EV/EBITDA, multiple compression unused.
A11: Sec 6: Comp Bucket Weights (rows 84-87) | B11: 4 | C11: 4 | D11: 0 | E11: 0 | F11: All wired. Comps tab references C/D/E directly for thesis-anchored brackets (intentional).
A12: Sec 7: IPO Range (rows 90-94) | B12: 5 | C12: 1 | D12: 0 | E12: 4 | F12: Wired: only F94 / C94/D94/E94 (Stage 1 fair value). Timing, discount, IRR — defined but unused.
A13: Sec 8: Precedents (rows 97-102) | B13: 6 | C13: 0 | D13: 0 | E13: 6 | F13: ENTIRE SECTION ORPHAN. Precedents tab does not reference Assumptions.
A14: Sec 9: Real Options (rows 156-161) | B14: 6 | C14: 5 | D14: 1 | E14: 0 | F14: All wired. RealOptions tab references C/D/E directly (intentional, scenario-aligned).
A15: Sec 10: Gross Adds Drivers (rows 117-123) | B15: 5 | C15: 5 | D15: 0 | E15: 0 | F15: All wired. Members tab uses F117, F118, F121, F122, F123.
A16: Sec 11: ARCHIVED ARPU decomp (rows 130-149) | B16: 18 | C16: 0 | D16: 0 | E16: 18 | F16: ARCHIVED per header A126. Replaced by R4g/C7d_start/C7d_end (rows 150-152). DELETE CANDIDATES.
A17: Collapsed Drivers (rows 150-152) | B17: 3 | C17: 3 | D17: 0 | E17: 0 | F17: All wired. R4g (ARPU growth) → ARPU tab. C7d_start/end → P&L.
A18: TOTAL | B18: =SUM(B6:B17) -> 110 | C18: =SUM(C6:C17) -> 44 | D18: =SUM(D6:D17) -> 4 | E18: =SUM(E6:E17) -> 62 | F18: Total assumption rows / wired / internal / orphan + archived
A20: Detailed Orphan List — Delete Candidates
A21: Row | B21: ID | C21: Label | D21: Status | E21: Reason / Replacement | F21: Action
A22: 14 | B22: R5 | C22: Subscription Revenue % | D22: ORPHAN | E22: Members tab tracks subscribers directly; sub % not used. Revenue Build derives from members × ARPU. | F22: DELETE
A23: 15 | B23: R6 | C23: 2025 YoY Subscription Growth | D23: ORPHAN | E23: Not referenced. Growth flows from Members tab cohort math. | F23: DELETE
A24: 16 | B24: R7 | C24: Phase 1 Revenue Growth (2026-27) | D24: ORPHAN | E24: Phase growth replaced by bottom-up Members × ARPU build. R7-R9 are legacy top-down inputs. | F24: DELETE
A25: 17 | B25: R8 | C25: Phase 2 Revenue Growth (2028-30) | D25: ORPHAN | E25: Same — superseded by bottom-up build. | F25: DELETE
A26: 18 | B26: R9 | C26: Phase 3 Revenue Growth (2031-33) | D26: ORPHAN | E26: Same — superseded by bottom-up build. | F26: DELETE
A27: 23 | B27: R11 | C27: B2B Unite Revenue % | D27: ORPHAN | E27: B2B not separately modeled in current build. Revenue Build aggregates. | F27: DELETE
A28: 24 | B28: R12 | C28: Advanced Labs Attach Rate | D28: ORPHAN | E28: Sec 11 ARCHIVED equivalent (R25a, row 137) was wired but archived. | F28: DELETE
A29: 25 | B29: R14 | C29: Labs Avg Test Price | D29: ORPHAN | E29: Sec 11 archived. Labs not currently driving. | F29: DELETE
A30: 26 | B30: R15 | C30: Annual Price Inflation | D30: ORPHAN | E30: Replaced by R4g (row 150) Blended ARPU growth. | F30: DELETE
A31: 27 | B31: R16 | C31: 2026 Gross Adds (M) | D31: ORPHAN | E31: Members tab back-solves gross adds from S&M / CAC (Sec 10 drivers). | F31: DELETE
A33: 31 | B33: C1 | C33: Hardware BOM per Device | D33: ORPHAN | E33: Hardware GM not separately modeled — collapsed into blended C7d_start/end. | F33: DELETE
A34: 33 | B34: C4 | C34: Subscription Delivery Cost % | D34: ORPHAN | E34: Same — collapsed into blended COGS. | F34: DELETE
... A61: 93 | B61: I4 | C61: Investor Required IRR | D61: ORPHAN | E61: F94 derivation uses C92/D92/E92 (the discount factor row, not visible in extract). | F61: VERIFY F93 not used; likely DELETE
A63: 97-102 | B63: P1-Pb3 | C63: Sec 8 Precedents (entire section) | D63: ORPHAN | E63: Precedents tab built independently. None of these inputs flow through. | F63: DELETE entire section
A65: 130-149 | B65: R24a-R27c | C65: Sec 11 ARCHIVED ARPU decomp | D65: ARCHIVED | E65: Header A126 confirms archived. 18 rows of tier-mix / labs / accessories / BP-healthspan decomp — all replaced by R4g (row 150). | F65: DELETE entire section
A67: Recommendations & Cleanup Path
A68: 1. Safe Bulk Delete — Sec 11 ARCHIVED (rows 126-149)
A69: Drop the entire 'Section 11 (ARCHIVED)' block. Header A126 explicitly marks it deprecated. Replaced by R4g/C7d_start/C7d_end (rows 150-152) which ARE wired. Verified zero downstream references. Removes 24 rows of clutter.
A70: 2. Safe Bulk Delete — Sec 8 Precedents (rows 96-102)
A71: Entire section unreferenced. Precedents tab does not pull from Assumptions. If precedents analysis is parked for later, leave inputs on Precedents tab itself, not in master Assumptions.
A72: 3. Sec 1 + Sec 2 Cleanup — Legacy top-down inputs
...

Sheet Members
A1: WHOOP — Member Cohort Engine
A2: Members in millions; cohort engine drives revenue. 2025 beginning treated as Y3+ legacy block (simplification — see note).
B5: Units | C5: 2024 | D5: 2025 | E5: 2026 | F5: 2027 | G5: 2028 | H5: 2029 | I5: 2030 | J5: 2031 | K5: 2032 | L5: 2033
C6: Historical | D6: Historical | E6: Phase 1 | F6: Phase 1 | G6: Phase 2 | H6: Phase 2 | I6: Phase 2 | J6: Phase 3 | K6: Phase 3 | L6: Phase 3
A8: 1. Beginning Members (start of year)
A9: Beginning Members (total) | B9: M | C9: 0.7 | D9: =Assumptions!$F$8 -> 1.3 | E9: =D34 -> 2.5 | F9: =E34 -> 2.98669 | G9: =F34 -> 3.6873114 | H9: =G34 -> 4.4220311 | I9: =H34 -> 5.1901123 | J9: =I34 -> 5.9725117 | K9: =J34 -> 6.7474478 | L9: =K34 -> 7.4928859
A10: of which: Year-1 cohort | B10: M | C10: 0.5 | D10: 0 | E10: =D31 -> 1.304 | F10: =E31 -> 0.86925 | G10: =F31 -> 1.1222788 | H10: =G31 -> 1.2275045 | I10: =H31 -> 1.346217 | J10: =I31 -> 1.443526 | K10: =J31 -> 1.5178336 | L10: =K31 -> 1.5652877
A11: of which: Year-2 cohort | B11: M | C11: 0.15 | D11: 0 | E11: =D26 -> 0 | F11: =E26 -> 1.01712 | G11: =F26 -> 0.678015 | H11: =G26 -> 0.87537746 | I11: =H26 -> 0.95745351 | J11: =I26 -> 1.0500492 | K11: =J26 -> 1.1259503 | L11: =K26 -> 1.1839102
A12: of which: Year-3+ cohort | B12: M | C12: 0.05 | D12: =Assumptions!$F$8 -> 1.3 | E12: =D28 -> 1.196 | F12: =E28 -> 1.10032 | G12: =F28 -> 1.8870176 | H12: =G28 -> 2.3191491 | I12: =H28 -> 2.8864418 | J12: =I28 -> 3.4789365 | K12: =J28 -> 4.1036639 | L12: =K28 -> 4.743688
A14: 2. Churn Rates (cohort-aged, from Assumptions)
A15: Year-1 churn rate | B15: % | C15: =Assumptions!$F$19 -> 0.22 | D15: =Assumptions!$F$19 -> 0.22 | E15: =Assumptions!$F$19 -> 0.22 | F15: =Assumptions!$F$19 -> 0.22 | G15: =Assumptions!$F$19 -> 0.22 | H15: =Assumptions!$F$19 -> 0.22 | I15: =Assumptions!$F$19 -> 0.22 | J15: =Assumptions!$F$19 -> 0.22 | ... L15: =Assumptions!$F$19 -> 0.22
A16: Year-2 churn rate | B16: % | C16: =Assumptions!$F$20 -> 0.14 | D16: =Assumptions!$F$20 -> 0.14 | E16: =Assumptions!$F$20 -> 0.14 | F16: =Assumptions!$F$20 -> 0.14 | G16: =Assumptions!$F$20 -> 0.14 | H16: =Assumptions!$F$20 -> 0.14 | I16: =Assumptions!$F$20 -> 0.14 | J16: =Assumptions!$F$20 -> 0.14 | ... L16: =Assumptions!$F$20 -> 0.14
A17: Year-3+ churn rate | B17: % | C17: =Assumptions!$F$21 -> 0.08 | D17: =Assumptions!$F$21 -> 0.08 | E17: =Assumptions!$F$21 -> 0.08 | F17: =Assumptions!$F$21 -> 0.08 | G17: =Assumptions!$F$21 -> 0.08 | H17: =Assumptions!$F$21 -> 0.08 | I17: =Assumptions!$F$21 -> 0.08 | J17: =Assumptions!$F$21 -> 0.08 | ... L17: =Assumptions!$F$21 -> 0.08
A19: 3. Churned Members
A20: Y1 churned | B20: M | C20: =C10*C15 -> 0.11 | D20: =D10*D15 -> 0 | E20: =E10*E15 -> 0.28688 | F20: =F10*F15 -> 0.191235 | G20: =G10*G15 -> 0.24690133 | H20: =H10*H15 -> 0.27005099 | I20: =I10*I15 -> 0.29616773 | J20: =J10*J15 -> 0.31757572 | ... L20: =L10*L15 -> 0.34436329
A21: Y2 churned | B21: M | C21: =C11*C16 -> 0.021 | D21: =D11*D16 -> 0 | E21: =E11*E16 -> 0 | F21: =F11*F16 -> 0.1423968 | G21: =G11*G16 -> 0.0949221 | H21: =H11*H16 -> 0.12255284 | I21: =I11*I16 -> 0.13404349 | J21: =J11*J16 -> 0.14700689 | ... L21: =L11*L16 -> 0.16574743
A22: Y3+ churned | B22: M | C22: =C12*C17 -> 0.004 | D22: =D12*D17 -> 0.104 | E22: =E12*E17 -> 0.09568 | F22: =F12*F17 -> 0.0880256 | G22: =G12*G17 -> 0.15096141 | H22: =H12*H17 -> 0.18553193 | I22: =I12*I17 -> 0.23091534 | J22: =J12*J17 -> 0.27831492 | ... L22: =L12*L17 -> 0.37949504
A23: Total churned | B23: M | C23: =SUM(C20:C22) -> 0.135 | D23: =SUM(D20:D22) -> 0.104 | E23: =SUM(E20:E22) -> 0.38256 | F23: =SUM(F20:F22) -> 0.4216574 | G23: =SUM(G20:G22) -> 0.49278484 | H23: =SUM(H20:H22) -> 0.57813576 | I23: =SUM(I20:I22) -> 0.66112657 | J23: =SUM(J20:J22) -> 0.74289753 | ... L23: =SUM(L20:L22) -> 0.88960576
A25: 4. Surviving Members (end of year, before new adds)
A26: Y1 survivors | B26: M | C26: =C10-C20 -> 0.39 | D26: =D10-D20 -> 0 | E26: =E10-E20 -> 1.01712 | F26: =F10-F20 -> 0.678015 | G26: =G10-G20 -> 0.87537746 | H26: =H10-H20 -> 0.95745351 | I26: =I10-I20 -> 1.0500492 | J26: =J10-J20 -> 1.1259503 | ... L26: =L10-L20 -> 1.2209244
A27: Y2 survivors | B27: M | C27: =C11-C21 -> 0.129 | D27: =D11-D21 -> 0 | E27: =E11-E21 -> 0 | F27: =F11-F21 -> 0.8747232 | G27: =G11-G21 -> 0.5830929 | H27: =H11-H21 -> 0.75282461 | I27: =I11-I21 -> 0.82341002 | J27: =J11-J21 -> 0.90304235 | ... L27: =L11-L21 -> 1.0181628
A28: Y3+ end state (incl. Y2 graduates) | B28: M | C28: =C12-C22+C27 -> 0.175 | D28: =D12-D22+D27 -> 1.196 | E28: =E12-E22+E27 -> 1.10032 | F28: =F12-F22+F27 -> 1.8870176 | G28: =G12-G22+G27 -> 2.3191491 | H28: =H12-H22+H27 -> 2.8864418 | I28: =I12-I22+I27 -> 3.4789365 | J28: =J12-J22+J27 -> 4.1036639 | ... L28: =L12-L22+L27 -> 5.3823558
A30: 5. New Members (Gross Adds — input per year)
A31: Gross Adds | B31: M | C31: 0.6 | D31: =Assumptions!$F$9-D28 -> 1.304 | E31: =E51 -> 0.86925 | F31: =F51 -> 1.1222788 | G31: =G51 -> 1.2275045 | H31: =H51 -> 1.346217 | I31: =I51 -> 1.443526 | J31: =J51 -> 1.5178336 | K31: =K51 -> 1.5652877 | L31: =L51 -> 1.5830071
A33: 6. Ending & Average Members
A34: Ending Members | B34: M | C34: =C26+C28+C31 -> 1.165 | D34: =D26+D28+D31 -> 2.5 | E34: =E26+E28+E31 -> 2.98669 | F34: =F26+F28+F31 -> 3.6873114 | G34: =G26+G28+G31 -> 4.4220311 | H34: =H26+H28+H31 -> 5.1901123 | I34: =I26+I28+I31 -> 5.9725117 | J34: =J26+J28+J31 -> 6.7474478 | ... L34: =L26+L28+L31 -> 8.1862873
A35: Average Members | B35: M | C35: =(C9+C34)/2 -> 0.9325 | D35: =(D9+D34)/2 -> 1.9 | E35: =(E9+E34)/2 -> 2.743345 | F35: =(F9+F34)/2 -> 3.3370007 | G35: =(G9+G34)/2 -> 4.0546712 | H35: =(H9+H34)/2 -> 4.8060717 | I35: =(I9+I34)/2 -> 5.581312 | J35: =(J9+J34)/2 -> 6.3599798 | ... L35: =(L9+L34)/2 -> 7.8395866
A37: 7. Diagnostics (output, not input)
A38: Net Adds (Gross - Churned) | B38: M | C38: =C31-C23 -> 0.465 | D38: =D31-D23 -> 1.2 | E38: =E31-E23 -> 0.48669 | F38: =F31-F23 -> 0.70062139 | G38: =G31-G23 -> 0.73471966 | H38: =H31-H23 -> 0.76808121 | I38: =I31-I23 -> 0.78239945 | J38: =J31-J23 -> 0.77493607 | ... L38: =L31-L23 -> 0.69340135
A39: Net Member Growth % | B39: % | D39: =D34/C34-1 -> 1.1459227 | E39: =E34/D34-1 -> 0.194676 | F39: =F34/E34-1 -> 0.23458122 | G39: =G34/F34-1 -> 0.1992562 | H39: =H34/G34-1 -> 0.17369422 | I39: =I34/H34-1 -> 0.15074808 | J39: =J34/I34-1 -> 0.12975045 | K39: =K34/J34-1 -> 0.11047705 | L39: =L34/K34-1 -> 0.092541293
A40: Blended Annual Churn Rate (output) | B40: % | C40: =IFERROR(C23/C9,0) -> 0.19285714 | D40: =IFERROR(D23/D9,0) -> 0.08 | E40: =IFERROR(E23/E9,0) -> 0.153024 | F40: =IFERROR(F23/F9,0) -> 0.14117883 | G40: =IFERROR(G23/G9,0) -> 0.1336434 | H40: =IFERROR(H23/H9,0) -> 0.13073987 | I40: =IFERROR(I23/I9,0) -> 0.12738194 | J40: =IFERROR(J23/J9,0) -> 0.12438612 | ... L40: =IFERROR(L23/L9,0) -> 0.11872672
A41: 2025 ending vs Assumptions R3b (consistency) | B41: % | D41: =D34/Assumptions!$F$9-1 -> 0
A43: NOTE: 2025 beginning is treated as Y3+ legacy block (simplification). Replace with audited cohort splits when S-1 data is available. 2024 column is historical reference; engine fully runs 2025 onwards.
A45: 8. Gross Adds Build (DERIVED — S&M / CAC, with TAM diagnostic)
A46: Phase # (DEPRECATED — replaced by linear interpolation) | B46: # | C46: Hist | D46: Hist
A47: S&M Budget ($M = prior-yr rev × interpolated S&M%) | B47: $M | D47: 195 | E47: ='Revenue Build'!D20*(Assumptions!$F$117 + (Assumptions!$F$118-Assumptions!$F$117)*(E$5-2026)/7) -> 173.85 | F47: ='Revenue Build'!E20*(Assumptions!$F$117 + (Assumptions!$F$118-Assumptions!$F$117)*(F$5-2026)/7) -> 247.38231 | G47: ='Revenue Build'!F20*(Assumptions!$F$117 + (Assumptions!$F$118-Assumptions!$F$117)*(G$5-2026)/7) -> 295.65323 | H47: ='Revenue Build'!G20*(Assumptions!$F$117 + (Assumptions!$F$118-Assumptions!$F$117)*(H$5-2026)/7) -> 351.74726 | I47: ='Revenue Build'!H20*(Assumptions!$F$117 + (Assumptions!$F$118-Assumptions!$F$117)*(I$5-2026)/7) -> 406.6619 | J47: ='Revenue Build'!I20*(Assumptions!$F$117 + (Assumptions!$F$118-Assumptions!$F$117)*(J$5-2026)/7) -> 458.60258 | K47: ='Revenue Build'!J20*(Assumptions!$F$117 + (Assumptions!$F$118-Assumptions!$F$117)*(K$5-2026)/7) -> 504.91708 | L47: ='Revenue Build'!K20*(Assumptions!$F$117 + (Assumptions!$F$118-Assumptions!$F$117)*(L$5-2026)/7) -> 542.97144
A48: Blended CAC ($, linearly interpolated F121→F122) | B48: $ | D48: 130 | E48: =Assumptions!$F$121 + (Assumptions!$F$122-Assumptions!$F$121)*(E$5-2026)/7 -> 200 | F48: =Assumptions!$F$121 + (Assumptions!$F$122-Assumptions!$F$121)*(F$5-2026)/7 -> 220.42857 | G48: =Assumptions!$F$121 + (Assumptions!$F$122-Assumptions!$F$121)*(G$5-2026)/7 -> 240.85714 | H48: =Assumptions!$F$121 + (Assumptions!$F$122-Assumptions!$F$121)*(H$5-2026)/7 -> 261.28571 | I48: =Assumptions!$F$121 + (Assumptions!$F$122-Assumptions!$F$121)*(I$5-2026)/7 -> 281.71429 | J48: =Assumptions!$F$121 + (Assumptions!$F$122-Assumptions!$F$121)*(J$5-2026)/7 -> 302.14286 | K48: =Assumptions!$F$121 + (Assumptions!$F$122-Assumptions!$F$121)*(K$5-2026)/7 -> 322.57143 | L48: =Assumptions!$F$121 + (Assumptions!$F$122-Assumptions!$F$121)*(L$5-2026)/7 -> 343
A49: Unconstrained Gross Adds (M) = S&M / CAC | B49: M | D49: =D47/D48 -> 1.5 | E49: =E47/E48 -> 0.86925 | F49: =F47/F48 -> 1.1222788 | G49: =G47/G48 -> 1.2275045 | H49: =H47/H48 -> 1.346217 | I49: =I47/I48 -> 1.443526 | J49: =J47/J48 -> 1.5178336 | K49: =K47/K48 -> 1.5652877 | L49: =L47/L48 -> 1.5830071
A50: TAM Penetration % (diagnostic — flag if >40%) | B50: % | D50: n/a | E50: =D34/Assumptions!$F$123 -> 0.1 | F50: =E34/Assumptions!$F$123 -> 0.1194676 | G50: =F34/Assumptions!$F$123 -> 0.14749246 | H50: =G34/Assumptions!$F$123 -> 0.17688124 | I50: =H34/Assumptions!$F$123 -> 0.20760449 | J50: =I34/Assumptions!$F$123 -> 0.23890047 | K50: =J34/Assumptions!$F$123 -> 0.26989791 | L50: =K34/Assumptions!$F$123 -> 0.29971544
A51: Final Gross Adds (M) | B51: M | D51: =D49 -> 1.5 | E51: =E49 -> 0.86925 | F51: =F49 -> 1.1222788 | G51: =G49 -> 1.2275045 | H51: =H49 -> 1.346217 | I51: =I49 -> 1.443526 | J51: =J49 -> 1.5178336 | K51: =K49 -> 1.5652877 | L51: =L49 -> 1.5830071

Sheet ARPU
A1: ARPU — Single-Line Blended Driver (collapsed from 5-component build)
A2: Active driver: Assumptions R4 (anchor) compounded by R4g (annual growth). Bottom-up justification preserved as memo block below — does not feed model. Consistency check at row 38 verifies Members × ARPU ≈ Methodology rev anchor.
A5: Year | B5: Unit | C5: 2024 | D5: 2025 | E5: 2026 | F5: 2027 | G5: 2028 | H5: 2029 | I5: 2030 | J5: 2031 | K5: 2032 | L5: 2033
A7: Blended ARPU (driver)
A8: 2025 Anchor (Assumptions R4) | B8: $/yr | D8: =Assumptions!$F$11 -> 305
A9: Annual growth rate (Assumptions R4g) | B9: % | D9: =Assumptions!$F$150 -> 0.04
A10: Blended ARPU | B10: $/yr | C10: 0 | D10: =D8 -> 305 | E10: =D10*(1+$D$9) -> 317.2 | F10: =E10*(1+$D$9) -> 329.888 | G10: =F10*(1+$D$9) -> 343.08352 | H10: =G10*(1+$D$9) -> 356.80686 | I10: =H10*(1+$D$9) -> 371.07914 | J10: =I10*(1+$D$9) -> 385.9223 | K10: =J10*(1+$D$9) -> 401.35919 | L10: =K10*(1+$D$9) -> 417.41356
A13: ARPU Justification (memo — does not drive model)
A14: Bottom-up reconciliation showing how blended ARPU reflects consumer + B2B mix. Numbers below are reference; active driver is Section 1 R4 above.
A16: Consumer per-member ARPU components:
A17: Subscription tier-weighted average | B17: $/yr | D17: 258 | E17: Tier mix 30/45/25 × $199/$239/$359 = $257; +$1.68 monthly premium
A18: Labs ARPU at maturity (10% attach × $250 × 1.5 tests) | B18: $/yr | D18: 38
A19: Accessories ARPU | B19: $/yr | D19: 18
A20: BP/Healthspan ARPU at 5% attach (post-launch) | B20: $/yr | D20: 5
A21: Consumer ARPU (mature, 2026+) | B21: $/yr | D21: =SUM(D17:D20) -> 319
A22: Consumer ARPU (2025, partial Labs only) | B22: $/yr | D22: 278
A24: B2B Unite per-seat:
A25: Per-seat employer-rate ARPU | B25: $/yr | D25: 260 | E25: B2B health platforms with bundled hardware: $200-350; standalone software: $100-180. Estimate $260 mid-range.
A27: Mix assumption (% of paying members):
A28: Consumer share | B28: % | D28: 0.8 | E28: BMCT estimate: Unite ~20% of recurring revenue
A29: Unite share | B29: % | D29: 0.2
A30: Mix sum check | D30: =D28+D29 -> 1 | E30: Must = 100%
A32: Implied blended ARPU 2025 (memo): | D32: =D28*D22 + D29*D25 -> 274.4
A33: Implied blended ARPU 2026 mature (memo): | D33: =D28*D21 + D29*D25 -> 307.2
A34: Anchor used in driver (R4) | D34: =Assumptions!$F$11 -> 305
A35: Variance vs implied (mature) | D35: =(D34-D33)/D33 -> -0.0071614583
A36: Status | D36: =IF(ABS(D35)<=0.1,"✓ within ±10% of justification","⚠ anchor diverges from justification — review") -> ✓ within ±10% of justification
A38: Consistency Check: Members × ARPU = Revenue
A39: 2025 Avg Members × Blended ARPU | B39: $M | D39: =Members!D35*D10 -> 579.5
A40: Methodology revenue prior (Assumptions R1 / F12) | B40: $M | D40: =Assumptions!$F$12 -> 579.5
A41: Variance | D41: =(D39-D40)/D40 -> 0
A42: Status | D42: =IF(ABS(D41)<=0.05,"✓ within ±5%","⚠ outside ±5% — reconcile") -> ✓ within ±5%

Sheet Revenue Build
A1: WHOOP — Revenue Build-Up
A2: $M unless noted; Calendar Year
B5: Units | C5: 2024 | D5: 2025 | E5: 2026 | F5: 2027 | G5: 2028 | H5: 2029 | I5: 2030 | J5: 2031 | K5: 2032 | L5: 2033
C6: Historical | D6: Historical | E6: Phase 1 | F6: Phase 1 | G6: Phase 2 | H6: Phase 2 | I6: Phase 2 | J6: Phase 3 | K6: Phase 3 | L6: Phase 3
A8: 1. Member Economics (linked from Members tab)
A9: Beginning Members | B9: M | C9: =Members!C9 -> 0.7 | D9: =Members!D9 -> 1.3 | E9: =Members!E9 -> 2.5 | F9: =Members!F9 -> 2.98669 | G9: =Members!G9 -> 3.6873114 | H9: =Members!H9 -> 4.4220311 | I9: =Members!I9 -> 5.1901123 | J9: =Members!J9 -> 5.9725117 | ... L9: =Members!L9 -> 7.4928859
A10: Gross Adds | B10: M | C10: =Members!C31 -> 0.6 | D10: =Members!D31 -> 1.304 | E10: =Members!E31 -> 0.86925 | F10: =Members!F31 -> 1.1222788 | G10: =Members!G31 -> 1.2275045 | H10: =Members!H31 -> 1.346217 | I10: =Members!I31 -> 1.443526 | J10: =Members!J31 -> 1.5178336 | ... L10: =Members!L31 -> 1.5830071
A11: Churned Members | B11: M | C11: =Members!C23 -> 0.135 | D11: =Members!D23 -> 0.104 | E11: =Members!E23 -> 0.38256 | F11: =Members!F23 -> 0.4216574 | G11: =Members!G23 -> 0.49278484 | H11: =Members!H23 -> 0.57813576 | I11: =Members!I23 -> 0.66112657 | J11: =Members!J23 -> 0.74289753 | ... L11: =Members!L23 -> 0.88960576
A12: Ending Members | B12: M | C12: =Members!C34 -> 1.165 | D12: =Members!D34 -> 2.5 | E12: =Members!E34 -> 2.98669 | F12: =Members!F34 -> 3.6873114 | G12: =Members!G34 -> 4.4220311 | H12: =Members!H34 -> 5.1901123 | I12: =Members!I34 -> 5.9725117 | J12: =Members!J34 -> 6.7474478 | ... L12: =Members!L34 -> 8.1862873
A13: Avg Members | B13: M | C13: =Members!C35 -> 0.9325 | D13: =Members!D35 -> 1.9 | E13: =Members!E35 -> 2.743345 | F13: =Members!F35 -> 3.3370007 | G13: =Members!G35 -> 4.0546712 | H13: =Members!H35 -> 4.8060717 | I13: =Members!I35 -> 5.581312 | J13: =Members!J35 -> 6.3599798 | ... L13: =Members!L35 -> 7.8395866
A14: Blended Annual Churn (output) | B14: % | C14: =IFERROR(Members!C23/Members!C9, 0) -> 0.19285714 | D14: =IFERROR(Members!D23/Members!D9, 0) -> 0.08 | E14: =IFERROR(Members!E23/Members!E9, 0) -> 0.153024 | F14: =IFERROR(Members!F23/Members!F9, 0) -> 0.14117883 | G14: =IFERROR(Members!G23/Members!G9, 0) -> 0.1336434 | H14: =IFERROR(Members!H23/Members!H9, 0) -> 0.13073987 | I14: =IFERROR(Members!I23/Members!I9, 0) -> 0.12738194 | J14: =IFERROR(Members!J23/Members!J9, 0) -> 0.12438612 | ... L14: =IFERROR(Members!L23/Members!L9, 0) -> 0.11872672
A16: 2. ARPU (linked from ARPU tab)
A17: Blended ARPU | B17: $/yr | C17: =ARPU!C10 -> 0 | D17: =ARPU!D10 -> 305 | E17: =ARPU!E10 -> 317.2 | F17: =ARPU!F10 -> 329.888 | G17: =ARPU!G10 -> 343.08352 | H17: =ARPU!H10 -> 356.80686 | I17: =ARPU!I10 -> 371.07914 | J17: =ARPU!J10 -> 385.9223 | ... L17: =ARPU!L10 -> 417.41356
A19: 3. Revenue Build
A20: Recognized Revenue (Total) | B20: $M | C20: =C13*C17 -> 0 | D20: =D13*D17 -> 579.5 | E20: =E13*E17 -> 870.18903 | F20: =F13*F17 -> 1100.8365 | G20: =G13*G17 -> 1391.0909 | H20: =H13*H17 -> 1714.8393 | I20: =I13*I17 -> 2071.1084 | J20: =J13*J17 -> 2454.458 | ... L20: =L13*L17 -> 3272.3497
A21: Memo: Δ Deferred Rev Balance (flows to NWC, not P&L) | B21: $M | C21: =C20*Assumptions!$F$28 -> 0 | D21: =D20*Assumptions!$F$28 -> -46.36 | E21: =E20*Assumptions!$F$28 -> -69.615123 | F21: =F20*Assumptions!$F$28 -> -88.066919 | G21: =G20*Assumptions!$F$28 -> -111.28727 | H21: =H20*Assumptions!$F$28 -> -137.18715 | I21: =I20*Assumptions!$F$28 -> -165.68867 | J21: =J20*Assumptions!$F$28 -> -196.35664 | ... L21: =L20*Assumptions!$F$28 -> -261.78798
A22: YoY Revenue Growth | B22: % | D22: =IFERROR(D20/C20-1,0) -> 0 | E22: =E20/D20-1 -> 0.50162042 | F22: =F20/E20-1 -> 0.26505442 | G22: =G20/F20-1 -> 0.26366712 | H22: =H20/G20-1 -> 0.23272992 | I22: =I20/H20-1 -> 0.20775654 | J22: =J20/I20-1 -> 0.18509393 | K22: =K20/J20-1 -> 0.16430772 | L22: =L20/K20-1 -> 0.14508132
A24: 4. Bookings Reconciliation
A25: Implied Bookings (End × ARPU) | B25: $M | C25: =C12*C17 -> 0 | D25: =D12*D17 -> 762.5 | E25: =E12*E17 -> 947.37807 | F25: =F12*F17 -> 1216.3998 | G25: =G12*G17 -> 1517.126 | H25: =H12*H17 -> 1851.8677 | I25: =I12*I17 -> 2216.2745 | J25: =J12*J17 -> 2603.9906 | ... L25: =L12*L17 -> 3417.0673
A26: Bookings/Revenue Ratio | B26: x | C26: =IFERROR(C25/C20, 0) -> 0 | D26: =IFERROR(D25/D20, 0) -> 1.3157895 | E26: =IFERROR(E25/E20, 0) -> 1.0887038 | F26: =IFERROR(F25/F20, 0) -> 1.1049777 | G26: =IFERROR(G25/G20, 0) -> 1.0906016 | H26: =IFERROR(H25/H20, 0) -> 1.0799074 | I26: =IFERROR(I25/I20, 0) -> 1.070091 | J26: =IFERROR(J25/J20, 0) -> 1.0609228 | ... L26: =IFERROR(L25/L20, 0) -> 1.0442244
A27: 2025 Recognized vs Assumptions R1 (consistency) | B27: % | D27: =D20/Assumptions!$F$12-1 -> 0

Sheet P&L
A1: WHOOP — Projected Income Statement
A2: $M; Calendar Year; Scenario per Assumptions toggle
A3: Calibration items: see notes on F31 (2027 dip), L23 (S&M architecture). Margin tapers and NOL wired; refer to CalibrationLog for status.
B5: Units | C5: 2024 | D5: 2025 | E5: 2026 | F5: 2027 | G5: 2028 | H5: 2029 | I5: 2030 | J5: 2031 | K5: 2032 | L5: 2033
A7: Revenue
A8: Total Revenue | B8: $M | C8: ='Revenue Build'!C20 -> 0 | D8: ='Revenue Build'!D20 -> 579.5 | E8: ='Revenue Build'!E20 -> 870.18903 | F8: ='Revenue Build'!F20 -> 1100.8365 | G8: ='Revenue Build'!G20 -> 1391.0909 | H8: ='Revenue Build'!H20 -> 1714.8393 | I8: ='Revenue Build'!I20 -> 2071.1084 | J8: ='Revenue Build'!J20 -> 2454.458 | ... L8: ='Revenue Build'!L20 -> 3272.3497 | M8: ← From Revenue Build tab
A9: YoY Growth | B9: % | D9: =IFERROR(D8/C8-1,0) -> 0 | E9: =E8/D8-1 -> 0.50162042 | F9: =F8/E8-1 -> 0.26505442 | G9: =G8/F8-1 -> 0.26366712 | H9: =H8/G8-1 -> 0.23272992 | I9: =I8/H8-1 -> 0.20775654 | J9: =J8/I8-1 -> 0.18509393 | K9: =K8/J8-1 -> 0.16430772 | L9: =L8/K8-1 -> 0.14508132
A11: Cost of Revenue
A12: Total COGS (Blended COGS% × Revenue, linearly interpolated) | B12: $M | D12: =D8*0.4 -> 231.8 | E12: =E8*(Assumptions!$F$151 + (Assumptions!$F$152-Assumptions!$F$151)*(E$5-2026)/7) -> 217.54726 | F12: =F8*(Assumptions!$F$151 + (Assumptions!$F$152-Assumptions!$F$151)*(F$5-2026)/7) -> 267.346 | G12: =G8*(Assumptions!$F$151 + (Assumptions!$F$152-Assumptions!$F$151)*(G$5-2026)/7) -> 327.89999 | H12: =H8*(Assumptions!$F$151 + (Assumptions!$F$152-Assumptions!$F$151)*(H$5-2026)/7) -> 391.96328 | I12: =I8*(Assumptions!$F$151 + (Assumptions!$F$152-Assumptions!$F$151)*(I$5-2026)/7) -> 458.60258 | J12: =J8*(Assumptions!$F$151 + (Assumptions!$F$152-Assumptions!$F$151)*(J$5-2026)/7) -> 525.95529 | K12: =K8*(Assumptions!$F$151 + (Assumptions!$F$152-Assumptions!$F$151)*(K$5-2026)/7) -> 591.96134 | L12: =L8*(Assumptions!$F$151 + (Assumptions!$F$152-Assumptions!$F$151)*(L$5-2026)/7) -> 654.46995
A13: Hardware COGS (MEMO ONLY — embedded in blended COGS%; used for WC inventory only) | B13: $M | D13: =Members!D31 * Assumptions!$F$32 -> 156.48 | E13: =Members!E31 * Assumptions!$F$32 -> 104.31 | F13: =Members!F31 * Assumptions!$F$32 -> 134.67346 | G13: =Members!G31 * Assumptions!$F$32 -> 147.30054 | H13: =Members!H31 * Assumptions!$F$32 -> 161.54604 | I13: =Members!I31 * Assumptions!$F$32 -> 173.22312 | J13: =Members!J31 * Assumptions!$F$32 -> 182.14003 | K13: =Members!K31 * Assumptions!$F$32 -> 187.83452 | L13: =Members!L31 * Assumptions!$F$32 -> 189.96085
A14: Total COGS (= row 12) | B14: $M | D14: =D12 -> 231.8 | E14: =E12 -> 217.54726 | F14: =F12 -> 267.346 | G14: =G12 -> 327.89999 | H14: =H12 -> 391.96328 | I14: =I12 -> 458.60258 | J14: =J12 -> 525.95529 | K14: =K12 -> 591.96134 | L14: =L12 -> 654.46995
A15: Gross Profit | B15: $M | D15: =D8-D12 -> 347.7 | E15: =E8-E12 -> 652.64178 | F15: =F8-F12 -> 833.49048 | G15: =G8-G12 -> 1063.1909 | H15: =H8-H12 -> 1322.8761 | I15: =I8-I12 -> 1612.5058 | J15: =J8-J12 -> 1928.5027 | K15: =K8-K12 -> 2265.7831 | L15: =L8-L12 -> 2617.8798
A16: Gross Margin | B16: % | D16: =D15/D8 -> 0.6 | E16: =E15/E8 -> 0.75 | F16: =F15/F8 -> 0.75714286 | G16: =G15/G8 -> 0.76428571 | H16: =H15/H8 -> 0.77142857 | I16: =I15/I8 -> 0.77857143 | J16: =J15/J8 -> 0.78571429 | K16: =K15/K8 -> 0.79285714 | L16: =L15/L8 -> 0.8
A20: Operating Expenses
A21: R&D | B21: $M | D21: =D8*Assumptions!$F$39 -> 127.49 | E21: =E8*(Assumptions!$F$39 + (Assumptions!$F$40-Assumptions!$F$39)*(E$5-2026)/7) -> 191.44159 | F21: =F8*(Assumptions!$F$39 + (Assumptions!$F$40-Assumptions!$F$39)*(F$5-2026)/7) -> 231.17566 | G21: =G8*(Assumptions!$F$39 + (Assumptions!$F$40-Assumptions!$F$39)*(G$5-2026)/7) -> 278.21818 | H21: =H8*(Assumptions!$F$39 + (Assumptions!$F$40-Assumptions!$F$39)*(H$5-2026)/7) -> 325.81948 | I21: =I8*(Assumptions!$F$39 + (Assumptions!$F$40-Assumptions!$F$39)*(I$5-2026)/7) -> 372.79952 | J21: =J8*(Assumptions!$F$39 + (Assumptions!$F$40-Assumptions!$F$39)*(J$5-2026)/7) -> 417.25786 | K21: =K8*(Assumptions!$F$39 + (Assumptions!$F$40-Assumptions!$F$39)*(K$5-2026)/7) -> 457.23911 | L21: =L8*(Assumptions!$F$39 + (Assumptions!$F$40-Assumptions!$F$39)*(L$5-2026)/7) -> 490.85246
A22: R&D % Revenue | B22: % | D22: =D21/D8 -> 0.22 | E22: =E21/E8 -> 0.22 | F22: =F21/F8 -> 0.21 | G22: =G21/G8 -> 0.2 | H22: =H21/H8 -> 0.19 | I22: =I21/I8 -> 0.18 | J22: =J21/J8 -> 0.17 | K22: =K21/K8 -> 0.16 | L22: =L21/L8 -> 0.15 | M22: ← From Assumptions F39/F40 (R&D phase % linearly interpolated)
A23: Sales & Marketing | B23: $M | D23: =D8*Assumptions!$F$41 -> 173.85 | E23: =Members!E47 -> 173.85 | F23: =Members!F47 -> 247.38231 | G23: =Members!G47 -> 295.65323 | H23: =Members!H47 -> 351.74726 | I23: =Members!I47 -> 406.6619 | J23: =Members!J47 -> 458.60258 | K23: =Members!K47 -> 504.91708 | L23: =Members!L47 -> 542.97144
A24: S&M % Revenue | B24: % | D24: =D23/D8 -> 0.3 | E24: =E23/E8 -> 0.19978418 | F24: =F23/F8 -> 0.22472212 | G24: =G23/G8 -> 0.21253337 | H24: =H23/H8 -> 0.20511966 | I24: =I23/I8 -> 0.19634988 | J24: =J23/J8 -> 0.18684474 | K24: =K23/K8 -> 0.17668378 | L24: =L23/L8 -> 0.16592708 | M24: ← From Members tab S&M build (= prior-yr revenue × GA1/GA2 endpoint)
A25: General & Administrative | B25: $M | D25: =D8*Assumptions!$F$45 -> 86.925 | E25: =E8*(Assumptions!$F$45 + (Assumptions!$F$46-Assumptions!$F$45)*(E$5-2026)/7) -> 130.52836 | F25: =F8*(Assumptions!$F$45 + (Assumptions!$F$46-Assumptions!$F$45)*(F$5-2026)/7) -> 158.83498 | G25: =G8*(Assumptions!$F$45 + (Assumptions!$F$46-Assumptions!$F$45)*(G$5-2026)/7) -> 192.76545 | H25: =H8*(Assumptions!$F$45 + (Assumptions!$F$46-Assumptions!$F$45)*(H$5-2026)/7) -> 227.82866 | I25: =I8*(Assumptions!$F$45 + (Assumptions!$F$46-Assumptions!$F$45)*(I$5-2026)/7) -> 263.32664 | J25: =J8*(Assumptions!$F$45 + (Assumptions!$F$46-Assumptions!$F$45)*(J$5-2026)/7) -> 298.04133 | K25: =K8*(Assumptions!$F$45 + (Assumptions!$F$46-Assumptions!$F$45)*(K$5-2026)/7) -> 330.68185 | L25: =L8*(Assumptions!$F$45 + (Assumptions!$F$46-Assumptions!$F$45)*(L$5-2026)/7) -> 359.95847
A26: G&A % Revenue | B26: % | D26: =D25/D8 -> 0.15 | E26: =E25/E8 -> 0.15 | F26: =F25/F8 -> 0.14428571 | G26: =G25/G8 -> 0.13857143 | H26: =H25/H8 -> 0.13285714 | I26: =I25/I8 -> 0.12714286 | J26: =J25/J8 -> 0.12142857 | K26: =K25/K8 -> 0.11571429 | L26: =L25/L8 -> 0.11 | M26: ← From Assumptions F45/F46 (G&A phase % linearly interpolated)
A27: Stock-Based Compensation | B27: $M | D27: =D8*Assumptions!$F$47 -> 81.13 | E27: =E8*(Assumptions!$F$47 + (Assumptions!$F$48-Assumptions!$F$47)*(E$5-2026)/7) -> 121.82646 | F27: =F8*(Assumptions!$F$47 + (Assumptions!$F$48-Assumptions!$F$47)*(F$5-2026)/7) -> 144.68137 | G27: =G8*(Assumptions!$F$47 + (Assumptions!$F$48-Assumptions!$F$47)*(G$5-2026)/7) -> 170.90545 | H27: =H8*(Assumptions!$F$47 + (Assumptions!$F$48-Assumptions!$F$47)*(H$5-2026)/7) -> 195.98164 | I27: =I8*(Assumptions!$F$47 + (Assumptions!$F$48-Assumptions!$F$47)*(I$5-2026)/7) -> 218.94575 | J27: =J8*(Assumptions!$F$47 + (Assumptions!$F$48-Assumptions!$F$47)*(J$5-2026)/7) -> 238.43306 | K27: =K8*(Assumptions!$F$47 + (Assumptions!$F$48-Assumptions!$F$47)*(K$5-2026)/7) -> 253.11451 | L27: =L8*(Assumptions!$F$47 + (Assumptions!$F$48-Assumptions!$F$47)*(L$5-2026)/7) -> 261.78798
A28: SBC % Revenue | B28: % | D28: =D27/D8 -> 0.14 | E28: =E27/E8 -> 0.14 | F28: =F27/F8 -> 0.13142857 | G28: =G27/G8 -> 0.12285714 | H28: =H27/H8 -> 0.11428571 | I28: =I27/I8 -> 0.10571429 | J28: =J27/J8 -> 0.097142857 | K28: =K27/K8 -> 0.088571429 | L28: =L27/L8 -> 0.08 | M28: ← From Assumptions F47/F48 (SBC phase % linearly interpolated)
A29: Total OpEx | B29: $M | D29: =D21+D23+D25+D27 -> 469.395 | E29: =E21+E23+E25+E27 -> 617.64641 | F29: =F21+F23+F25+F27 -> 782.07432 | G29: =G21+G23+G25+G27 -> 937.5423 | H29: =H21+H23+H25+H27 -> 1101.377 | I29: =I21+I23+I25+I27 -> 1261.7338 | J29: =J21+J23+J25+J27 -> 1412.3348 | K29: =K21+K23+K25+K27 -> 1545.9525 | L29: =L21+L23+L25+L27 -> 1655.5704
A31: Profitability
A32: EBITDA | B32: $M | D32: =D15-D29+D27 -> -40.565 | E32: =E15-E29+E27 -> 156.82183 | F32: =F15-F29+F27 -> 196.09753 | G32: =G15-G29+G27 -> 296.55403 | H32: =H15-H29+H27 -> 417.48067 | I32: =I15-I29+I27 -> 569.71779 | J32: =J15-J29+J27 -> 754.60095 | K32: =K15-K29+K27 -> 972.94503 | L32: =L15-L29+L27 -> 1224.0974
A33: EBITDA Margin | B33: % | D33: =D32/D8 -> -0.07 | E33: =E32/E8 -> 0.18021582 | F33: =F32/F8 -> 0.17813502 | G33: =G32/G8 -> 0.21318092 | H33: =H32/H8 -> 0.24345177 | I33: =I32/I8 -> 0.27507869 | J33: =J32/J8 -> 0.30744097 | K33: =K32/K8 -> 0.34045908 | L33: =L32/L8 -> 0.37407292
A34: EBIT / Operating Income | B34: $M | D34: =D15-D29 -> -121.695 | E34: =E15-E29 -> 34.995368 | F34: =F15-F29 -> 51.416164 | G34: =G15-G29 -> 125.64858 | H34: =H15-H29 -> 221.49903 | I34: =I15-I29 -> 350.77204 | J34: =J15-J29 -> 516.16789 | K34: =K15-K29 -> 719.83053 | L34: =L15-L29 -> 962.30944
A35: Operating Margin | B35: % | D35: =D34/D8 -> -0.21 | E35: =E34/E8 -> 0.040215823 | F35: =F34/F8 -> 0.046706449 | G35: =G34/G8 -> 0.090323776 | H35: =H34/H8 -> 0.12916605 | I35: =I34/I8 -> 0.1693644 | J35: =J34/J8 -> 0.21029811 | K35: =K34/K8 -> 0.25188765 | L35: =L34/L8 -> 0.29407292
A36: Rule of 40 Score | B36: # | D36: =(D9+D33)*100 -> -7 | E36: =(E9+E33)*100 -> 68.183624 | F36: =(F9+F33)*100 -> 44.318944 | G36: =(G9+G33)*100 -> 47.684804 | H36: =(H9+H33)*100 -> 47.618169 | I36: =(I9+I33)*100 -> 48.283523 | J36: =(J9+J33)*100 -> 49.25349 | K36: =(K9+K33)*100 -> 50.47668 | L36: =(L9+L33)*100 -> 51.915424 | M36: = Revenue Growth % + EBITDA Margin %
A38: Below the Line
A39: Interest Income / (Expense) | B39: $M | D39: ='WC & Cash'!$D$12*Assumptions!$F$67 -> 2.625 | E39: =('WC & Cash'!D33 + 'WC & Cash'!E13*0.5)*Assumptions!$F$67 -> 21.316263 | F39: ='WC & Cash'!E33*Assumptions!$F$67 -> 35.28779 | G39: ='WC & Cash'!F33*Assumptions!$F$67 -> 41.373373 | H39: ='WC & Cash'!G33*Assumptions!$F$67 -> 49.373971 | I39: ='WC & Cash'!H33*Assumptions!$F$67 -> 60.394012 | J39: ='WC & Cash'!I33*Assumptions!$F$67 -> 75.265325 | K39: ='WC & Cash'!J33*Assumptions!$F$67 -> 94.816087 | L39: ='WC & Cash'!K33*Assumptions!$F$67 -> 119.90376
A40: Pre-Tax Income | B40: $M | D40: =D34+D39 -> -119.07 | E40: =E34+E39 -> 56.311632 | F40: =F34+F39 -> 86.703953 | G40: =G34+G39 -> 167.02195 | H40: =H34+H39 -> 270.873 | I40: =I34+I39 -> 411.16605 | J40: =J34+J39 -> 591.43321 | K40: =K34+K39 -> 814.64662 | L40: =L34+L39 -> 1082.2132
A41: Taxes | B41: $M | D41: =MAX(0, D40-D48)*Assumptions!$F$52 -> 0 | E41: =MAX(0, E40-E48)*Assumptions!$F$52 -> 2.590335 | F41: =MAX(0, F40-F48)*Assumptions!$F$52 -> 3.9883819 | G41: =MAX(0, G40-G48)*Assumptions!$F$52 -> 37.343817 | H41: =MAX(0, H40-H48)*Assumptions!$F$52 -> 62.30079 | I41: =MAX(0, I40-I48)*Assumptions!$F$52 -> 94.568192 | J41: =MAX(0, J40-J48)*Assumptions!$F$52 -> 136.02964 | K41: =MAX(0, K40-K48)*Assumptions!$F$52 -> 187.36872 | L41: =MAX(0, L40-L48)*Assumptions!$F$52 -> 248.90904
A42: Net Income | B42: $M | D42: =D40-D41 -> -119.07 | E42: =E40-E41 -> 53.721296 | F42: =F40-F41 -> 82.715572 | G42: =G40-G41 -> 129.67814 | H42: =H40-H41 -> 208.57221 | I42: =I40-I41 -> 316.59786 | J42: =J40-J41 -> 455.40357 | K42: =K40-K41 -> 627.27789 | L42: =L40-L41 -> 833.30417
A43: Net Margin | B43: % | D43: =D42/D8 -> -0.20547023 | E43: =E42/E8 -> 0.061735203 | F43: =F42/F8 -> 0.075138836 | G43: =G42/G8 -> 0.093220464 | H43: =H42/H8 -> 0.12162784 | I43: =I42/I8 -> 0.15286397 | J43: =J42/J8 -> 0.1855414 | K43: =K42/K8 -> 0.21950105 | L43: =L42/L8 -> 0.25465009
A45: NOL Carryforward Schedule (post-TCJA, 80% utilization cap)
A46: Beginning NOL Balance | B46: $M | C46: 0 | D46: =C49 -> 0 | E46: =D49 -> 119.07 | F46: =E49 -> 74.020695 | G46: =F49 -> 4.657532 | H46: =G49 -> 0 | I46: =H49 -> 0 | J46: =I49 -> 0 | K46: =J49 -> 0 | L46: =K49 -> 0
A47: + Current Year Loss Added (if pretax < 0) | B47: $M | C47: 0 | D47: =MAX(0,-D40) -> 119.07 | E47: =MAX(0,-E40) -> 0 | F47: =MAX(0,-F40) -> 0 | G47: =MAX(0,-G40) -> 0 | H47: =MAX(0,-H40) -> 0 | I47: =MAX(0,-I40) -> 0 | J47: =MAX(0,-J40) -> 0 | K47: =MAX(0,-K40) -> 0 | L47: =MAX(0,-L40) -> 0
A48: − NOL Utilized Against Current Income | B48: $M | C48: 0 | D48: =MIN(D46, MAX(0,D40)*0.8) -> 0 | E48: =MIN(E46, MAX(0,E40)*0.8) -> 45.049305 | F48: =MIN(F46, MAX(0,F40)*0.8) -> 69.363163 | G48: =MIN(G46, MAX(0,G40)*0.8) -> 4.657532 | H48: =MIN(H46, MAX(0,H40)*0.8) -> 0 | I48: =MIN(I46, MAX(0,I40)*0.8) -> 0 | J48: =MIN(J46, MAX(0,J40)*0.8) -> 0 | K48: =MIN(K46, MAX(0,K40)*0.8) -> 0 | L48: =MIN(L46, MAX(0,L40)*0.8) -> 0
A49: Ending NOL Balance | B49: $M | C49: =C46+C47-C48 -> 0 | D49: =D46+D47-D48 -> 119.07 | E49: =E46+E47-E48 -> 74.020695 | F49: =F46+F47-F48 -> 4.657532 | G49: =G46+G47-G48 -> 0 | H49: =H46+H47-H48 -> 0 | I49: =I46+I47-I48 -> 0 | J49: =J46+J47-J48 -> 0 | ... L49: =L46+L47-L48 -> 0

Sheet FCF
A1: WHOOP — FCF
A2: Free cash flow build. ΔNWC sourced from WC & Cash tab (detailed deferred-rev schedule).
B5: Units | C5: 2024 | D5: 2025 | E5: 2026 | F5: 2027 | G5: 2028 | H5: 2029 | I5: 2030 | J5: 2031 | K5: 2032 | L5: 2033
C6: Historical | D6: Historical | E6: Phase 1 | F6: Phase 1 | G6: Phase 2 | H6: Phase 2 | I6: Phase 2 | J6: Phase 3 | K6: Phase 3 | L6: Phase 3
A8: 1. EBIT to NOPAT
A9: EBIT | B9: $M | D9: ='P&L'!D34 -> -121.695 | E9: ='P&L'!E34 -> 34.995368 | F9: ='P&L'!F34 -> 51.416164 | G9: ='P&L'!G34 -> 125.64858 | H9: ='P&L'!H34 -> 221.49903 | I9: ='P&L'!I34 -> 350.77204 | J9: ='P&L'!J34 -> 516.16789 | K9: ='P&L'!K34 -> 719.83053 | L9: ='P&L'!L34 -> 962.30944 | M9: = P&L EBIT (row 33)
A10: Less: Cash taxes on EBIT | B10: $M | D10: ='P&L'!D41 -> 0 | E10: ='P&L'!E41 -> 2.590335 | F10: ='P&L'!F41 -> 3.9883819 | G10: ='P&L'!G41 -> 37.343817 | H10: ='P&L'!H41 -> 62.30079 | I10: ='P&L'!I41 -> 94.568192 | J10: ='P&L'!J41 -> 136.02964 | K10: ='P&L'!K41 -> 187.36872 | L10: ='P&L'!L41 -> 248.90904 | M10: = P&L Cash Taxes (row 40), tax-affected at effective rate
A11: NOPAT | B11: $M | D11: =D9-D10 -> -121.695 | E11: =E9-E10 -> 32.405033 | F11: =F9-F10 -> 47.427782 | G11: =G9-G10 -> 88.304764 | H11: =H9-H10 -> 159.19824 | I11: =I9-I10 -> 256.20385 | J11: =J9-J10 -> 380.13825 | K11: =K9-K10 -> 532.46181 | L11: =L9-L10 -> 713.40041 | M11: = EBIT − Cash Taxes
A13: 2. NOPAT to Unlevered FCF
A14: Plus: D&A | B14: $M | D14: ='P&L'!D8*Assumptions!$F$53 -> 20.2825 | E14: ='P&L'!E8*Assumptions!$F$53 -> 30.456616 | F14: ='P&L'!F8*Assumptions!$F$53 -> 38.529277 | G14: ='P&L'!G8*Assumptions!$F$53 -> 48.688181 | H14: ='P&L'!H8*Assumptions!$F$53 -> 60.019377 | I14: ='P&L'!I8*Assumptions!$F$53 -> 72.488795 | J14: ='P&L'!J8*Assumptions!$F$53 -> 85.906031 | K14: ='P&L'!K8*Assumptions!$F$53 -> 100.02105 | L14: ='P&L'!L8*Assumptions!$F$53 -> 114.53224 | M14: = Revenue × D&A % (Assumptions F52)
A15: Less: CapEx | B15: $M | D15: =-'P&L'!D8*Assumptions!$F$49 -> -23.18 | E15: =-'P&L'!E8*Assumptions!$F$49 -> -34.807561 | F15: =-'P&L'!F8*Assumptions!$F$49 -> -44.033459 | G15: =-'P&L'!G8*Assumptions!$F$49 -> -55.643635 | H15: =-'P&L'!H8*Assumptions!$F$49 -> -68.593574 | I15: =-'P&L'!I8*Assumptions!$F$49 -> -82.844337 | J15: =-'P&L'!J8*Assumptions!$F$49 -> -98.178321 | K15: =-'P&L'!K8*Assumptions!$F$49 -> -114.30978 | L15: =-'P&L'!L8*Assumptions!$F$49 -> -130.89399 | M15: = −(Revenue × CapEx %) (Assumptions F48)
A16: Less: Change in NWC | B16: $M | D16: ='WC & Cash'!D26 -> 371.1286 | E16: ='WC & Cash'!E26 -> 83.632384 | F16: ='WC & Cash'!F26 -> 131.95021 | G16: ='WC & Cash'!G26 -> 147.23921 | H16: ='WC & Cash'!H26 -> 164.23426 | I16: ='WC & Cash'!I26 -> 179.04635 | J16: ='WC & Cash'!J26 -> 190.72724 | K16: ='WC & Cash'!K26 -> 198.61768 | L16: ='WC & Cash'!L26 -> 200.55688 | M16: = From WC & Cash tab (Section 3, Total ΔNWC)
A17: Note: SBC is REAL COST in P&L — do NOT add back | M17: Per methodology Sec 6 — SBC stays in P&L as cash-equivalent expense
A18: Unlevered Free Cash Flow | B18: $M | D18: =D11+D14+D15+D16 -> 246.5361 | E18: =E11+E14+E15+E16 -> 111.68647 | F18: =F11+F14+F15+F16 -> 173.87381 | G18: =G11+G14+G15+G16 -> 228.58852 | H18: =H11+H14+H15+H16 -> 314.8583 | I18: =I11+I14+I15+I16 -> 424.89465 | J18: =J11+J14+J15+J16 -> 558.5932 | K18: =K11+K14+K15+K16 -> 716.79076 | L18: =L11+L14+L15+L16 -> 897.59554 | M18: = NOPAT + D&A + CapEx + ΔNWC
A20: 3. FCF Diagnostics
A21: FCF Margin % | B21: % | D21: =IFERROR(D18/'P&L'!D8,0) -> 0.42542898 | E21: =IFERROR(E18/'P&L'!E8,0) -> 0.12834737 | F21: =IFERROR(F18/'P&L'!F8,0) -> 0.15794699 | G21: =IFERROR(G18/'P&L'!G8,0) -> 0.16432321 | H21: =IFERROR(H18/'P&L'!H8,0) -> 0.18360805 | I21: =IFERROR(I18/'P&L'!I8,0) -> 0.20515326 | J21: =IFERROR(J18/'P&L'!J8,0) -> 0.22758312 | K21: =IFERROR(K18/'P&L'!K8,0) -> 0.25082396 | L21: =IFERROR(L18/'P&L'!L8,0) -> 0.27429695 | M21: FCF / Revenue
A22: Rule of 40 (Growth + FCF Margin) | B22: % | E22: =IFERROR(('P&L'!E8/'P&L'!D8-1)*100 + E21*100,0) -> 62.996779 | F22: =IFERROR(('P&L'!F8/'P&L'!E8-1)*100 + F21*100,0) -> 42.300141 | G22: =IFERROR(('P&L'!G8/'P&L'!F8-1)*100 + G21*100,0) -> 42.799034 | H22: =IFERROR(('P&L'!H8/'P&L'!G8-1)*100 + H21*100,0) -> 41.633797 | I22: =IFERROR(('P&L'!I8/'P&L'!H8-1)*100 + I21*100,0) -> 41.29098 | J22: =IFERROR(('P&L'!J8/'P&L'!I8-1)*100 + J21*100,0) -> 41.267704 | K22: =IFERROR(('P&L'!K8/'P&L'!J8-1)*100 + K21*100,0) -> 41.513168 | L22: =IFERROR(('P&L'!L8/'P&L'!K8-1)*100 + L21*100,0) -> 41.937826 | M22: Revenue Growth % + FCF Margin %

Sheet WC & Cash
A1: WHOOP — Working Capital & Cash Roll-Forward
A2: $M; pre-IPO (no debt service / dividends / buybacks). Replaces FCF-tab ΔNWC plug with explicit WC build.
A3: Detailed WC schedule wired into FCF tab as of this session. DCF EV impact: +$813M.
B5: Units | C5: 2024 | D5: 2025 | E5: 2026 | F5: 2027 | G5: 2028 | H5: 2029 | I5: 2030 | J5: 2031 | K5: 2032 | L5: 2033
A7: 1. Drivers
A8: Avg months remaining on annual sub (deferred rev) | B8: mo | D8: 6
A9: Inventory days (gross adds device cost) | B9: days | D9: 45
A10: Accounts payable days (% of total COGS) | B10: days | D10: 18
A11: Other NWC (% of revenue) | B11: % | D11: 0.015
A12: Pre-existing cash balance (start 2025) | B12: $M | D12: 75
A13: Series G proceeds (closed Mar 2026) | B13: $M | D13: 0 | E13: 575
A15: 2. Working Capital Balances (Liabilities = Source / Assets = Use)
A16: Deferred Revenue (= End Members × ARPU × mo/12) | B16: $M | C16: 0 | D16: =Members!D34*ARPU!D10*$D$8/12 -> 381.25 | E16: =Members!E34*ARPU!E10*$D$8/12 -> 473.68903 | F16: =Members!F34*ARPU!F10*$D$8/12 -> 608.19989 | G16: =Members!G34*ARPU!G10*$D$8/12 -> 758.56299 | H16: =Members!H34*ARPU!H10*$D$8/12 -> 925.93383 | I16: =Members!I34*ARPU!I10*$D$8/12 -> 1108.1372 | J16: =Members!J34*ARPU!J10*$D$8/12 -> 1301.9953 | K16: =Members!K34*ARPU!K10*$D$8/12 -> 1503.6693 | L16: =Members!L34*ARPU!L10*$D$8/12 -> 1708.5337
A17: Inventory (= ~45 days of NEXT-yr hardware COGS) | B17: $M | C17: 0 | D17: ='P&L'!E13*$D$9/365 -> 12.860137 | E17: ='P&L'!F13*$D$9/365 -> 16.603577 | F17: ='P&L'!G13*$D$9/365 -> 18.160341 | G17: ='P&L'!H13*$D$9/365 -> 19.916635 | H17: ='P&L'!I13*$D$9/365 -> 21.356275 | I17: ='P&L'!J13*$D$9/365 -> 22.45562 | J17: ='P&L'!K13*$D$9/365 -> 23.157681 | K17: ='P&L'!L13*$D$9/365 -> 23.419831 | L17: =K17*1.05 -> 24.590823
A18: Accounts Payable (= ~18 days of total COGS) | B18: $M | C18: 0 | D18: ='P&L'!D14*$D$10/365 -> 11.431233 | E18: ='P&L'!E14*$D$10/365 -> 10.728358 | F18: ='P&L'!F14*$D$10/365 -> 13.184186 | G18: ='P&L'!G14*$D$10/365 -> 16.170411 | H18: ='P&L'!H14*$D$10/365 -> 19.329696 | I18: ='P&L'!I14*$D$10/365 -> 22.616018 | J18: ='P&L'!J14*$D$10/365 -> 25.937521 | K18: ='P&L'!K14*$D$10/365 -> 29.192614 | L18: ='P&L'!L14*$D$10/365 -> 32.27523
A19: Other NWC (= 1.5% of revenue) | B19: $M | C19: 0 | D19: ='P&L'!D8*$D$11 -> 8.6925 | E19: ='P&L'!E8*$D$11 -> 13.052836 | F19: ='P&L'!F8*$D$11 -> 16.512547 | G19: ='P&L'!G8*$D$11 -> 20.866363 | H19: ='P&L'!H8*$D$11 -> 25.72259 | I19: ='P&L'!I8*$D$11 -> 31.066626 | J19: ='P&L'!J8*$D$11 -> 36.81687 | K19: ='P&L'!K8*$D$11 -> 42.866166 | L19: ='P&L'!L8*$D$11 -> 49.085246
A21: 3. Change in WC (positive = cash source)
A22: Δ Deferred Revenue (liability ↑ = source) | B22: $M | D22: =D16-C16 -> 381.25 | E22: =E16-D16 -> 92.439034 | F22: =F16-E16 -> 134.51086 | G22: =G16-F16 -> 150.3631 | H22: =H16-G16 -> 167.37084 | I22: =I16-H16 -> 182.20341 | J22: =J16-I16 -> 193.85804 | K22: =K16-J16 -> 201.67403 | L22: =L16-K16 -> 204.86434
A23: Δ Inventory (asset ↑ = use) | B23: $M | D23: =-(D17-C17) -> -12.860137 | E23: =-(E17-D17) -> -3.7434397 | F23: =-(F17-E17) -> -1.5567639 | G23: =-(G17-F17) -> -1.7562941 | H23: =-(H17-G17) -> -1.4396406 | I23: =-(I17-H17) -> -1.099345 | J23: =-(J17-I17) -> -0.70206013 | K23: =-(K17-J17) -> -0.26215072 | L23: =-(L17-K17) -> -1.1709916
A24: Δ Accounts Payable (liability ↑ = source) | B24: $M | D24: =D18-C18 -> 11.431233 | E24: =E18-D18 -> -0.70287492 | F24: =F18-E18 -> 2.4558285 | G24: =G18-F18 -> 2.9862241 | H24: =H18-G18 -> 3.1592853 | I24: =I18-H18 -> 3.2863218 | J24: =J18-I18 -> 3.3215035 | K24: =K18-J18 -> 3.2550931 | L24: =L18-K18 -> 3.0826162
A25: Δ Other NWC (asset ↑ = use) | B25: $M | D25: =-(D19-C19) -> -8.6925 | E25: =-(E19-D19) -> -4.3603355 | F25: =-(F19-E19) -> -3.4597118 | G25: =-(G19-F19) -> -4.3538159 | H25: =-(H19-G19) -> -4.856227 | I25: =-(I19-H19) -> -5.3440363 | J25: =-(J19-I19) -> -5.7502438 | K25: =-(K19-J19) -> -6.049296 | L25: =-(L19-K19) -> -6.21908
A26: Total Δ NWC (cash impact) | B26: $M | D26: =SUM(D22:D25) -> 371.1286 | E26: =SUM(E22:E25) -> 83.632384 | F26: =SUM(F22:F25) -> 131.95021 | G26: =SUM(G22:G25) -> 147.23921 | H26: =SUM(H22:H25) -> 164.23426 | I26: =SUM(I22:I25) -> 179.04635 | J26: =SUM(J22:J25) -> 190.72724 | K26: =SUM(K22:K25) -> 198.61768 | L26: =SUM(L22:L25) -> 200.55688
A28: 4. Cash Roll-Forward (pre-IPO; no debt service / dividends / buybacks)
A29: Beginning Cash | B29: $M | D29: =$D$12 -> 75 | E29: =D33 -> 321.5361 | F29: =E33 -> 1008.2226 | G29: =F33 -> 1182.0964 | H29: =G33 -> 1410.6849 | I29: =H33 -> 1725.5432 | J29: =I33 -> 2150.4379 | K29: =J33 -> 2709.0311 | L29: =K33 -> 3425.8218
A30: + Series G proceeds | B30: $M | D30: =$D$13 -> 0 | E30: =$E$13 -> 575 | F30: 0 | G30: 0 | H30: 0 | I30: 0 | J30: 0 | K30: 0 | L30: 0
A31: + Unlevered Free Cash Flow (FCF tab) | B31: $M | D31: =FCF!D18 -> 246.5361 | E31: =FCF!E18 -> 111.68647 | F31: =FCF!F18 -> 173.87381 | G31: =FCF!G18 -> 228.58852 | H31: =FCF!H18 -> 314.8583 | I31: =FCF!I18 -> 424.89465 | J31: =FCF!J18 -> 558.5932 | K31: =FCF!K18 -> 716.79076 | L31: =FCF!L18 -> 897.59554
A33: Ending Cash | B33: $M | D33: =D29+D30+D31 -> 321.5361 | E33: =E29+E30+E31 -> 1008.2226 | F33: =F29+F30+F31 -> 1182.0964 | G33: =G29+G30+G31 -> 1410.6849 | H33: =H29+H30+H31 -> 1725.5432 | I33: =I29+I30+I31 -> 2150.4379 | J33: =J29+J30+J31 -> 2709.0311 | K33: =K29+K30+K31 -> 3425.8218 | L33: =L29+L30+L31 -> 4323.4174

Sheet DCF
A1: WHOOP — Discounted Cash Flow
A2: $M; Calendar Year; Base case below — see Sensitivity tab for ranges
A3: ✓ Integrity flags clear: TV divergence 2.9% (<25% threshold), TV % EV 72% (<75% threshold). Both passed after exit-multiple tightening to 3.5x and WC schedule wiring.
B5: Units | C5: 2025 | D5: 2026 | E5: 2027 | F5: 2028 | G5: 2029 | H5: 2030 | I5: 2031 | J5: 2032 | K5: 2033
A7: 1. Cash Flow & Discounting
A8: Revenue (memo) | B8: $M | C8: ='P&L'!D8 -> 579.5 | D8: ='P&L'!E8 -> 870.18903 | E8: ='P&L'!F8 -> 1100.8365 | F8: ='P&L'!G8 -> 1391.0909 | G8: ='P&L'!H8 -> 1714.8393 | H8: ='P&L'!I8 -> 2071.1084 | I8: ='P&L'!J8 -> 2454.458 | J8: ='P&L'!K8 -> 2857.7444 | K8: ='P&L'!L8 -> 3272.3497 | M8: ← From P&L tab
A9: Unlevered Free Cash Flow | B9: $M | C9: =FCF!D18 -> 246.5361 | D9: =FCF!E18 -> 111.68647 | E9: =FCF!F18 -> 173.87381 | F9: =FCF!G18 -> 228.58852 | G9: =FCF!H18 -> 314.8583 | H9: =FCF!I18 -> 424.89465 | I9: =FCF!J18 -> 558.5932 | J9: =FCF!K18 -> 716.79076 | K9: =FCF!L18 -> 897.59554 | M9: ← From FCF tab (single source of truth)
A10: FCF Margin % | B10: % | C10: =IFERROR(C9/C8,0) -> 0.42542898 | D10: =IFERROR(D9/D8,0) -> 0.12834737 | E10: =IFERROR(E9/E8,0) -> 0.15794699 | F10: =IFERROR(F9/F8,0) -> 0.16432321 | G10: =IFERROR(G9/G8,0) -> 0.18360805 | H10: =IFERROR(H9/H8,0) -> 0.20515326 | I10: =IFERROR(I9/I8,0) -> 0.22758312 | J10: =IFERROR(J9/J8,0) -> 0.25082396 | K10: =IFERROR(K9/K8,0) -> 0.27429695
A12: WACC | B12: % | C12: n/a | D12: =Assumptions!$F$74 -> 0.10845 | E12: =Assumptions!$F$74 -> 0.10845 | F12: =Assumptions!$F$74 -> 0.10845 | G12: =Assumptions!$F$74 -> 0.10845 | H12: =Assumptions!$F$74 -> 0.10845 | I12: =Assumptions!$F$74 -> 0.10845 | J12: =Assumptions!$F$74 -> 0.10845 | K12: =Assumptions!$F$74 -> 0.10845 | M12: ← From Assumptions F74
A13: Discount Period (mid-year) | B13: yrs | C13: n/a | D13: 0.5 | E13: 1.5 | F13: 2.5 | G13: 3.5 | H13: 4.5 | I13: 5.5 | J13: 6.5 | K13: 7.5 | M13: Mid-year convention
A14: Discount Factor | B14: x | C14: n/a | D14: =1/(1+D12)^D13 -> 0.94982139 | E14: =1/(1+E12)^E13 -> 0.85689151 | F14: =1/(1+F12)^F13 -> 0.77305382 | G14: =1/(1+G12)^G13 -> 0.69741876 | H14: =1/(1+H12)^H13 -> 0.62918378 | I14: =1/(1+I12)^I13 -> 0.56762486 | J14: =1/(1+J12)^J13 -> 0.51208883 | K14: =1/(1+K12)^K13 -> 0.4619864
A15: PV of Unlevered FCF | B15: $M | C15: n/a | D15: =D9*D14 -> 106.0822 | E15: =E9*E14 -> 148.99099 | F15: =F9*F14 -> 176.71123 | G15: =G9*G14 -> 219.58809 | H15: =H9*H14 -> 267.33682 | I15: =I9*I14 -> 317.07139 | J15: =J9*J14 -> 367.06054 | K15: =K9*K14 -> 414.67693 | M15: = UFCF / (1+WACC)^period
A17: 2. Terminal Value
A18: Terminal Year Revenue | B18: $M | C18: =K8 -> 3272.3497
A19: Terminal Year EBITDA | B19: $M | C19: ='P&L'!L32 -> 1224.0974
A20: Terminal Year FCF | B20: $M | C20: =K9 -> 897.59554
A21: Exit Multiple (EV/Revenue) | B21: x | C21: =Assumptions!$F$78 -> 3.5 | L21: ← From Assumptions F78
A22: Terminal Value (Exit Multiple) | B22: $M | C22: =C18*C21 -> 11453.224
A23: Terminal Value (Gordon Growth) | B23: $M | C23: =C20*(1+Assumptions!$F$80)/(D12-Assumptions!$F$80) -> 11784.875 | L23: Gordon: =FCF × (1+g) / (WACC − g)
