Workbook
Name Scenario: Assumptions!$B$3

Sheet Cover
B3: WHOOP Inc.
B4: Private Company Valuation
B5: Investment Committee Memo — Supporting Model
B8: Company: | C8: WHOOP Inc.
B9: Ticker: | C9: Private (Pre-IPO)
B10: Last Round: | C10: Series G — $575M at $10.1B post-money (Mar 31, 2026)
B11: Model Date: | C11: April 16, 2026
B12: Analyst: | C12: Landon Brice
B13: Fiscal Year: | C13: Calendar Year (Jan-Dec)
B14: Currency: | C14: USD ($M unless noted)
B17: Valuation Methods:
B18: 1. Intrinsic DCF (scenario-based + real options)
B19: 2. Trading Comps (three-bucket framework)
B20: 3. Precedent Transactions
B21: 4. Last-Round Implied ($10.1B)
B22: 5. Implied IPO Trading Range (back-solved)
B25: Color Convention:
B26: Hard-coded input
B27: Formula / calculation
B28: Cross-sheet link
B29: Needs verification / FLAGGED_GAP
B32: Source Files:
B33: Valuation Summary (live, scenario-driven)
B34: Active Scenario | C34: =Assumptions!$B$3 -> Base
B36: Base DCF — Enterprise Value | C36: =DCF!C39 -> 9467.9686
B37: + Cash | C37: =DCF!C44 -> 700
B38: − Debt | C38: =DCF!C43 -> -10
B39: = Equity Value | C39: =DCF!C45 -> 10157.969
B40: Per Share (FD) | C40: =DCF!C47 -> 24.775533
B42: Real Options (Expected) | C42: =DCF!C53 -> 2392.5
B43: Total EV (DCF + Options) | C43: =DCF!C54 -> 11860.469
B45: Series G Mark | C45: =DCF!C59 -> 10100
B46: Base DCF vs Series G | C46: =DCF!C60 -> -0.062577364
B47: DCF + Options vs Series G | C47: =DCF!C61 -> 0.17430382
B48: Football Field (multi-method synthesis)
B49: Weighted Average EV | C49: ='Football Field'!D16*1000 -> 8635.452
B50: Per Share (FD) | C50: ='Football Field'!G16 -> 22.745005
B51: vs Series G | C51: ='Football Field'!D18 -> -0.14500475
B53: Model Integrity (Checks tab)
B54: Passing | C54: =Checks!B17 -> 7
...

Sheet Assumptions
A1: WHOOP — Master Assumptions
A3: Scenario: | B3: Base | C3: Select Bear / Base / Bull — drives Active column F throughout the model. Other tabs reference Active values only.
A5: ID | B5: Assumption | C5: Bear | D5: Base | E5: Bull | F5: Active | G5: Tier | H5: Status | I5: Notes
A7: Section 1: Revenue & Growth
A8: R3a | B8: 2025 Beginning Members (M) | C8: 1.5 | D8: 1.3 | E8: 1.1 | F8: =IF($B$3="Bear",C8,IF($B$3="Bull",E8,D8)) -> 1.3 | G8: Tier 3 | H8: High | I8: Back-solved to reconcile avg×ARPU ≈ $650M base. Bear slower decel; bull faster acquisition.
A9: R3b | B9: 2025 Ending Members (M) | C9: 2.3 | D9: 2.5 | E9: 2.7 | F9: =IF($B$3="Bear",C9,IF($B$3="Bull",E9,D9)) -> 2.5 | G9: Tier 1 | H9: Critical | I9: Series G press release: 2.5M+ paying members
A10: R3 | B10: 2025 Average Members (M) — DERIVED | C10: =(C8+C9)/2 -> 1.9 | D10: =(D8+D9)/2 -> 1.9 | E10: =(E8+E9)/2 -> 1.9 | F10: =IF($B$3="Bear",C10,IF($B$3="Bull",E10,D10)) -> 1.9 | G10: Derived | H10: Critical | I10: Per methodology: ARPU applies to AVERAGE members during period, NOT year-end.
A11: R4 | B11: 2025 Blended ARPU ($/yr) | C11: 300 | D11: 338 | E11: 375 | F11: =IF($B$3="Bear",C11,IF($B$3="Bull",E11,D11)) -> 338 | G11: Tier 3 | H11: Critical | I11: v2 build per CLAUDE.md rebuild directives ($300/$338/$375). Single-line; 5-component decomposition deferred to ARPU tab.
A12: R1 | B12: 2025 Recognized Revenue ($M) — DERIVED | C12: =C10*C11 -> 570 | D12: =D10*D11 -> 642.2 | E12: =E10*E11 -> 712.5 | F12: =IF($B$3="Bear",C12,IF($B$3="Bull",E12,D12)) -> 642.2 | G12: Derived | H12: Critical | I12: DERIVED: Avg Members × Blended ARPU. Target ~$650M base. Methodology consistency check: must reconcile within ±5%.
A13: R2 | B13: 2025 Bookings Run-Rate ($M) | C13: 1100 | D13: 1100 | E13: 1100 | F13: =IF($B$3="Bear",C13,IF($B$3="Bull",E13,D13)) -> 1100 | G13: Tier 1 | H13: Locked | I13: Series G press release; CEO statement (Dec 2025 exit rate × 12)
A14: R5 | B14: Subscription Revenue % | C14: 0.8 | D14: 0.85 | E14: 0.88 | F14: =IF($B$3="Bear",C14,IF($B$3="Bull",E14,D14)) -> 0.85 | G14: Tier 2 | H14: High | I14: Sacra/BMCT: ~80-88% range
A15: R6 | B15: 2025 YoY Subscription Growth | C15: 1.03 | D15: 1.03 | E15: 1.03 | F15: =IF($B$3="Bear",C15,IF($B$3="Bull",E15,D15)) -> 1.03 | G15: Tier 1 | H15: Locked | I15: Series G press release: 103%
A16: R7 | B16: Phase 1 Revenue Growth (2026-27) | C16: 0.5 | D16: 0.7 | E16: 0.9 | F16: =IF($B$3="Bear",C16,IF($B$3="Bull",E16,D16)) -> 0.7 | G16: Tier 3 | H16: Critical | I16: Peer trajectories; Series G deployment & WHOOP 5.0 cycle
A17: R8 | B17: Phase 2 Revenue Growth (2028-30) | C17: 0.15 | D17: 0.25 | E17: 0.4 | F17: =IF($B$3="Bear",C17,IF($B$3="Bull",E17,D17)) -> 0.25 | G17: Tier 3 | H17: Critical | I17: Deceleration shape: Dexcom (bull) / Netflix (base) / Peloton (bear)
A18: R9 | B18: Phase 3 Revenue Growth (2031-33) | C18: 0.05 | D18: 0.12 | E18: 0.2 | F18: =IF($B$3="Bear",C18,IF($B$3="Bull",E18,D18)) -> 0.12 | G18: Tier 3 | H18: High | I18: TAM ceiling; healthcare attach resolution
A19: R10a | B19: Year-1 Cohort Annual Churn | C19: 0.3 | D19: 0.22 | E19: 0.15 | F19: =IF($B$3="Bear",C19,IF($B$3="Bull",E19,D19)) -> 0.22 | G19: Tier 3 | H19: Critical | I19: Highest churn ("try and quit"). Will drive Members tab cohort engine.
A20: R10b | B20: Year-2 Cohort Annual Churn | C20: 0.18 | D20: 0.14 | E20: 0.1 | F20: =IF($B$3="Bear",C20,IF($B$3="Bull",E20,D20)) -> 0.14 | G20: Tier 3 | H20: Critical | I20: Stabilizing cohort
A21: R10c | B21: Year-3+ Cohort Annual Churn | C21: 0.12 | D21: 0.08 | E21: 0.05 | F21: =IF($B$3="Bear",C21,IF($B$3="Bull",E21,D21)) -> 0.08 | G21: Tier 3 | H21: Critical | I21: Retained core; very sticky power users
A22: R11 | B22: International Revenue % | C22: 0.35 | D22: 0.43 | E22: 0.55 | F22: =IF($B$3="Bear",C22,IF($B$3="Bull",E22,D22)) -> 0.43 | G22: Tier 2 | H22: High | I22: Stress-tested: 40-45% base; NYT DealBook source ambiguous on "new sales" vs total
A23: R12 | B23: B2B Unite Revenue % | C23: 0.12 | D23: 0.18 | E23: 0.25 | F23: =IF($B$3="Bear",C23,IF($B$3="Bull",E23,D23)) -> 0.18 | G23: Tier 2 | H23: Medium | I23: Sacra/BMCT: ~20% recurring revenue; growing rapidly
A24: R14 | B24: Advanced Labs Attach Rate | C24: 0.03 | D24: 0.1 | E24: 0.25 | F24: =IF($B$3="Bear",C24,IF($B$3="Bull",E24,D24)) -> 0.1 | G24: Tier 3 | H24: Critical | I24: BUCKET-3 THESIS VARIABLE. Bear/Base/Bull per methodology Sec 3. Single most important ARPU assumption — swings $80/member.
... A28: R19 | B28: Deferred Revenue Adjustment (% of bookings) | C28: -0.1 | D28: -0.08 | E28: -0.05 | F28: =IF($B$3="Bear",C28,IF($B$3="Bull",E28,D28)) -> -0.08 | G28: Tier 3 | H28: Medium | I28: Drag during growth (recognized < booked); ASC 606. Approaches 0 at steady state.
A30: Section 2: Cost Structure & Margins
A31: C1 | B31: Hardware BOM per Device ($) | C31: 100 | D31: 80 | E31: 60 | F31: =IF($B$3="Bear",C31,IF($B$3="Bull",E31,D31)) -> 80 | G31: Tier 3 | H31: Critical | I31: Est. $50-80 at scale; 2016 BOM was $250-300 per Contrary Research
A32: C2 | B32: Loaded Hardware Cost per Acquisition ($) | C32: 150 | D32: 120 | E32: 90 | F32: =IF($B$3="Bear",C32,IF($B$3="Bull",E32,D32)) -> 120 | G32: Tier 3 | H32: Critical | I32: C1 + assembly, ship, warranty, returns. Drives unit economics.
A33: C4 | B33: Subscription Delivery Cost (% of sub rev) | C33: 0.15 | D33: 0.1 | E33: 0.08 | F33: =IF($B$3="Bear",C33,IF($B$3="Bull",E33,D33)) -> 0.1 | G33: Tier 3 | H33: High | I33: Infra + support; AWS/GCP benchmarks; declining at scale
A34: C5 | B34: Subscription Gross Margin (standalone) | C34: 0.72 | D34: 0.78 | E34: 0.83 | F34: =IF($B$3="Bear",C34,IF($B$3="Bull",E34,D34)) -> 0.78 | G34: Tier 3 | H34: Critical | I34: Peer: pure SaaS ~80%, Dexcom ~64% (incl consumables). WHOOP higher quality recurring.
A35: C6 | B35: Hardware Gross Margin (standalone) | C35: -0.1 | D35: -0.02 | E35: 0.05 | F35: =IF($B$3="Bear",C35,IF($B$3="Bull",E35,D35)) -> -0.02 | G35: Tier 3 | H35: Critical | I35: Subsidized at acquisition; Peloton HW GM trajectory: -18% to +14%
A36: C7a | B36: Blended GM Phase 1 (2026-27) | C36: 0.56 | D36: 0.6 | E36: 0.64 | F36: =IF($B$3="Bear",C36,IF($B$3="Bull",E36,D36)) -> 0.6 | G36: Tier 3 | H36: Critical | I36: Derived prior; lower in growth years (more hardware drag)
A37: C7b | B37: Blended GM Phase 2 (2028-30) | C37: 0.63 | D37: 0.67 | E37: 0.72 | F37: =IF($B$3="Bear",C37,IF($B$3="Bull",E37,D37)) -> 0.67 | G37: Tier 3 | H37: High | I37: Margin expansion as growth decelerates
A38: C7c | B38: Blended GM Terminal | C38: 0.72 | D38: 0.76 | E38: 0.8 | F38: =IF($B$3="Bear",C38,IF($B$3="Bull",E38,D38)) -> 0.76 | G38: Tier 3 | H38: High | I38: Peer terminal: Dexcom 60%, Spotify 32%; software-heavy mix at scale
A39: C8a | B39: R&D % of Revenue (current) | C39: 0.25 | D39: 0.22 | E39: 0.2 | F39: =IF($B$3="Bear",C39,IF($B$3="Bull",E39,D39)) -> 0.22 | G39: Tier 3 | H39: High | I39: Peers: Dexcom 13%, Garmin 16%, growth SaaS 20-30%
A40: C8b | B40: R&D % of Revenue (terminal) | C40: 0.12 | D40: 0.15 | E40: 0.18 | F40: =IF($B$3="Bear",C40,IF($B$3="Bull",E40,D40)) -> 0.15 | G40: Tier 3 | H40: Medium | I40: Peer steady-state
A41: C9 | B41: S&M % of Revenue (current) | C41: 0.35 | D41: 0.3 | E41: 0.25 | F41: =IF($B$3="Bear",C41,IF($B$3="Bull",E41,D41)) -> 0.3 | G41: Tier 3 | H41: Critical | I41: Peloton peak 28.4% FY22, current 16.9% FY25. Bear = stuck high.
A42: C9a | B42: Paid CAC per Gross Add ($) | C42: 220 | D42: 175 | E42: 130 | F42: =IF($B$3="Bear",C42,IF($B$3="Bull",E42,D42)) -> 175 | G42: Tier 3 | H42: Critical | I42: 30-50% of first-year ARPU. S&M consistency check on Checks tab.
... A53: C12 | B53: D&A % of Revenue | C53: 0.045 | D53: 0.035 | E53: 0.025 | F53: =IF($B$3="Bear",C53,IF($B$3="Bull",E53,D53)) -> 0.035 | G53: Tier 2 | H53: Medium | I53: D&A trails CapEx (~4% of rev) as PP&E ramps. Lower in bull (asset-light scale economies). Used in FCF tab to compute NOPAT → UFCF bridge.
A54: Section 3: Capital Structure & Cap Table (incl. cash yield)
A55: S1 | B55: Fully Diluted Shares Outstanding (M) | C55: 420 | D55: 410 | E55: 400 | F55: =IF($B$3="Bear",C55,IF($B$3="Bull",E55,D55)) -> 410 | G55: Tier 3 | H55: Critical | I55: 361.2M common + ~50M option pool est. Pitchbook auth pref 537.9M, outs 361.2M.
A56: S2 | B56: Series G Price per Share ($) | C56: 28 | D56: 28 | E56: 28 | F56: =IF($B$3="Bear",C56,IF($B$3="Bull",E56,D56)) -> 28 | G56: Tier 2 | H56: High | I56: Pitchbook Series G data; back-solve from $575M raise / shares issued
A57: S3 | B57: Liquidation Preference Type | C57: Participating | D57: 1x non-participating | E57: 1x non-participating | F57: =IF($B$3="Bear",C57,IF($B$3="Bull",E57,D57)) -> 1x non-participating | G57: Tier 2 | H57: Locked | I57: Pitchbook: 1x non-participating pari passu. Bear assumes participating ratchet.
...

Sheet Members
A1: WHOOP — Member Cohort Engine
A2: Members in millions; cohort engine drives revenue. 2025 beginning treated as Y3+ legacy block (simplification — see note).
B5: Units | C5: 2024 | D5: 2025 | E5: 2026 | F5: 2027 | G5: 2028 | H5: 2029 | I5: 2030 | J5: 2031 | K5: 2032 | L5: 2033
C6: Historical | D6: Historical | E6: Phase 1 | F6: Phase 1 | G6: Phase 2 | H6: Phase 2 | I6: Phase 2 | J6: Phase 3 | K6: Phase 3 | L6: Phase 3
A8: 1. Beginning Members (start of year)
A9: Beginning Members (total) | B9: M | C9: 0.7 | D9: =Assumptions!$F$8 -> 1.3 | E9: =D34 -> 2.5 | F9: =E34 -> 2.9099858 | G9: =F34 -> 3.7413302 | H9: =G34 -> 4.4065901 | I9: =H34 -> 5.222723 | J9: =I34 -> 6.1448459 | K9: =J34 -> 6.8029328 | L9: =K34 -> 7.5677286
A10: of which: Year-1 cohort | B10: M | C10: 0.5 | D10: 0 | E10: =D31 -> 1.304 | F10: =E31 -> 0.79254581 | G10: =F31 -> 1.2361269 | H10: =G31 -> 1.1747152 | I10: =H31 -> 1.3909709 | J10: =I31 -> 1.5896534 | K10: =J31 -> 1.4373234 | L10: =K31 -> 1.5846515
A11: of which: Year-2 cohort | B11: M | C11: 0.15 | D11: 0 | E11: =D26 -> 0 | F11: =E26 -> 1.01712 | G11: =F26 -> 0.61818573 | H11: =G26 -> 0.96417899 | I11: =H26 -> 0.91627784 | J11: =I26 -> 1.0849573 | K11: =J26 -> 1.2399297 | L11: =K26 -> 1.1211123
A12: of which: Year-3+ cohort | B12: M | C12: 0.05 | D12: =Assumptions!$F$8 -> 1.3 | E12: =D28 -> 1.196 | F12: =E28 -> 1.10032 | G12: =F28 -> 1.8870176 | H12: =G28 -> 2.2676959 | I12: =H28 -> 2.9154742 | J12: =I28 -> 3.4702352 | K12: =J28 -> 4.1256797 | L12: =K28 -> 4.8619648
A14: 2. Churn Rates (cohort-aged, from Assumptions)
A15: Year-1 churn rate | B15: % | C15: =Assumptions!$F$19 -> 0.22 | D15: =Assumptions!$F$19 -> 0.22 | E15: =Assumptions!$F$19 -> 0.22 | F15: =Assumptions!$F$19 -> 0.22 | G15: =Assumptions!$F$19 -> 0.22 | H15: =Assumptions!$F$19 -> 0.22 | I15: =Assumptions!$F$19 -> 0.22 | J15: =Assumptions!$F$19 -> 0.22 | ... L15: =Assumptions!$F$19 -> 0.22
A16: Year-2 churn rate | B16: % | C16: =Assumptions!$F$20 -> 0.14 | D16: =Assumptions!$F$20 -> 0.14 | E16: =Assumptions!$F$20 -> 0.14 | F16: =Assumptions!$F$20 -> 0.14 | G16: =Assumptions!$F$20 -> 0.14 | H16: =Assumptions!$F$20 -> 0.14 | I16: =Assumptions!$F$20 -> 0.14 | J16: =Assumptions!$F$20 -> 0.14 | ... L16: =Assumptions!$F$20 -> 0.14
A17: Year-3+ churn rate | B17: % | C17: =Assumptions!$F$21 -> 0.08 | D17: =Assumptions!$F$21 -> 0.08 | E17: =Assumptions!$F$21 -> 0.08 | F17: =Assumptions!$F$21 -> 0.08 | G17: =Assumptions!$F$21 -> 0.08 | H17: =Assumptions!$F$21 -> 0.08 | I17: =Assumptions!$F$21 -> 0.08 | J17: =Assumptions!$F$21 -> 0.08 | ... L17: =Assumptions!$F$21 -> 0.08
A19: 3. Churned Members
A20: Y1 churned | B20: M | C20: =C10*C15 -> 0.11 | D20: =D10*D15 -> 0 | E20: =E10*E15 -> 0.28688 | F20: =F10*F15 -> 0.17436008 | G20: =G10*G15 -> 0.27194792 | H20: =H10*H15 -> 0.25843734 | I20: =I10*I15 -> 0.30601361 | J20: =J10*J15 -> 0.34972375 | ... L20: =L10*L15 -> 0.34862333
A21: Y2 churned | B21: M | C21: =C11*C16 -> 0.021 | D21: =D11*D16 -> 0 | E21: =E11*E16 -> 0 | F21: =F11*F16 -> 0.1423968 | G21: =G11*G16 -> 0.086546003 | H21: =H11*H16 -> 0.13498506 | I21: =I11*I16 -> 0.1282789 | J21: =J11*J16 -> 0.15189403 | ... L21: =L11*L16 -> 0.15695572
A22: Y3+ churned | B22: M | C22: =C12*C17 -> 0.004 | D22: =D12*D17 -> 0.104 | E22: =E12*E17 -> 0.09568 | F22: =F12*F17 -> 0.0880256 | G22: =G12*G17 -> 0.15096141 | H22: =H12*H17 -> 0.18141567 | I22: =I12*I17 -> 0.23323793 | J22: =J12*J17 -> 0.27761881 | ... L22: =L12*L17 -> 0.38895719
A23: Total churned | B23: M | C23: =SUM(C20:C22) -> 0.135 | D23: =SUM(D20:D22) -> 0.104 | E23: =SUM(E20:E22) -> 0.38256 | F23: =SUM(F20:F22) -> 0.40478248 | G23: =SUM(G20:G22) -> 0.50945533 | H23: =SUM(H20:H22) -> 0.57483807 | I23: =SUM(I20:I22) -> 0.66753044 | J23: =SUM(J20:J22) -> 0.77923659 | ... L23: =SUM(L20:L22) -> 0.89453623
A25: 4. Surviving Members (end of year, before new adds)
A26: Y1 survivors | B26: M | C26: =C10-C20 -> 0.39 | D26: =D10-D20 -> 0 | E26: =E10-E20 -> 1.01712 | F26: =F10-F20 -> 0.61818573 | G26: =G10-G20 -> 0.96417899 | H26: =H10-H20 -> 0.91627784 | I26: =I10-I20 -> 1.0849573 | J26: =J10-J20 -> 1.2399297 | ... L26: =L10-L20 -> 1.2360282
A27: Y2 survivors | B27: M | C27: =C11-C21 -> 0.129 | D27: =D11-D21 -> 0 | E27: =E11-E21 -> 0 | F27: =F11-F21 -> 0.8747232 | G27: =G11-G21 -> 0.53163973 | H27: =H11-H21 -> 0.82919393 | I27: =I11-I21 -> 0.78799894 | J27: =J11-J21 -> 0.93306331 | ... L27: =L11-L21 -> 0.96415655
A28: Y3+ end state (incl. Y2 graduates) | B28: M | C28: =C12-C22+C27 -> 0.175 | D28: =D12-D22+D27 -> 1.196 | E28: =E12-E22+E27 -> 1.10032 | F28: =F12-F22+F27 -> 1.8870176 | G28: =G12-G22+G27 -> 2.2676959 | H28: =H12-H22+H27 -> 2.9154742 | I28: =I12-I22+I27 -> 3.4702352 | J28: =J12-J22+J27 -> 4.1256797 | ... L28: =L12-L22+L27 -> 5.4371642
A30: 5. New Members (Gross Adds — input per year)
A31: Gross Adds | B31: M | C31: 0.6 | D31: =Assumptions!$F$9-D28 -> 1.304 | E31: =E51 -> 0.79254581 | F31: =F51 -> 1.2361269 | G31: =G51 -> 1.1747152 | H31: =H51 -> 1.3909709 | I31: =I51 -> 1.5896534 | J31: =J51 -> 1.4373234 | K31: =K51 -> 1.5846515 | L31: =L51 -> 1.7033124
A33: 6. Ending & Average Members
A34: Ending Members | B34: M | C34: =C26+C28+C31 -> 1.165 | D34: =D26+D28+D31 -> 2.5 | E34: =E26+E28+E31 -> 2.9099858 | F34: =F26+F28+F31 -> 3.7413302 | G34: =G26+G28+G31 -> 4.4065901 | H34: =H26+H28+H31 -> 5.222723 | I34: =I26+I28+I31 -> 6.1448459 | J34: =J26+J28+J31 -> 6.8029328 | ... L34: =L26+L28+L31 -> 8.3765048
A35: Average Members | B35: M | C35: =(C9+C34)/2 -> 0.9325 | D35: =(D9+D34)/2 -> 1.9 | E35: =(E9+E34)/2 -> 2.7049929 | F35: =(F9+F34)/2 -> 3.325658 | G35: =(G9+G34)/2 -> 4.0739602 | H35: =(H9+H34)/2 -> 4.8146565 | I35: =(I9+I34)/2 -> 5.6837844 | J35: =(J9+J34)/2 -> 6.4738894 | ... L35: =(L9+L34)/2 -> 7.9721167
A37: 7. Diagnostics (output, not input)
A38: Net Adds (Gross - Churned) | B38: M | C38: =C31-C23 -> 0.465 | D38: =D31-D23 -> 1.2 | E38: =E31-E23 -> 0.40998581 | F38: =F31-F23 -> 0.83134443 | G38: =G31-G23 -> 0.66525985 | H38: =H31-H23 -> 0.81613287 | I38: =I31-I23 -> 0.92212298 | J38: =J31-J23 -> 0.65808683 | ... L38: =L31-L23 -> 0.80877619
A39: Net Member Growth % | B39: % | D39: =D34/C34-1 -> 1.1459227 | E39: =E34/D34-1 -> 0.16399433 | F39: =F34/E34-1 -> 0.28568676 | G39: =G34/F34-1 -> 0.17781372 | H39: =H34/G34-1 -> 0.18520735 | I39: =I34/H34-1 -> 0.17655981 | J39: =J34/I34-1 -> 0.10709574 | K39: =K34/J34-1 -> 0.11242149 | L39: =L34/K34-1 -> 0.10687172
A40: Blended Annual Churn Rate (output) | B40: % | C40: =IFERROR(C23/C9,0) -> 0.19285714 | D40: =IFERROR(D23/D9,0) -> 0.08 | E40: =IFERROR(E23/E9,0) -> 0.153024 | F40: =IFERROR(F23/F9,0) -> 0.13910119 | G40: =IFERROR(G23/G9,0) -> 0.13616957 | H40: =IFERROR(H23/H9,0) -> 0.13044964 | I40: =IFERROR(I23/I9,0) -> 0.12781272 | J40: =IFERROR(J23/J9,0) -> 0.12681141 | ... L40: =IFERROR(L23/L9,0) -> 0.11820406
A41: 2025 ending vs Assumptions R3b (consistency) | B41: % | D41: =D34/Assumptions!$F$9-1 -> 0
A43: NOTE: 2025 beginning is treated as Y3+ legacy block (simplification). Replace with audited cohort splits when S-1 data is available. 2024 column is historical reference; engine fully runs 2025 onwards.
A45: 8. Gross Adds Build (DERIVED — S&M / CAC, with TAM diagnostic)
A46: Phase (1=2026-27, 2=2028-30, 3=2031-33) | B46: # | C46: Hist | D46: Hist | E46: 1 | F46: 1 | G46: 2 | H46: 2 | I46: 2 | J46: 3 | K46: 3 | L46: 3
A47: S&M Budget ($M, % × prior-yr revenue) | B47: $M | D47: 195 | E47: ='Revenue Build'!D20*CHOOSE(E46,Assumptions!$F$117,Assumptions!$F$118,Assumptions!$F$119) -> 158.50916 | F47: ='Revenue Build'!E20*CHOOSE(F46,Assumptions!$F$117,Assumptions!$F$118,Assumptions!$F$119) -> 267.00341 | G47: ='Revenue Build'!F20*CHOOSE(G46,Assumptions!$F$117,Assumptions!$F$118,Assumptions!$F$119) -> 274.03756 | H47: ='Revenue Build'!G20*CHOOSE(H46,Assumptions!$F$117,Assumptions!$F$118,Assumptions!$F$119) -> 350.44456 | I47: ='Revenue Build'!H20*CHOOSE(I46,Assumptions!$F$117,Assumptions!$F$118,Assumptions!$F$119) -> 432.54118 | J47: ='Revenue Build'!I20*CHOOSE(J46,Assumptions!$F$117,Assumptions!$F$118,Assumptions!$F$119) -> 422.37993 | K47: ='Revenue Build'!J20*CHOOSE(K46,Assumptions!$F$117,Assumptions!$F$118,Assumptions!$F$119) -> 502.92855 | L47: ='Revenue Build'!K20*CHOOSE(L46,Assumptions!$F$117,Assumptions!$F$118,Assumptions!$F$119) -> 583.83563
A48: Blended CAC ($) | B48: $ | D48: 130 | E48: =Assumptions!$F$121 -> 200 | F48: =E48*(1+Assumptions!$F$122) -> 216 | G48: =F48*(1+Assumptions!$F$122) -> 233.28 | H48: =G48*(1+Assumptions!$F$122) -> 251.9424 | I48: =H48*(1+Assumptions!$F$122) -> 272.09779 | J48: =I48*(1+Assumptions!$F$122) -> 293.86562 | K48: =J48*(1+Assumptions!$F$122) -> 317.37486 | L48: =K48*(1+Assumptions!$F$122) -> 342.76485
A49: Unconstrained Gross Adds (M) = S&M / CAC | B49: M | D49: =D47/D48 -> 1.5 | E49: =E47/E48 -> 0.79254581 | F49: =F47/F48 -> 1.2361269 | G49: =G47/G48 -> 1.1747152 | H49: =H47/H48 -> 1.3909709 | I49: =I47/I48 -> 1.5896534 | J49: =J47/J48 -> 1.4373234 | K49: =K47/K48 -> 1.5846515 | L49: =L47/L48 -> 1.7033124
A50: TAM Penetration % (diagnostic — flag if >40%) | B50: % | D50: n/a | E50: =D34/Assumptions!$F$123 -> 0.1 | F50: =E34/Assumptions!$F$123 -> 0.11639943 | G50: =F34/Assumptions!$F$123 -> 0.14965321 | H50: =G34/Assumptions!$F$123 -> 0.1762636 | I50: =H34/Assumptions!$F$123 -> 0.20890892 | J50: =I34/Assumptions!$F$123 -> 0.24579384 | K50: =J34/Assumptions!$F$123 -> 0.27211731 | L50: =K34/Assumptions!$F$123 -> 0.30270914
A51: Final Gross Adds (M) | B51: M | D51: =D49 -> 1.5 | E51: =E49 -> 0.79254581 | F51: =F49 -> 1.2361269 | G51: =G49 -> 1.1747152 | H51: =H49 -> 1.3909709 | I51: =I49 -> 1.5896534 | J51: =J49 -> 1.4373234 | K51: =K49 -> 1.5846515 | L51: =L49 -> 1.7033124

Sheet ARPU
A1: ARPU Decomposition (5 components per Methodology Sec 3)
A2: Driven from Assumptions Section 11. Sub ARPU = tier-mix × disclosed prices + monthly premium. Labs = attach × price × tests/yr (with 2025 launch-year scaling). Accessories = baseline × (1+inflation). BP/Healthspan = attach × price (paid add-on layer). Sums to Blended ARPU on row 32; consistency check vs. Assumptions R4 below.
A5: Year | B5: Unit | C5: 2024 | D5: 2025 | E5: 2026 | F5: 2027 | G5: 2028 | H5: 2029 | I5: 2030 | J5: 2031 | K5: 2032 | L5: 2033
A7: 1. Subscription ARPU (tier-mix-driven)
A8: Tier mix: % WHOOP One | B8: % | D8: =Assumptions!$F$130 -> 0.3 | E8: =MAX(0,D8-Assumptions!$F$134) -> 0.285 | F8: =MAX(0,E8-Assumptions!$F$134) -> 0.27 | G8: =MAX(0,F8-Assumptions!$F$134) -> 0.255 | H8: =MAX(0,G8-Assumptions!$F$134) -> 0.24 | I8: =MAX(0,H8-Assumptions!$F$134) -> 0.225 | J8: =MAX(0,I8-Assumptions!$F$134) -> 0.21 | K8: =MAX(0,J8-Assumptions!$F$134) -> 0.195 | L8: =MAX(0,K8-Assumptions!$F$134) -> 0.18
A9: Tier mix: % WHOOP Peak | B9: % | D9: =Assumptions!$F$131 -> 0.45 | E9: =D9+Assumptions!$F$134*0.5 -> 0.4575 | F9: =E9+Assumptions!$F$134*0.5 -> 0.465 | G9: =F9+Assumptions!$F$134*0.5 -> 0.4725 | H9: =G9+Assumptions!$F$134*0.5 -> 0.48 | I9: =H9+Assumptions!$F$134*0.5 -> 0.4875 | J9: =I9+Assumptions!$F$134*0.5 -> 0.495 | K9: =J9+Assumptions!$F$134*0.5 -> 0.5025 | L9: =K9+Assumptions!$F$134*0.5 -> 0.51
A10: Tier mix: % WHOOP Life | B10: % | D10: =Assumptions!$F$132 -> 0.25 | E10: =1-E8-E9 -> 0.2575 | F10: =1-F8-F9 -> 0.265 | G10: =1-G8-G9 -> 0.2725 | H10: =1-H8-H9 -> 0.28 | I10: =1-I8-I9 -> 0.2875 | J10: =1-J8-J9 -> 0.295 | K10: =1-K8-K9 -> 0.3025 | L10: =1-L8-L9 -> 0.31
A11: Sub ARPU before monthly premium | B11: $/yr | D11: =D8*199+D9*239+D10*359 -> 257 | E11: =E8*199+E9*239+E10*359 -> 258.5 | F11: =F8*199+F9*239+F10*359 -> 260 | G11: =G8*199+G9*239+G10*359 -> 261.5 | H11: =H8*199+H9*239+H10*359 -> 263 | I11: =I8*199+I9*239+I10*359 -> 264.5 | J11: =J8*199+J9*239+J10*359 -> 266 | K11: =K8*199+K9*239+K10*359 -> 267.5 | L11: =L8*199+L9*239+L10*359 -> 269
A12: Monthly-payer premium ($14 × monthly share) | B12: $/yr | D12: =Assumptions!$F$133*14 -> 1.68 | E12: =Assumptions!$F$133*14 -> 1.68 | F12: =Assumptions!$F$133*14 -> 1.68 | G12: =Assumptions!$F$133*14 -> 1.68 | H12: =Assumptions!$F$133*14 -> 1.68 | I12: =Assumptions!$F$133*14 -> 1.68 | J12: =Assumptions!$F$133*14 -> 1.68 | K12: =Assumptions!$F$133*14 -> 1.68 | L12: =Assumptions!$F$133*14 -> 1.68
A13: Sub ARPU (final) | B13: $/yr | D13: =D11+D12 -> 258.68 | E13: =(E11+E12)*(1+Assumptions!$F$26)^(E$5-$D$5) -> 267.9854 | F13: =(F11+F12)*(1+Assumptions!$F$26)^(F$5-$D$5) -> 277.61631 | G13: =(G11+G12)*(1+Assumptions!$F$26)^(G$5-$D$5) -> 287.58389 | H13: =(H11+H12)*(1+Assumptions!$F$26)^(H$5-$D$5) -> 297.89967 | I13: =(I11+I12)*(1+Assumptions!$F$26)^(I$5-$D$5) -> 308.57557 | J13: =(J11+J12)*(1+Assumptions!$F$26)^(J$5-$D$5) -> 319.62392 | K13: =(K11+K12)*(1+Assumptions!$F$26)^(K$5-$D$5) -> 331.05745 | L13: =(L11+L12)*(1+Assumptions!$F$26)^(L$5-$D$5) -> 342.88933
A15: 2. Advanced Labs ARPU (THE bucket-3 swing variable)
A16: Labs attach % | B16: % | D16: =Assumptions!$F$137*0.5 -> 0.05 | E16: =Assumptions!$F$137 -> 0.1 | F16: =E16*(1+Assumptions!$F$140) -> 0.109 | G16: =F16*(1+Assumptions!$F$140) -> 0.11881 | H16: =G16*(1+Assumptions!$F$140) -> 0.1295029 | I16: =H16*(1+Assumptions!$F$140) -> 0.14115816 | J16: =I16*(1+Assumptions!$F$140) -> 0.1538624 | K16: =J16*(1+Assumptions!$F$140) -> 0.16771001 | L16: =K16*(1+Assumptions!$F$140) -> 0.18280391
A17: Avg test price | B17: $ | D17: =Assumptions!$F$138 -> 250 | E17: =Assumptions!$F$138 -> 250 | F17: =E17 -> 250 | G17: =F17 -> 250 | H17: =G17 -> 250 | I17: =H17 -> 250 | J17: =I17 -> 250 | K17: =J17 -> 250 | L17: =K17 -> 250
A18: Tests per attached member | B18: tests/yr | D18: =Assumptions!$F$139 -> 1.5 | E18: =Assumptions!$F$139 -> 1.5 | F18: =E18 -> 1.5 | G18: =F18 -> 1.5 | H18: =G18 -> 1.5 | I18: =H18 -> 1.5 | J18: =I18 -> 1.5 | K18: =J18 -> 1.5 | L18: =K18 -> 1.5
A19: Launch-year scaling (2025 partial) | B19: factor | D19: 0.075 | E19: 1 | F19: 1 | G19: 1 | H19: 1 | I19: 1 | J19: 1 | K19: 1 | L19: 1
A20: Labs ARPU (attach × price × tests) | B20: $/yr | D20: =D16*D17*D18*D19 -> 1.40625 | E20: =E16*E17*E18*E19 -> 37.5 | F20: =F16*F17*F18*F19 -> 40.875 | G20: =G16*G17*G18*G19 -> 44.55375 | H20: =H16*H17*H18*H19 -> 48.563588 | I20: =I16*I17*I18*I19 -> 52.93431 | J20: =J16*J17*J18*J19 -> 57.698398 | K20: =K16*K17*K18*K19 -> 62.891254 | L20: =L16*L17*L18*L19 -> 68.551467
A22: 3. Accessories ARPU
A23: Accessories ARPU | B23: $/yr | D23: =Assumptions!$F$143 -> 18 | E23: =D23*(1+Assumptions!$F$144) -> 18.54 | F23: =E23*(1+Assumptions!$F$144) -> 19.0962 | G23: =F23*(1+Assumptions!$F$144) -> 19.669086 | H23: =G23*(1+Assumptions!$F$144) -> 20.259159 | I23: =H23*(1+Assumptions!$F$144) -> 20.866933 | J23: =I23*(1+Assumptions!$F$144) -> 21.492941 | K23: =J23*(1+Assumptions!$F$144) -> 22.13773 | L23: =K23*(1+Assumptions!$F$144) -> 22.801861
A25: 4. BP/Healthspan ARPU (paid add-on layer)
A26: BP/Healthspan attach % | B26: % | D26: 0 | E26: =Assumptions!$F$147 -> 0.05 | F26: =E26*(1+Assumptions!$F$149) -> 0.0575 | G26: =F26*(1+Assumptions!$F$149) -> 0.066125 | H26: =G26*(1+Assumptions!$F$149) -> 0.07604375 | I26: =H26*(1+Assumptions!$F$149) -> 0.087450312 | J26: =I26*(1+Assumptions!$F$149) -> 0.10056786 | K26: =J26*(1+Assumptions!$F$149) -> 0.11565304 | L26: =K26*(1+Assumptions!$F$149) -> 0.13300099
A27: BP/Healthspan add-on price | B27: $ | D27: 0 | E27: =Assumptions!$F$148 -> 100 | F27: =E27 -> 100 | G27: =F27 -> 100 | H27: =G27 -> 100 | I27: =H27 -> 100 | J27: =I27 -> 100 | K27: =J27 -> 100 | L27: =K27 -> 100
A28: BP/Healthspan ARPU | B28: $/yr | D28: =D26*D27 -> 0 | E28: =E26*E27 -> 5 | F28: =F26*F27 -> 5.75 | G28: =G26*G27 -> 6.6125 | H28: =H26*H27 -> 7.604375 | I28: =I26*I27 -> 8.7450312 | J28: =J26*J27 -> 10.056786 | K28: =K26*K27 -> 11.565304 | L28: =L26*L27 -> 13.300099
A30: 5. BLENDED ARPU (DERIVED)
A31: Sub ARPU | B31: $/yr | D31: =D13 -> 258.68 | E31: =E13 -> 267.9854 | F31: =F13 -> 277.61631 | G31: =G13 -> 287.58389 | H31: =H13 -> 297.89967 | I31: =I13 -> 308.57557 | J31: =J13 -> 319.62392 | K31: =K13 -> 331.05745 | L31: =L13 -> 342.88933
A32: + Labs ARPU | B32: $/yr | D32: =D20 -> 1.40625 | E32: =E20 -> 37.5 | F32: =F20 -> 40.875 | G32: =G20 -> 44.55375 | H32: =H20 -> 48.563588 | I32: =I20 -> 52.93431 | J32: =J20 -> 57.698398 | K32: =K20 -> 62.891254 | L32: =L20 -> 68.551467
A33: + Accessories ARPU | B33: $/yr | D33: =D23 -> 18 | E33: =E23 -> 18.54 | F33: =F23 -> 19.0962 | G33: =G23 -> 19.669086 | H33: =H23 -> 20.259159 | I33: =I23 -> 20.866933 | J33: =J23 -> 21.492941 | K33: =K23 -> 22.13773 | L33: =L23 -> 22.801861
A34: + BP/Healthspan ARPU | B34: $/yr | D34: =D28 -> 0 | E34: =E28 -> 5 | F34: =F28 -> 5.75 | G34: =G28 -> 6.6125 | H34: =H28 -> 7.604375 | I34: =I28 -> 8.7450312 | J34: =J28 -> 10.056786 | K34: =K28 -> 11.565304 | L34: =L28 -> 13.300099
A35: = Blended ARPU | B35: $/yr | D35: =SUM(D31:D34) -> 278.08625 | E35: =SUM(E31:E34) -> 329.0254 | F35: =SUM(F31:F34) -> 343.33751 | G35: =SUM(G31:G34) -> 358.41923 | H35: =SUM(H31:H34) -> 374.32679 | I35: =SUM(I31:I34) -> 391.12185 | J35: =SUM(J31:J34) -> 408.87204 | K35: =SUM(K31:K34) -> 427.65173 | L35: =SUM(L31:L34) -> 447.54275
A37: Consistency Check (vs. Assumptions R4 anchor)
A38: R4 anchor (2025 single-line ARPU) | B38: $/yr | D38: =Assumptions!$F$11 -> 338
A39: Derived (2025 sum of components) | B39: $/yr | D39: =D35 -> 278.08625
A40: Variance | B40: % | D40: =(D39-D38)/D38 -> -0.17725962
A41: Status | D41: =IF(ABS(D40)<=0.05,"✓ within ±5%","⚠ outside ±5% — reconcile R4 vs. component build") -> ⚠ outside ±5% — reconcile R4 vs. component build

Sheet Revenue Build
A1: WHOOP — Revenue Build-Up
A2: $M unless noted; Calendar Year
B5: Units | C5: 2024 | D5: 2025 | E5: 2026 | F5: 2027 | G5: 2028 | H5: 2029 | I5: 2030 | J5: 2031 | K5: 2032 | L5: 2033
C6: Historical | D6: Historical | E6: Phase 1 | F6: Phase 1 | G6: Phase 2 | H6: Phase 2 | I6: Phase 2 | J6: Phase 3 | K6: Phase 3 | L6: Phase 3
A8: 1. Member Economics (linked from Members tab)
A9: Beginning Members | B9: M | C9: =Members!C9 -> 0.7 | D9: =Members!D9 -> 1.3 | E9: =Members!E9 -> 2.5 | F9: =Members!F9 -> 2.9099858 | G9: =Members!G9 -> 3.7413302 | H9: =Members!H9 -> 4.4065901 | I9: =Members!I9 -> 5.222723 | J9: =Members!J9 -> 6.1448459 | ... L9: =Members!L9 -> 7.5677286
A10: Gross Adds | B10: M | C10: =Members!C31 -> 0.6 | D10: =Members!D31 -> 1.304 | E10: =Members!E31 -> 0.79254581 | F10: =Members!F31 -> 1.2361269 | G10: =Members!G31 -> 1.1747152 | H10: =Members!H31 -> 1.3909709 | I10: =Members!I31 -> 1.5896534 | J10: =Members!J31 -> 1.4373234 | ... L10: =Members!L31 -> 1.7033124
A11: Churned Members | B11: M | C11: =Members!C23 -> 0.135 | D11: =Members!D23 -> 0.104 | E11: =Members!E23 -> 0.38256 | F11: =Members!F23 -> 0.40478248 | G11: =Members!G23 -> 0.50945533 | H11: =Members!H23 -> 0.57483807 | I11: =Members!I23 -> 0.66753044 | J11: =Members!J23 -> 0.77923659 | ... L11: =Members!L23 -> 0.89453623
A12: Ending Members | B12: M | C12: =Members!C34 -> 1.165 | D12: =Members!D34 -> 2.5 | E12: =Members!E34 -> 2.9099858 | F12: =Members!F34 -> 3.7413302 | G12: =Members!G34 -> 4.4065901 | H12: =Members!H34 -> 5.222723 | I12: =Members!I34 -> 6.1448459 | J12: =Members!J34 -> 6.8029328 | ... L12: =Members!L34 -> 8.3765048
A13: Avg Members | B13: M | C13: =Members!C35 -> 0.9325 | D13: =Members!D35 -> 1.9 | E13: =Members!E35 -> 2.7049929 | F13: =Members!F35 -> 3.325658 | G13: =Members!G35 -> 4.0739602 | H13: =Members!H35 -> 4.8146565 | I13: =Members!I35 -> 5.6837844 | J13: =Members!J35 -> 6.4738894 | ... L13: =Members!L35 -> 7.9721167
A14: Blended Annual Churn (output) | B14: % | C14: =IFERROR(Members!C23/Members!C9, 0) -> 0.19285714 | D14: =IFERROR(Members!D23/Members!D9, 0) -> 0.08 | E14: =IFERROR(Members!E23/Members!E9, 0) -> 0.153024 | F14: =IFERROR(Members!F23/Members!F9, 0) -> 0.13910119 | G14: =IFERROR(Members!G23/Members!G9, 0) -> 0.13616957 | H14: =IFERROR(Members!H23/Members!H9, 0) -> 0.13044964 | I14: =IFERROR(Members!I23/Members!I9, 0) -> 0.12781272 | J14: =IFERROR(Members!J23/Members!J9, 0) -> 0.12681141 | ... L14: =IFERROR(Members!L23/Members!L9, 0) -> 0.11820406
A16: 2. ARPU (linked from ARPU tab)
A17: Blended ARPU | B17: $/yr | C17: =ARPU!C35 -> 0 | D17: =ARPU!D35 -> 278.08625 | E17: =ARPU!E35 -> 329.0254 | F17: =ARPU!F35 -> 343.33751 | G17: =ARPU!G35 -> 358.41923 | H17: =ARPU!H35 -> 374.32679 | I17: =ARPU!I35 -> 391.12185 | J17: =ARPU!J35 -> 408.87204 | ... L17: =ARPU!L35 -> 447.54275
A19: 3. Revenue Build
A20: Recognized Revenue (Total) | B20: $M | C20: =C13*C17 -> 0 | D20: =D13*D17 -> 528.36388 | E20: =E13*E17 -> 890.01137 | F20: =F13*F17 -> 1141.8232 | G20: =G13*G17 -> 1460.1857 | H20: =H13*H17 -> 1802.2549 | I20: =I13*I17 -> 2223.0523 | J20: =J13*J17 -> 2646.9924 | ... L20: =L13*L17 -> 3567.863
A21: Memo: Δ Deferred Rev Balance (flows to NWC, not P&L) | B21: $M | C21: =C20*Assumptions!$F$28 -> 0 | D21: =D20*Assumptions!$F$28 -> -42.26911 | E21: =E20*Assumptions!$F$28 -> -71.20091 | F21: =F20*Assumptions!$F$28 -> -91.345852 | G21: =G20*Assumptions!$F$28 -> -116.81485 | H21: =H20*Assumptions!$F$28 -> -144.18039 | I21: =I20*Assumptions!$F$28 -> -177.84418 | J21: =J20*Assumptions!$F$28 -> -211.75939 | ... L21: =L20*Assumptions!$F$28 -> -285.42904
A22: YoY Revenue Growth | B22: % | D22: =D20/C20-1 -> #DIV/0! | E22: =E20/D20-1 -> 0.68446674 | F22: =F20/E20-1 -> 0.28293097 | G22: =G20/F20-1 -> 0.27881945 | H22: =H20/G20-1 -> 0.23426424 | I22: =I20/H20-1 -> 0.23348381 | J22: =J20/I20-1 -> 0.19070181 | K22: =K20/J20-1 -> 0.16087192 | L22: =L20/K20-1 -> 0.16110415
A24: 4. Bookings Reconciliation
A25: Implied Bookings (End × ARPU) | B25: $M | C25: =C12*C17 -> 0 | D25: =D12*D17 -> 695.21563 | E25: =E12*E17 -> 957.45925 | F25: =F12*F17 -> 1284.539 | G25: =G12*G17 -> 1579.4066 | H25: =H12*H17 -> 1955.0051 | I25: =I12*I17 -> 2403.3835 | J25: =J12*J17 -> 2781.529 | ... L25: =L12*L17 -> 3748.844
A26: Bookings/Revenue Ratio | B26: x | C26: =IFERROR(C25/C20, 0) -> 0 | D26: =IFERROR(D25/D20, 0) -> 1.3157895 | E26: =IFERROR(E25/E20, 0) -> 1.0757832 | F26: =IFERROR(F25/F20, 0) -> 1.1249895 | G26: =IFERROR(G25/G20, 0) -> 1.0816478 | H26: =IFERROR(H25/H20, 0) -> 1.084755 | I26: =IFERROR(I25/I20, 0) -> 1.0811187 | J26: =IFERROR(J25/J20, 0) -> 1.0508262 | ... L26: =IFERROR(L25/L20, 0) -> 1.0507253
A27: 2025 Recognized vs Assumptions R1 (consistency) | B27: % | D27: =D20/Assumptions!$F$12-1 -> -0.17725962
A29: 5. Revenue by Component (feeds COGS on P&L)
A30: Subscription Revenue | B30: $M | C30: =C13*ARPU!C31 -> 0 | D30: =D13*ARPU!D31 -> 491.492 | E30: =E13*ARPU!E31 -> 724.89861 | F30: =F13*ARPU!F31 -> 923.25692 | G30: =G13*ARPU!G31 -> 1171.6053 | H30: =H13*ARPU!H31 -> 1434.2846 | I30: =I13*ARPU!I31 -> 1753.877 | J30: =J13*ARPU!J31 -> 2069.2099 | ... L30: =L13*ARPU!L31 -> 2733.5537
A31: Labs Revenue | B31: $M | C31: =C13*ARPU!C32 -> 0 | D31: =D13*ARPU!D32 -> 2.671875 | E31: =E13*ARPU!E32 -> 101.43723 | F31: =F13*ARPU!F32 -> 135.93627 | G31: =G13*ARPU!G32 -> 181.5102 | H31: =H13*ARPU!H32 -> 233.81699 | I31: =I13*ARPU!I32 -> 300.86721 | J31: =J13*ARPU!J32 -> 373.53305 | ... L31: =L13*ARPU!L32 -> 546.50029
A32: Accessories Revenue | B32: $M | C32: =C13*ARPU!C33 -> 0 | D32: =D13*ARPU!D33 -> 34.2 | E32: =E13*ARPU!E33 -> 50.150568 | F32: =F13*ARPU!F33 -> 63.507431 | G32: =G13*ARPU!G33 -> 80.131073 | H32: =H13*ARPU!H33 -> 97.54089 | I32: =I13*ARPU!I33 -> 118.60315 | J32: =J13*ARPU!J33 -> 139.14292 | ... L32: =L13*ARPU!L33 -> 181.7791
A33: BP/Healthspan Revenue | B33: $M | C33: =C13*ARPU!C34 -> 0 | D33: =D13*ARPU!D34 -> 0 | E33: =E13*ARPU!E34 -> 13.524965 | F33: =F13*ARPU!F34 -> 19.122534 | G33: =G13*ARPU!G34 -> 26.939062 | H33: =H13*ARPU!H34 -> 36.612454 | I33: =I13*ARPU!I34 -> 49.704873 | J33: =J13*ARPU!J34 -> 65.106519 | ... L33: =L13*ARPU!L34 -> 106.02994
A34: Memo: Components Sum | B34: $M | C34: =SUM(C30:C33) -> 0 | D34: =SUM(D30:D33) -> 528.36388 | E34: =SUM(E30:E33) -> 890.01137 | F34: =SUM(F30:F33) -> 1141.8232 | G34: =SUM(G30:G33) -> 1460.1857 | H34: =SUM(H30:H33) -> 1802.2549 | I34: =SUM(I30:I33) -> 2223.0523 | J34: =SUM(J30:J33) -> 2646.9924 | ... L34: =SUM(L30:L33) -> 3567.863
A35: Memo: Reconciliation vs row 19 | B35: % | C35: =IFERROR((C34-C20)/C20, 0) -> 0 | D35: =IFERROR((D34-D20)/D20, 0) -> 0 | E35: =IFERROR((E34-E20)/E20, 0) -> -1.2773639e-16 | F35: =IFERROR((F34-F20)/F20, 0) -> -1.9913213e-16 | G35: =IFERROR((G34-G20)/G20, 0) -> 1.5571559e-16 | H35: =IFERROR((H34-H20)/H20, 0) -> -2.5232132e-16 | I35: =IFERROR((I34-I20)/I20, 0) -> 0 | J35: =IFERROR((J34-J20)/J20, 0) -> 0 | ... L35: =IFERROR((L34-L20)/L20, 0) -> 1.274565e-16

Sheet P&L
A1: WHOOP — Projected Income Statement
A2: $M; Calendar Year; Scenario per Assumptions toggle
A3: Calibration items: see notes on F31 (2027 dip), L23 (S&M architecture). Margin tapers and NOL wired; refer to CalibrationLog for status.
B5: Units | C5: 2024 | D5: 2025 | E5: 2026 | F5: 2027 | G5: 2028 | H5: 2029 | I5: 2030 | J5: 2031 | K5: 2032 | L5: 2033
A7: Revenue
A8: Total Revenue | B8: $M | C8: ='Revenue Build'!C20 -> 0 | D8: ='Revenue Build'!D20 -> 528.36388 | E8: ='Revenue Build'!E20 -> 890.01137 | F8: ='Revenue Build'!F20 -> 1141.8232 | G8: ='Revenue Build'!G20 -> 1460.1857 | H8: ='Revenue Build'!H20 -> 1802.2549 | I8: ='Revenue Build'!I20 -> 2223.0523 | J8: ='Revenue Build'!J20 -> 2646.9924 | ... L8: ='Revenue Build'!L20 -> 3567.863 | M8: ← From Revenue Build tab
A9: YoY Growth | B9: % | D9: =IFERROR(D8/C8-1,0) -> 0 | E9: =E8/D8-1 -> 0.68446674 | F9: =F8/E8-1 -> 0.28293097 | G9: =G8/F8-1 -> 0.27881945 | H9: =H8/G8-1 -> 0.23426424 | I9: =I8/H8-1 -> 0.23348381 | J9: =J8/I8-1 -> 0.19070181 | K9: =K8/J8-1 -> 0.16087192 | L9: =L8/K8-1 -> 0.16110415
A11: Cost of Revenue
A12: Subscription COGS (% of sub rev) | B12: $M | D12: =('Revenue Build'!D30 + 'Revenue Build'!D32 + 'Revenue Build'!D33) * Assumptions!$F$33 -> 52.5692 | E12: =('Revenue Build'!E30 + 'Revenue Build'!E32 + 'Revenue Build'!E33) * Assumptions!$F$33 -> 78.857414 | F12: =('Revenue Build'!F30 + 'Revenue Build'!F32 + 'Revenue Build'!F33) * Assumptions!$F$33 -> 100.58869 | G12: =('Revenue Build'!G30 + 'Revenue Build'!G32 + 'Revenue Build'!G33) * Assumptions!$F$33 -> 127.86755 | H12: =('Revenue Build'!H30 + 'Revenue Build'!H32 + 'Revenue Build'!H33) * Assumptions!$F$33 -> 156.84379 | I12: =('Revenue Build'!I30 + 'Revenue Build'!I32 + 'Revenue Build'!I33) * Assumptions!$F$33 -> 192.21851 | J12: =('Revenue Build'!J30 + 'Revenue Build'!J32 + 'Revenue Build'!J33) * Assumptions!$F$33 -> 227.34593 | K12: =('Revenue Build'!K30 + 'Revenue Build'!K32 + 'Revenue Build'!K33) * Assumptions!$F$33 -> 262.09247 | L12: =('Revenue Build'!L30 + 'Revenue Build'!L32 + 'Revenue Build'!L33) * Assumptions!$F$33 -> 302.13628
A13: Hardware COGS (gross adds × loaded cost) | B13: $M | D13: =Members!D31 * Assumptions!$F$32 -> 156.48 | E13: =Members!E31 * Assumptions!$F$32 -> 95.105497 | F13: =Members!F31 * Assumptions!$F$32 -> 148.33523 | G13: =Members!G31 * Assumptions!$F$32 -> 140.96582 | H13: =Members!H31 * Assumptions!$F$32 -> 166.91651 | I13: =Members!I31 * Assumptions!$F$32 -> 190.75841 | J13: =Members!J31 * Assumptions!$F$32 -> 172.47881 | K13: =Members!K31 * Assumptions!$F$32 -> 190.15818 | L13: =Members!L31 * Assumptions!$F$32 -> 204.39749
A14: Total COGS | B14: $M | D14: =D12+D13+D19 -> 210.78592 | E14: =E12+E13+E19 -> 239.89711 | F14: =F12+F13+F19 -> 337.28249 | G14: =G12+G13+G19 -> 386.815 | H14: =H12+H13+H19 -> 475.74135 | I14: =I12+I13+I19 -> 578.5406 | J14: =J12+J13+J19 -> 642.62122 | K14: =K12+K13+K19 -> 745.98204 | L14: =L12+L13+L19 -> 861.75896
A15: Gross Profit | B15: $M | D15: =D8-D14 -> 317.57796 | E15: =E8-E14 -> 650.11426 | F15: =F8-F14 -> 804.54066 | G15: =G8-G14 -> 1073.3707 | H15: =H8-H14 -> 1326.5136 | I15: =I8-I14 -> 1644.5117 | J15: =J8-J14 -> 2004.3712 | K15: =K8-K14 -> 2326.8371 | L15: =L8-L14 -> 2706.1041
A16: Gross Margin | B16: % | D16: =D15/D8 -> 0.60105918 | E16: =E15/E8 -> 0.73045613 | F16: =F15/F8 -> 0.70461057 | G16: =G15/G8 -> 0.73509191 | H16: =H15/H8 -> 0.73602993 | I16: =I15/I8 -> 0.73975394 | J16: =J15/J8 -> 0.75722589 | K16: =K15/K8 -> 0.75723204 | L16: =L15/L8 -> 0.75846636
A17: Subscription GM | B17: % | D17: =IFERROR(('Revenue Build'!D30+'Revenue Build'!D32+'Revenue Build'!D33-D12)/('Revenue Build'!D30+'Revenue Build'!D32+'Revenue Build'!D33),0) -> 0.9 | E17: =IFERROR(('Revenue Build'!E30+'Revenue Build'!E32+'Revenue Build'!E33-E12)/('Revenue Build'!E30+'Revenue Build'!E32+'Revenue Build'!E33),0) -> 0.9 | F17: =IFERROR(('Revenue Build'!F30+'Revenue Build'!F32+'Revenue Build'!F33-F12)/('Revenue Build'!F30+'Revenue Build'!F32+'Revenue Build'!F33),0) -> 0.9 | G17: =IFERROR(('Revenue Build'!G30+'Revenue Build'!G32+'Revenue Build'!G33-G12)/('Revenue Build'!G30+'Revenue Build'!G32+'Revenue Build'!G33),0) -> 0.9 | H17: =IFERROR(('Revenue Build'!H30+'Revenue Build'!H32+'Revenue Build'!H33-H12)/('Revenue Build'!H30+'Revenue Build'!H32+'Revenue Build'!H33),0) -> 0.9 | I17: =IFERROR(('Revenue Build'!I30+'Revenue Build'!I32+'Revenue Build'!I33-I12)/('Revenue Build'!I30+'Revenue Build'!I32+'Revenue Build'!I33),0) -> 0.9 | J17: =IFERROR(('Revenue Build'!J30+'Revenue Build'!J32+'Revenue Build'!J33-J12)/('Revenue Build'!J30+'Revenue Build'!J32+'Revenue Build'!J33),0) -> 0.9 | K17: =IFERROR(('Revenue Build'!K30+'Revenue Build'!K32+'Revenue Build'!K33-K12)/('Revenue Build'!K30+'Revenue Build'!K32+'Revenue Build'!K33),0) -> 0.9 | L17: =IFERROR(('Revenue Build'!L30+'Revenue Build'!L32+'Revenue Build'!L33-L12)/('Revenue Build'!L30+'Revenue Build'!L32+'Revenue Build'!L33),0) -> 0.9 | M17: ← From Assumptions C2
A18: Hardware Margin $ memo (negative = device subsidy, see Sec 6) | B18: $M | D18: n/m | E18: =Members!E31 * ARPU!E33 - E13 -> -80.411698 | F18: =Members!F31 * ARPU!F33 - F13 -> -124.7299 | G18: =Members!G31 * ARPU!G33 - G13 -> -117.86025 | H18: =Members!H31 * ARPU!H33 - H13 -> -138.73661 | I18: =Members!I31 * ARPU!I33 - I13 -> -157.58722 | J18: =Members!J31 * ARPU!J33 - J13 -> -141.5865 | K18: =Members!K31 * ARPU!K33 - K13 -> -155.07759 | L18: =Members!L31 * ARPU!L33 - L13 -> -165.5588 | M18: ← From Assumptions C3
A19: Labs COGS (% of Labs rev) | B19: $M | D19: ='Revenue Build'!D31 * Assumptions!$F$51 -> 1.7367188 | E19: ='Revenue Build'!E31 * Assumptions!$F$51 -> 65.934202 | F19: ='Revenue Build'!F31 * Assumptions!$F$51 -> 88.358577 | G19: ='Revenue Build'!G31 * Assumptions!$F$51 -> 117.98163 | H19: ='Revenue Build'!H31 * Assumptions!$F$51 -> 151.98105 | I19: ='Revenue Build'!I31 * Assumptions!$F$51 -> 195.56369 | J19: ='Revenue Build'!J31 * Assumptions!$F$51 -> 242.79648 | K19: ='Revenue Build'!K31 * Assumptions!$F$51 -> 293.7314 | L19: ='Revenue Build'!L31 * Assumptions!$F$51 -> 355.22519
A20: Operating Expenses
A21: R&D | B21: $M | D21: =D8*Assumptions!$F$39 -> 116.24005 | E21: =E8*(Assumptions!$F$39 + (Assumptions!$F$40-Assumptions!$F$39)*(E$5-2026)/7) -> 195.8025 | F21: =F8*(Assumptions!$F$39 + (Assumptions!$F$40-Assumptions!$F$39)*(F$5-2026)/7) -> 239.78286 | G21: =G8*(Assumptions!$F$39 + (Assumptions!$F$40-Assumptions!$F$39)*(G$5-2026)/7) -> 292.03713 | H21: =H8*(Assumptions!$F$39 + (Assumptions!$F$40-Assumptions!$F$39)*(H$5-2026)/7) -> 342.42844 | I21: =I8*(Assumptions!$F$39 + (Assumptions!$F$40-Assumptions!$F$39)*(I$5-2026)/7) -> 400.14941 | J21: =J8*(Assumptions!$F$39 + (Assumptions!$F$40-Assumptions!$F$39)*(J$5-2026)/7) -> 449.9887 | K21: =K8*(Assumptions!$F$39 + (Assumptions!$F$40-Assumptions!$F$39)*(K$5-2026)/7) -> 491.65106 | L21: =L8*(Assumptions!$F$39 + (Assumptions!$F$40-Assumptions!$F$39)*(L$5-2026)/7) -> 535.17946
A22: R&D % Revenue | B22: % | D22: =D21/D8 -> 0.22 | E22: =E21/E8 -> 0.22 | F22: =F21/F8 -> 0.21 | G22: =G21/G8 -> 0.2 | H22: =H21/H8 -> 0.19 | I22: =I21/I8 -> 0.18 | J22: =J21/J8 -> 0.17 | K22: =K21/K8 -> 0.16 | L22: =L21/L8 -> 0.15 | M22: ← From Assumptions C7/C8
A23: Sales & Marketing | B23: $M | D23: =D8*Assumptions!$F$41 -> 158.50916 | E23: =Members!E47 -> 158.50916 | F23: =Members!F47 -> 267.00341 | G23: =Members!G47 -> 274.03756 | H23: =Members!H47 -> 350.44456 | I23: =Members!I47 -> 432.54118 | J23: =Members!J47 -> 422.37993 | K23: =Members!K47 -> 502.92855 | L23: =Members!L47 -> 583.83563
A24: S&M % Revenue | B24: % | D24: =D23/D8 -> 0.3 | E24: =E23/E8 -> 0.17809791 | F24: =F23/F8 -> 0.23383955 | G24: =G23/G8 -> 0.18767309 | H24: =H23/H8 -> 0.19444783 | I24: =I23/I8 -> 0.19457086 | J24: =J23/J8 -> 0.15956976 | K24: =K23/K8 -> 0.16367008 | L24: =L23/L8 -> 0.16363734 | M24: ← From Assumptions C9/C10
A25: General & Administrative | B25: $M | D25: =D8*Assumptions!$F$45 -> 79.254581 | E25: =E8*(Assumptions!$F$45 + (Assumptions!$F$46-Assumptions!$F$45)*(E$5-2026)/7) -> 133.50171 | F25: =F8*(Assumptions!$F$45 + (Assumptions!$F$46-Assumptions!$F$45)*(F$5-2026)/7) -> 164.74877 | G25: =G8*(Assumptions!$F$45 + (Assumptions!$F$46-Assumptions!$F$45)*(G$5-2026)/7) -> 202.34001 | H25: =H8*(Assumptions!$F$45 + (Assumptions!$F$46-Assumptions!$F$45)*(H$5-2026)/7) -> 239.44244 | I25: =I8*(Assumptions!$F$45 + (Assumptions!$F$46-Assumptions!$F$45)*(I$5-2026)/7) -> 282.64522 | J25: =J8*(Assumptions!$F$45 + (Assumptions!$F$46-Assumptions!$F$45)*(J$5-2026)/7) -> 321.4205 | K25: =K8*(Assumptions!$F$45 + (Assumptions!$F$46-Assumptions!$F$45)*(K$5-2026)/7) -> 355.56907 | L25: =L8*(Assumptions!$F$45 + (Assumptions!$F$46-Assumptions!$F$45)*(L$5-2026)/7) -> 392.46494
A26: G&A % Revenue | B26: % | D26: =D25/D8 -> 0.15 | E26: =E25/E8 -> 0.15 | F26: =F25/F8 -> 0.14428571 | G26: =G25/G8 -> 0.13857143 | H26: =H25/H8 -> 0.13285714 | I26: =I25/I8 -> 0.12714286 | J26: =J25/J8 -> 0.12142857 | K26: =K25/K8 -> 0.11571429 | L26: =L25/L8 -> 0.11 | M26: ← From Assumptions C11/C12
A27: Stock-Based Compensation | B27: $M | D27: =D8*Assumptions!$F$47 -> 73.970943 | E27: =E8*(Assumptions!$F$47 + (Assumptions!$F$48-Assumptions!$F$47)*(E$5-2026)/7) -> 124.60159 | F27: =F8*(Assumptions!$F$47 + (Assumptions!$F$48-Assumptions!$F$47)*(F$5-2026)/7) -> 150.06819 | G27: =G8*(Assumptions!$F$47 + (Assumptions!$F$48-Assumptions!$F$47)*(G$5-2026)/7) -> 179.39424 | H27: =H8*(Assumptions!$F$47 + (Assumptions!$F$48-Assumptions!$F$47)*(H$5-2026)/7) -> 205.97199 | I27: =I8*(Assumptions!$F$47 + (Assumptions!$F$48-Assumptions!$F$47)*(I$5-2026)/7) -> 235.00838 | J27: =J8*(Assumptions!$F$47 + (Assumptions!$F$48-Assumptions!$F$47)*(J$5-2026)/7) -> 257.1364 | K27: =K8*(Assumptions!$F$47 + (Assumptions!$F$48-Assumptions!$F$47)*(K$5-2026)/7) -> 272.16398 | L27: =L8*(Assumptions!$F$47 + (Assumptions!$F$48-Assumptions!$F$47)*(L$5-2026)/7) -> 285.42904
A28: SBC % Revenue | B28: % | D28: =D27/D8 -> 0.14 | E28: =E27/E8 -> 0.14 | F28: =F27/F8 -> 0.13142857 | G28: =G27/G8 -> 0.12285714 | H28: =H27/H8 -> 0.11428571 | I28: =I27/I8 -> 0.10571429 | J28: =J27/J8 -> 0.097142857 | K28: =K27/K8 -> 0.088571429 | L28: =L27/L8 -> 0.08 | M28: ← From Assumptions C13
A29: Total OpEx | B29: $M | D29: =D21+D23+D25+D27 -> 427.97474 | E29: =E21+E23+E25+E27 -> 612.41496 | F29: =F21+F23+F25+F27 -> 821.60323 | G29: =G21+G23+G25+G27 -> 947.80894 | H29: =H21+H23+H25+H27 -> 1138.2874 | I29: =I21+I23+I25+I27 -> 1350.3442 | J29: =J21+J23+J25+J27 -> 1450.9255 | K29: =K21+K23+K25+K27 -> 1622.3127 | L29: =L21+L23+L25+L27 -> 1796.9091
A31: Profitability
A32: EBITDA | B32: $M | D32: =D15-D29+D27 -> -36.42584 | E32: =E15-E29+E27 -> 162.30089 | F32: =F15-F29+F27 -> 133.00562 | G32: =G15-G29+G27 -> 304.95596 | H32: =H15-H29+H27 -> 394.19815 | I32: =I15-I29+I27 -> 529.17586 | J32: =J15-J29+J27 -> 810.58201 | K32: =K15-K29+K27 -> 976.6884 | L32: =L15-L29+L27 -> 1194.6241
A33: EBITDA Margin | B33: % | D33: =D32/D8 -> -0.068940822 | E33: =E32/E8 -> 0.18235822 | F33: =F32/F8 -> 0.1164853 | G33: =G32/G8 -> 0.20884739 | H33: =H32/H8 -> 0.21872496 | I33: =I32/I8 -> 0.23804022 | J33: =J32/J8 -> 0.30622756 | K33: =K32/K8 -> 0.31784767 | L33: =L32/L8 -> 0.33482901
A34: EBIT / Operating Income | B34: $M | D34: =D15-D29 -> -110.39678 | E34: =E15-E29 -> 37.699297 | F34: =F15-F29 -> -17.06257 | G34: =G15-G29 -> 125.56172 | H34: =H15-H29 -> 188.22615 | I34: =I15-I29 -> 294.16748 | J34: =J15-J29 -> 553.44561 | K34: =K15-K29 -> 704.52442 | L34: =L15-L29 -> 909.19502
A35: Operating Margin | B35: % | D35: =D34/D8 -> -0.20894082 | E35: =E34/E8 -> 0.042358219 | F35: =F34/F8 -> -0.014943268 | G35: =G34/G8 -> 0.085990243 | H35: =H34/H8 -> 0.10443925 | I35: =I34/I8 -> 0.13232594 | J35: =J34/J8 -> 0.2090847 | K35: =K34/K8 -> 0.22927624 | L35: =L34/L8 -> 0.25482901
A36: Rule of 40 Score | B36: # | D36: =(D9+D33)*100 -> -6.8940822 | E36: =(E9+E33)*100 -> 86.682496 | F36: =(F9+F33)*100 -> 39.941627 | G36: =(G9+G33)*100 -> 48.766684 | H36: =(H9+H33)*100 -> 45.29892 | I36: =(I9+I33)*100 -> 47.152403 | J36: =(J9+J33)*100 -> 49.692937 | K36: =(K9+K33)*100 -> 47.871959 | L36: =(L9+L33)*100 -> 49.593317 | M36: = Revenue Growth % + EBITDA Margin %
A38: Below the Line
A39: Interest Income / (Expense) | B39: $M | D39: ='WC & Cash'!$D$12*Assumptions!$F$67 -> 2.625 | E39: =('WC & Cash'!D33 + 'WC & Cash'!E13*0.5)*Assumptions!$F$67 -> 20.573467 | F39: ='WC & Cash'!E33*Assumptions!$F$67 -> 35.925826 | G39: ='WC & Cash'!F33*Assumptions!$F$67 -> 40.890032 | H39: ='WC & Cash'!G33*Assumptions!$F$67 -> 49.026588 | I39: ='WC & Cash'!H33*Assumptions!$F$67 -> 59.833222 | J39: ='WC & Cash'!I33*Assumptions!$F$67 -> 74.772358 | K39: ='WC & Cash'!J33*Assumptions!$F$67 -> 95.051872 | L39: ='WC & Cash'!K33*Assumptions!$F$67 -> 120.5887
A40: Pre-Tax Income | B40: $M | D40: =D34+D39 -> -107.77178 | E40: =E34+E39 -> 58.272764 | F40: =F34+F39 -> 18.863256 | G40: =G34+G39 -> 166.45175 | H40: =H34+H39 -> 237.25274 | I40: =I34+I39 -> 354.0007 | J40: =J34+J39 -> 628.21797 | K40: =K34+K39 -> 799.57629 | L40: =L34+L39 -> 1029.7837
A41: Taxes | B41: $M | D41: =MAX(0, D40-D48)*Assumptions!$F$52 -> 0 | E41: =MAX(0, E40-E48)*Assumptions!$F$52 -> 2.6805471 | F41: =MAX(0, F40-F48)*Assumptions!$F$52 -> 0.8677098 | G41: =MAX(0, G40-G48)*Assumptions!$F$52 -> 27.689421 | H41: =MAX(0, H40-H48)*Assumptions!$F$52 -> 54.56813 | I41: =MAX(0, I40-I48)*Assumptions!$F$52 -> 81.420161 | J41: =MAX(0, J40-J48)*Assumptions!$F$52 -> 144.49013 | K41: =MAX(0, K40-K48)*Assumptions!$F$52 -> 183.90255 | L41: =MAX(0, L40-L48)*Assumptions!$F$52 -> 236.85026
A42: Net Income | B42: $M | D42: =D40-D41 -> -107.77178 | E42: =E40-E41 -> 55.592217 | F42: =F40-F41 -> 17.995547 | G42: =G40-G41 -> 138.76233 | H42: =H40-H41 -> 182.68461 | I42: =I40-I41 -> 272.58054 | J42: =J40-J41 -> 483.72784 | K42: =K40-K41 -> 615.67375 | L42: =L40-L41 -> 792.93347
A43: Net Margin | B43: % | D43: =D42/D8 -> -0.20397266 | E43: =E42/E8 -> 0.062462366 | F43: =F42/F8 -> 0.015760362 | G43: =G42/G8 -> 0.095030608 | H43: =H42/H8 -> 0.10136447 | I43: =I42/I8 -> 0.12261544 | J43: =J42/J8 -> 0.18274621 | K43: =K42/K8 -> 0.20036121 | L43: =L42/L8 -> 0.22224325
A45: NOL Carryforward Schedule (post-TCJA, 80% utilization cap)
A46: Beginning NOL Balance | B46: $M | C46: 0 | D46: =C49 -> 0 | E46: =D49 -> 107.77178 | F46: =E49 -> 61.153572 | G46: =F49 -> 46.062966 | H46: =G49 -> 0 | I46: =H49 -> 0 | J46: =I49 -> 0 | K46: =J49 -> 0 | L46: =K49 -> 0
...

Sheet FCF
A1: WHOOP — FCF
A2: Free cash flow build. ΔNWC sourced from WC & Cash tab (detailed deferred-rev schedule).
B5: Units | C5: 2024 | D5: 2025 | E5: 2026 | F5: 2027 | G5: 2028 | H5: 2029 | I5: 2030 | J5: 2031 | K5: 2032 | L5: 2033
C6: Historical | D6: Historical | E6: Phase 1 | F6: Phase 1 | G6: Phase 2 | H6: Phase 2 | I6: Phase 2 | J6: Phase 3 | K6: Phase 3 | L6: Phase 3
A8: 1. EBIT to NOPAT
A9: EBIT | B9: $M | D9: ='P&L'!D34 -> -110.39678 | E9: ='P&L'!E34 -> 37.699297 | F9: ='P&L'!F34 -> -17.06257 | G9: ='P&L'!G34 -> 125.56172 | H9: ='P&L'!H34 -> 188.22615 | I9: ='P&L'!I34 -> 294.16748 | J9: ='P&L'!J34 -> 553.44561 | K9: ='P&L'!K34 -> 704.52442 | L9: ='P&L'!L34 -> 909.19502 | M9: = P&L EBIT (row 33)
A10: Less: Cash taxes on EBIT | B10: $M | D10: ='P&L'!D41 -> 0 | E10: ='P&L'!E41 -> 2.6805471 | F10: ='P&L'!F41 -> 0.8677098 | G10: ='P&L'!G41 -> 27.689421 | H10: ='P&L'!H41 -> 54.56813 | I10: ='P&L'!I41 -> 81.420161 | J10: ='P&L'!J41 -> 144.49013 | K10: ='P&L'!K41 -> 183.90255 | L10: ='P&L'!L41 -> 236.85026 | M10: = P&L Cash Taxes (row 40), tax-affected at effective rate
A11: NOPAT | B11: $M | D11: =D9-D10 -> -110.39678 | E11: =E9-E10 -> 35.01875 | F11: =F9-F10 -> -17.93028 | G11: =G9-G10 -> 97.872299 | H11: =H9-H10 -> 133.65802 | I11: =I9-I10 -> 212.74732 | J11: =J9-J10 -> 408.95548 | K11: =K9-K10 -> 520.62187 | L11: =L9-L10 -> 672.34476 | M11: = EBIT − Cash Taxes
A13: 2. NOPAT to Unlevered FCF
A14: Plus: D&A | B14: $M | D14: ='P&L'!D8*Assumptions!$F$53 -> 18.492736 | E14: ='P&L'!E8*Assumptions!$F$53 -> 31.150398 | F14: ='P&L'!F8*Assumptions!$F$53 -> 39.96381 | G14: ='P&L'!G8*Assumptions!$F$53 -> 51.106498 | H14: ='P&L'!H8*Assumptions!$F$53 -> 63.078923 | I14: ='P&L'!I8*Assumptions!$F$53 -> 77.80683 | J14: ='P&L'!J8*Assumptions!$F$53 -> 92.644733 | K14: ='P&L'!K8*Assumptions!$F$53 -> 107.54867 | L14: ='P&L'!L8*Assumptions!$F$53 -> 124.87521 | M14: = Revenue × D&A % (Assumptions F52)
A15: Less: CapEx | B15: $M | D15: =-'P&L'!D8*Assumptions!$F$49 -> -21.134555 | E15: =-'P&L'!E8*Assumptions!$F$49 -> -35.600455 | F15: =-'P&L'!F8*Assumptions!$F$49 -> -45.672926 | G15: =-'P&L'!G8*Assumptions!$F$49 -> -58.407426 | H15: =-'P&L'!H8*Assumptions!$F$49 -> -72.090197 | I15: =-'P&L'!I8*Assumptions!$F$49 -> -88.922091 | J15: =-'P&L'!J8*Assumptions!$F$49 -> -105.87969 | K15: =-'P&L'!K8*Assumptions!$F$49 -> -122.91277 | L15: =-'P&L'!L8*Assumptions!$F$49 -> -142.71452 | M15: = −(Revenue × CapEx %) (Assumptions F48)
A16: Less: Change in NWC | B16: $M | D16: ='WC & Cash'!D26 -> 338.35194 | E16: ='WC & Cash'!E26 -> 120.57015 | F16: ='WC & Cash'!F26 -> 165.47383 | G16: ='WC & Cash'!G26 -> 141.90166 | H16: ='WC & Cash'!H26 -> 184.11422 | I16: ='WC & Cash'!I26 -> 225.20042 | J16: ='WC & Cash'!J26 -> 183.69416 | K16: ='WC & Cash'!K26 -> 224.36592 | L16: ='WC & Cash'!L26 -> 253.26978 | M16: = From WC & Cash tab (Section 3, Total ΔNWC)
A17: Note: SBC is REAL COST in P&L — do NOT add back | M17: Per methodology Sec 6 — SBC stays in P&L as cash-equivalent expense
A18: Unlevered Free Cash Flow | B18: $M | D18: =D11+D14+D15+D16 -> 225.31334 | E18: =E11+E14+E15+E16 -> 151.13884 | F18: =F11+F14+F15+F16 -> 141.83444 | G18: =G11+G14+G15+G16 -> 232.47303 | H18: =H11+H14+H15+H16 -> 308.76097 | I18: =I11+I14+I15+I16 -> 426.83248 | J18: =J11+J14+J15+J16 -> 579.41467 | K18: =K11+K14+K15+K16 -> 729.6237 | L18: =L11+L14+L15+L16 -> 907.77523 | M18: = NOPAT + D&A + CapEx + ΔNWC
A20: 3. FCF Diagnostics
A21: FCF Margin % | B21: % | D21: =IFERROR(D18/'P&L'!D8,0) -> 0.42643593 | E21: =IFERROR(E18/'P&L'!E8,0) -> 0.16981675 | F21: =IFERROR(F18/'P&L'!F8,0) -> 0.12421752 | G21: =IFERROR(G18/'P&L'!G8,0) -> 0.15920786 | H21: =IFERROR(H18/'P&L'!H8,0) -> 0.17131925 | I21: =IFERROR(I18/'P&L'!I8,0) -> 0.1920029 | J21: =IFERROR(J18/'P&L'!J8,0) -> 0.21889548 | K21: =IFERROR(K18/'P&L'!K8,0) -> 0.2374444 | L21: =IFERROR(L18/'P&L'!L8,0) -> 0.25443107 | M21: FCF / Revenue
A22: Rule of 40 (Growth + FCF Margin) | B22: % | E22: =IFERROR(('P&L'!E8/'P&L'!D8-1)*100 + E21*100,0) -> 85.428349 | F22: =IFERROR(('P&L'!F8/'P&L'!E8-1)*100 + F21*100,0) -> 40.714849 | G22: =IFERROR(('P&L'!G8/'P&L'!F8-1)*100 + G21*100,0) -> 43.802731 | H22: =IFERROR(('P&L'!H8/'P&L'!G8-1)*100 + H21*100,0) -> 40.558349 | I22: =IFERROR(('P&L'!I8/'P&L'!H8-1)*100 + I21*100,0) -> 42.54867 | J22: =IFERROR(('P&L'!J8/'P&L'!I8-1)*100 + J21*100,0) -> 40.959729 | K22: =IFERROR(('P&L'!K8/'P&L'!J8-1)*100 + K21*100,0) -> 39.831633 | L22: =IFERROR(('P&L'!L8/'P&L'!K8-1)*100 + L21*100,0) -> 41.553523 | M22: Revenue Growth % + FCF Margin %

Sheet WC & Cash
A1: WHOOP — Working Capital & Cash Roll-Forward
A2: $M; pre-IPO (no debt service / dividends / buybacks). Replaces FCF-tab ΔNWC plug with explicit WC build.
A3: Detailed WC schedule wired into FCF tab as of this session. DCF EV impact: +$813M.
B5: Units | C5: 2024 | D5: 2025 | E5: 2026 | F5: 2027 | G5: 2028 | H5: 2029 | I5: 2030 | J5: 2031 | K5: 2032 | L5: 2033
A7: 1. Drivers
A8: Avg months remaining on annual sub (deferred rev) | B8: mo | D8: 6
A9: Inventory days (gross adds device cost) | B9: days | D9: 45
A10: Accounts payable days (% of total COGS) | B10: days | D10: 18
A11: Other NWC (% of revenue) | B11: % | D11: 0.015
A12: Pre-existing cash balance (start 2025) | B12: $M | D12: 75
A13: Series G proceeds (closed Mar 2026) | B13: $M | D13: 0 | E13: 575
A15: 2. Working Capital Balances (Liabilities = Source / Assets = Use)
A16: Deferred Revenue (= End Members × ARPU × mo/12) | B16: $M | C16: 0 | D16: =Members!D34*ARPU!D35*$D$8/12 -> 347.60781 | E16: =Members!E34*ARPU!E35*$D$8/12 -> 478.72962 | F16: =Members!F34*ARPU!F35*$D$8/12 -> 642.26951 | G16: =Members!G34*ARPU!G35*$D$8/12 -> 789.70331 | H16: =Members!H34*ARPU!H35*$D$8/12 -> 977.50257 | I16: =Members!I34*ARPU!I35*$D$8/12 -> 1201.6917 | J16: =Members!J34*ARPU!J35*$D$8/12 -> 1390.7645 | K16: =Members!K34*ARPU!K35*$D$8/12 -> 1618.1761 | L16: =Members!L34*ARPU!L35*$D$8/12 -> 1874.422
A17: Inventory (= ~45 days of NEXT-yr hardware COGS) | B17: $M | C17: 0 | D17: ='P&L'!E13*$D$9/365 -> 11.725335 | E17: ='P&L'!F13*$D$9/365 -> 18.287905 | F17: ='P&L'!G13*$D$9/365 -> 17.379348 | G17: ='P&L'!H13*$D$9/365 -> 20.578748 | H17: ='P&L'!I13*$D$9/365 -> 23.51816 | I17: ='P&L'!J13*$D$9/365 -> 21.264511 | J17: ='P&L'!K13*$D$9/365 -> 23.444159 | K17: ='P&L'!L13*$D$9/365 -> 25.199691 | L17: =K17*1.05 -> 26.459675
A18: Accounts Payable (= ~18 days of total COGS) | B18: $M | C18: 0 | D18: ='P&L'!D14*$D$10/365 -> 10.394922 | E18: ='P&L'!E14*$D$10/365 -> 11.830543 | F18: ='P&L'!F14*$D$10/365 -> 16.633109 | G18: ='P&L'!G14*$D$10/365 -> 19.075808 | H18: ='P&L'!H14*$D$10/365 -> 23.461217 | I18: ='P&L'!I14*$D$10/365 -> 28.530769 | J18: ='P&L'!J14*$D$10/365 -> 31.69091 | K18: ='P&L'!K14*$D$10/365 -> 36.788156 | L18: ='P&L'!L14*$D$10/365 -> 42.497702
A19: Other NWC (= 1.5% of revenue) | B19: $M | C19: 0 | D19: ='P&L'!D8*$D$11 -> 7.9254581 | E19: ='P&L'!E8*$D$11 -> 13.350171 | F19: ='P&L'!F8*$D$11 -> 17.127347 | G19: ='P&L'!G8*$D$11 -> 21.902785 | H19: ='P&L'!H8*$D$11 -> 27.033824 | I19: ='P&L'!I8*$D$11 -> 33.345784 | J19: ='P&L'!J8*$D$11 -> 39.704886 | K19: ='P&L'!K8*$D$11 -> 46.092287 | L19: ='P&L'!L8*$D$11 -> 53.517946
A21: 3. Change in WC (positive = cash source)
A22: Δ Deferred Revenue (liability ↑ = source) | B22: $M | D22: =D16-C16 -> 347.60781 | E22: =E16-D16 -> 131.12181 | F22: =F16-E16 -> 163.53989 | G22: =G16-F16 -> 147.4338 | H22: =H16-G16 -> 187.79926 | I22: =I16-H16 -> 224.18918 | J22: =J16-I16 -> 189.07276 | K22: =K16-J16 -> 227.41161 | L22: =L16-K16 -> 256.24588
A23: Δ Inventory (asset ↑ = use) | B23: $M | D23: =-(D17-C17) -> -11.725335 | E23: =-(E17-D17) -> -6.5625696 | F23: =-(F17-E17) -> 0.90855709 | G23: =-(G17-F17) -> -3.1994004 | H23: =-(H17-G17) -> -2.9394119 | I23: =-(I17-H17) -> 2.2536492 | J23: =-(J17-I17) -> -2.179648 | K23: =-(K17-J17) -> -1.7555317 | L23: =-(L17-K17) -> -1.2599845
A24: Δ Accounts Payable (liability ↑ = source) | B24: $M | D24: =D18-C18 -> 10.394922 | E24: =E18-D18 -> 1.4356206 | F24: =F18-E18 -> 4.8025667 | G24: =G18-F18 -> 2.4426989 | H24: =H18-G18 -> 4.3854093 | I24: =I18-H18 -> 5.0695521 | J24: =J18-I18 -> 3.1601402 | K24: =K18-J18 -> 5.0972459 | L24: =L18-K18 -> 5.7095465
A25: Δ Other NWC (asset ↑ = use) | B25: $M | D25: =-(D19-C19) -> -7.9254581 | E25: =-(E19-D19) -> -5.4247125 | F25: =-(F19-E19) -> -3.7771767 | G25: =-(G19-F19) -> -4.7754376 | H25: =-(H19-G19) -> -5.1310392 | I25: =-(I19-H19) -> -6.3119601 | J25: =-(J19-I19) -> -6.3591015 | K25: =-(K19-J19) -> -6.3874013 | L25: =-(L19-K19) -> -7.4256588
A26: Total Δ NWC (cash impact) | B26: $M | D26: =SUM(D22:D25) -> 338.35194 | E26: =SUM(E22:E25) -> 120.57015 | F26: =SUM(F22:F25) -> 165.47383 | G26: =SUM(G22:G25) -> 141.90166 | H26: =SUM(H22:H25) -> 184.11422 | I26: =SUM(I22:I25) -> 225.20042 | J26: =SUM(J22:J25) -> 183.69416 | K26: =SUM(K22:K25) -> 224.36592 | L26: =SUM(L22:L25) -> 253.26978
A28: 4. Cash Roll-Forward (pre-IPO; no debt service / dividends / buybacks)
A29: Beginning Cash | B29: $M | D29: =$D$12 -> 75 | E29: =D33 -> 300.31334 | F29: =E33 -> 1026.4522 | G29: =F33 -> 1168.2866 | H29: =G33 -> 1400.7597 | I29: =H33 -> 1709.5206 | J29: =I33 -> 2136.3531 | K29: =J33 -> 2715.7678 | L29: =K33 -> 3445.3915
A30: + Series G proceeds | B30: $M | D30: =$D$13 -> 0 | E30: =$E$13 -> 575
A31: + Unlevered Free Cash Flow (FCF tab) | B31: $M | D31: =FCF!D18 -> 225.31334 | E31: =FCF!E18 -> 151.13884 | F31: =FCF!F18 -> 141.83444 | G31: =FCF!G18 -> 232.47303 | H31: =FCF!H18 -> 308.76097 | I31: =FCF!I18 -> 426.83248 | J31: =FCF!J18 -> 579.41467 | K31: =FCF!K18 -> 729.6237 | L31: =FCF!L18 -> 907.77523
A33: Ending Cash | B33: $M | D33: =D29+D30+D31 -> 300.31334 | E33: =E29+E30+E31 -> 1026.4522 | F33: =F29+F31 -> 1168.2866 | G33: =G29+G31 -> 1400.7597 | H33: =H29+H31 -> 1709.5206 | I33: =I29+I31 -> 2136.3531 | J33: =J29+J31 -> 2715.7678 | K33: =K29+K31 -> 3445.3915 | L33: =L29+L31 -> 4353.1667
A40: Beginning Cash | B40: $M | D40: =$D$12 -> 75 | E40: =D44 -> 300.31334 | F40: =E44 -> 1026.4522 | G40: =F44 -> 1168.2866 | H40: =G44 -> 1400.7597 | I40: =H44 -> 1709.5206 | J40: =I44 -> 2136.3531 | K40: =J44 -> 2715.7678 | L40: =K44 -> 3445.3915
A41: + Series G proceeds | B41: $M | D41: =$D$13 -> 0 | E41: =$E$13 -> 575
A42: + UFCF rebuilt: NOPAT + D&A + CapEx + DETAILED ΔNWC | B42: $M | D42: =FCF!D11+FCF!D14+FCF!D15+D26 -> 225.31334 | E42: =FCF!E11+FCF!E14+FCF!E15+E26 -> 151.13884 | F42: =FCF!F11+FCF!F14+FCF!F15+F26 -> 141.83444 | G42: =FCF!G11+FCF!G14+FCF!G15+G26 -> 232.47303 | H42: =FCF!H11+FCF!H14+FCF!H15+H26 -> 308.76097 | I42: =FCF!I11+FCF!I14+FCF!I15+I26 -> 426.83248 | J42: =FCF!J11+FCF!J14+FCF!J15+J26 -> 579.41467 | K42: =FCF!K11+FCF!K14+FCF!K15+K26 -> 729.6237 | L42: =FCF!L11+FCF!L14+FCF!L15+L26 -> 907.77523
