Workbook
Name Scenario: Assumptions!$B$3

Sheet Claude Log
A1: Turn | B1: Date | C1: User Request | D1: Action Taken | E1: Details | F1: Outcome
A2: 1 | B2: 46149 | C2: Continue Member Thesis full rebuild in Comps idiom (sections 2-11). | D2: Built Sections 2-11 from scratch with Comps style fingerprint applied throughout. Wiped sheet, rebuilt with calculator-panel anchors, navy banners, alt zebra rows, peach/blue/green lens tints, horizontal Lens C, composite span, trajectory build, cross-checks, Series G back-solve, key findings. | E2: Lens tints: A=peach #FCE4D6 (aggressive), B/C=blue #DDEBF7 (base), D=green #E2EFDA (disciplined floor). Math chain reproduces all prior values: B16=11.954 (Lens A), B17=11.209 (B), B18=10.625 (C), B19=8.379 (D), B20=10.917 (median), J93=10.918 (trajectory), B103=+0.06% (cross-check). New diagnostic: B112=15.03M Series G implied members (proxy), B113=+25.7% above Lens A ceiling. | F2: Member Thesis fully rebuilt: 11 sections, 125 rows. DCF unchanged ($17.89/sh). Memo-ready. Awaiting user review.
A3: 2 | B3: 46149 | C3: Get sizes equivalent from Comps to Member Thesis — heights, zoom, columns don't look parallel. | D3: Read actual Comps column widths + row heights via Office.js. Decoded the 4-tier row height pattern (title 28pt / subtitle 36pt / banners 22pt / intros 30pt / body 15pt). Applied Comps-equivalent sizing to Member Thesis. Also fixed broken §2 Convergence formulas (B16:B19 were empty) and downstream Assumptions!F179 reference (was pointing at obsolete B11, now B20). | E3: Comps col widths: A=320, B-F=95 uniform, J=380 (wide notes). Member Thesis adapted: A=320, B=95, C/D=75, E/G/I/K=160 (Lens C horizontal blocks), H/L=15 gutters, M=380 (mirrors Comps J wide notes). Row tiers: 28/36/22/30/22/15. Wire-ups: B16=B30, B17=B43, B18=B67, B19=B78. Repointed Assumptions!F179 from B11 to B20. | F3: Sheets now parallel in size rhythm. Math chain restored: B20=10.917M lens median, F179=+0.06% triangulation, DCF $17.89/sh.
A4: 3 | B4: 46149 | C4: Build probability-weighted DCF capability: add ProbWeighted scenario as 4th option that weights 16 high-leverage inputs at the input level (P_Bear×Bear + P_Base×Base + P_Bull×Bull) rather than at scenario level, to avoid joint-extreme overstatement of tail dispersion. Also fix R79 Bear-branch bug. | D4: Unmerged Assumptions!A2:N2 (was a single merged cell blocking writes). Built probability weight cells in row 2 (B2-I2: P_Bear=20%, P_Base=50%, P_Bull=30%, sum check with red-fill conditional format if ≠1). Added ProbWeighted column at J for 16 inputs (R19-21 churn, R36-38 GMs, R73 CSRP, R79 terminal multiple, R169-176 MG1-MG8). Fixed R79 Bear-branch bug (was pointing to D79 Base 3.5x; now correctly C79 Bear 3.0x). Updated Active formulas on all 16 rows to handle ProbWeighted branch. Extended B3 dropdown to 4 options (Bear/Base/Bull/ProbWeighted). Added DCF tab guardrail block at rows 56-74: 4-scenario EV snapshot, scenario-weighted bookend (P-weighted DCF runs), and Jensen gap analysis. | E4: ProbWeighted formula: =$C$2*C[row]+$E$2*D[row]+$G$2*E[row] (absolute refs on weight cells). Active formula: =IF($B$3="Bear",C[r],IF($B$3="Bull",E[r],IF($B$3="ProbWeighted",J[r],D[r]))). 16 cells touched: F19,F20,F21,F36,F37,F38,F73,F79,F169-F176. R79 bug delta on Bear: -$191M EV (terminal multiple correctly 3.0x not 3.5x). Notes column at I preserved untouched — used column J instead to avoid disturbing audit trail. DCF guardrails snapshot is STATIC values — refresh manually if any of the 16 inputs change materially. | F4: All 4 scenarios run cleanly. Bear=$2.50B equity / $2.66B w/opts, Base=$7.34B / $8.28B, Bull=$19.88B / $22.60B, ProbWeighted=$7.96B / $8.90B (closes ~$626M of $1.82B gap to Series G). Major finding: Jensen gap = +$2.15B (29.7%) — DCF strongly convex in inputs. Scenario-weighted equity ($10.13B) hits Series G ($10.10B) almost exactly. Memo narrative now: input-weighted = central tendency under independence, scenario-weighted = E[EV] under perfect correlation, Series G sits between (partial correlation). The Jensen gap IS the optionality premium. R79 bug fix dropped Bear EV by $191M as expected. No #REF/#VALUE/#NAME errors introduced. F179 #DIV/0! preserved as expected (Member Thesis B20 blank during rebuild).
A5: 4 | B5: 46149 | C5: Push ProbWeighted scenario through entire memo — documentation, Cover, Football Field, Sensitivity, Scenarios, Checks. Style anchor to Comps + WACC Bottom-Up. Cover snapshot live on B3 toggle. | D5: (1) Assumptions Section 13 doc at row 181 (header banner, weights table linked to row 2, eligible-inputs table, Jensen caveat, refresh protocol). (2) Cover triangulation block at B63-C77 (live deps to DCF rows 60-65, Bear/Base/Bull/ProbWeighted/Scenario-Wtd/Series G/Jensen Gap; memo read narrative). (3) Cover B60/B61 narrative updated for new outputs. (4) Football Field K6 footnote on DCF row — NOT a new method line. (5) Sensitivity Section 5 prob-weight grid (5×5 P_Bear×P_Bull, base case yellow center, range $7.27-8.36B). (6) Scenarios fully populated: 6-method table with live links (DCF, Comps, Series G, IPO range), ProbWeighted column, Probability Weight Sensitivity block (3 schemes × Scenario-Wtd vs ProbWeighted vs Jensen Gap vs Series G). (7) Checks row 16: Check 12 weight-sum integrity, summary formulas expanded D5:D16. (8) Retried C3 description (had not persisted previously) — success on second attempt. | E5: Style fingerprint applied uniformly: Title bold 14-16pt white on #2F5496/#1F4E78; Subtitle italic 9-11pt #595959; Section banner bold 12pt white on #1F4E78; Table header bold 11pt black on #D9E1F2; Data 11pt black with #0000FF for inputs; Number formats $#,##0 / 0.0%/ 0.0"x" / +0.00;-0.00;0.00 deltas; Yellow #FFF2CC base case; #E2EFDA scenario-wtd; #FCE4D6 Jensen gap. Cover triangulation cells C67-C73 = LIVE formulas reading DCF!C60-C63 (single source of truth, refresh DCF and everything updates). DCF rows 60-63 themselves are STATIC — manually refreshed via validation pass. Sensitivity grid B67:F71 generated via Office.js auto-toggling P_Bear/P_Bull/P_Base across 5×5 grid (running ProbWeighted + recalc each time), base case D69 yellow. | F5: All decisions executed. ProbWeighted now end-to-end: docs (Assumptions row 181), Cover narrative + triangulation, Football Field footnote, Sensitivity grid, Scenarios full table, Checks weight-sum. Live test confirms toggling B3 to ProbWeighted updates Cover C34, C39 ($7.96B), C40 per-share. Memo narrative locked: input-weighted ($7.96B) = conservative anchor under input independence; scenario-weighted ($10.13B) = upper anchor at perfect correlation hits Series G almost exactly; Series G ($10.10B) reflects partial correlation; Jensen gap ($2.17B / +27%) IS the optionality premium. Checks 12/12 (11 PASS, 1 WARN). Open items flagged: Cover C43 has pre-existing label/formula mismatch (says 'Total Equity + Options' but formula reads DCF!C47 = EV+Options); RealOptions tab does not differentiate Base from ProbWeighted (both return $940M).
A8: 7 | B8: 46149 | C8: Reviewed Sensitivity tab: validity of formulaic approach, accuracy of F54-F58 churn approximation tooltip, whether Grid 4 should recompute against live DCF, whether ±100bps WACC range is wide enough | D8: Audited Sensitivity tab against live DCF and Cover; identified two real reconciliation issues | E8: Confirmed: (1) formulaic SUMPRODUCT-based grids are correct architecture (live DCF would lock all cells to one scenario); (2) F54-F58 'directional only' tooltip is accurate — formula is linear approx scaled 5x, doesn't capture compounding; (3) Grid 4 should add EV column for IC relevance; (4) WACC range too narrow on the low side (Series G implied WACC <10.85% can't be reached). Found Cover!C43 still pulling DCF!C47 ($7,557M EV) but labeled 'Total Equity + Options' (should be DCF!C51 = $8,276M). Found Sensitivity!E9 = $9.51B EV at base, but DCF base equity = $7.34B — narrative in A2 says $10.23B equity, which doesn't tie to live DCF. | F8: Findings delivered to user with P1/P2/P3 prioritization. Awaiting decision on whether to execute fixes (Cover C43 ref change, Sensitivity A2 reconciliation, Grid 1 WACC range extension, Grid 4 EV column).
A9: 8 | B9: 46149 | C9: Approved Sensitivity tab rework: Grids stale with WACC/exit, Section 5 base wrong (showed 11.24M instead of 10.92M base members). Asked to rework Section 5 to match Grid 1-3 conventional (label-row + label-column + grid) format used by other grids. | D9: Full rebuild of Sensitivity rows 5-86: Grid 1/2/3/3b headers re-centered on live base values (WACC 11.59%, Exit Mult 3.5x, Term Growth 2.5%, Beta 0.83, CSRP 2%); base cells highlighted yellow. Grid 4 expanded with EV columns and live formulas. Section 5 (Probability Weighting + Members Lens) completely rebuilt as conventional grids with live DCF ties. | E9: Grid 1 (WACC×Exit Mult): A6:A12 = 10.09-13.09% step 50bps base 11.59% at A9 yellow; B5:H5 = 2.0-5.0x step 0.5x base 3.5x at E5 yellow. Grid 1 base E9 = $7.45B (pure Exit Mult). Grid 2 (WACC×Term Growth): A16:A22 same WACC; B16:F16 = 1.5-4.5% base 2.5% at D16. Grid 2 base D20 = $5.54B (pure Gordon). Grid 3 (Beta×CSRP top-down WACC) and Grid 3b (EV at top-down WACC × 3.5x exit): A28-A32 = 0.70/0.83/1.00/1.20/1.40 base 0.83; B27:F27 = 1.0-3.0% base 2% at D27. Grid 3 base D29 = 10.85% (top-down). Grid 3b base D37 = $7.80B EV. Grid 4 summary: B43:D43 EV columns (Low/Base/High by method using all three grid bases). Section 5 Block 1 (rows 63-72): 5×5 P_Bear×P_Bull grid using formula =$A66*DCF!$C$60+B$65*DCF!$C$62+(1-$A66-B$65)*DCF!$C$61. Base D68 = $10.13B = scenario-weighted bookend, NOT input-weighted $7.96B (caveat in A64). Section 5 Block 2 (rows 73-83): 6 rows of member counts centered on Members!L34=10.92M base at row 80 yellow (range 8.4-14.5M = -23%/+33% vs base). Block A: EV from FCF margin held constant. Block B: margin coupled ±60bps per ±10% members from base. Base D80=E80=$7,336M = DCF!C38. G80=$17.89/sh = DCF!C40. Coupled-bull G83=$25.22 (ONLY path > Series G $24.63). All formulas live: pull from DCF!K8/K9/K10/C32/C36/C37/C38/C39/C60/C61/C62 and Members!L34. Methodology footnote at A88. Section 5 narrative A85 reads live ($9.0/sh swing, coupling adds $2.04 at bull, subtracts $0.84 at floor). | F9: Sensitivity tab live and audit-clean. Tie-out: E9=$7.45B (Grid 1 Exit Mult @ live WACC/Mult), D20=$5.54B (Grid 2 Gordon), D37=$7.80B (Grid 3b top-down), D68=$10.13B (Block 1 scenario-weighted bookend), D80=$7,336M = DCF!C38, G80=$17.89=DCF!C40. Methodology gaps documented in caveats. Open: Cover!C43 label/formula mismatch (deferred, low priority). Awaiting next direction.
A10: 9 | B10: 46149 | C10: Reviewer (committee/IC) pushed back on RealOptions: Bull case is consumer-driven not healthcare-driven, comps multiple already prices implicit option premium (double-counting risk), and what if medical pathway doesn't materialize — ARPU defense needed. Asked to (a) add scenario-weighted line, (b) sensitivity grid scenario × probability weight, (c) memo sentences on three pushbacks, (d) elevate Bull timing logic, (e) hold multiple at 6x flat. | D10: Built scenario-weighted aggregation, sensitivity grid (Section 7), memo additions (Section 5b), and elevated Bull timing logic with explicit conditions. | E10: (1) Section 4 Scenario-weighted EV: B38 = =P_Bear*B31+P_Base*C31+P_Bull*D31 = $1,286M ($1.29B vs Base scenario $940M); C38 caveat explains two-layer probability is not double-counting (within-scenario P(materialize) at row 30 already weights by trigger probability; cross-scenario weights weight outcome distributions — they compound). (2) Section 7 Block A: per-scenario contribution decomposition Bear $33M/2.6%, Base $470M/36.6%, Bull $783M/60.9% (Bull dominates despite only 30% weight — reflects $2.6B Bull intrinsic value). (3) Section 7 Block B: 5×5 P_Bear×P_Bull grid centered on D97=$1,286M; floor max-bear=$874M, ceiling max-bull=$1,697M, range=$823M. P_Bull lever=$167M per 10pp, P_Bear lever=$39M per 10pp — Bull weight is dominant lever. Read narrative at A109 with live TEXT formulas reading B38, D97, B96/F98 floor/ceiling, B98/F96 corner cases. (4) Section 5b Pushback responses (rows 80-90): consumer-only Bull (clean separation — DCF runs consumer assumptions, option valued discretely, scenario-weighted EV adds them), implicit option premium ($220-440M estimated comps premium; recommend reading explicit option as standalone module — reader can subtract premium if they believe it's already priced; or keep $700-1,000M proves-in floor), ARPU defense ($338/yr blended consumer+B2B is intact regardless of medical materialization — only incremental medical-bill ARPU is at risk; Bear $164M residual = 15% prob × $1.07B intrinsic still positive). (5) Bull timing elevated (row 68 yellow callout): 4yr requires three conditions ALL to break right (CMS Innovation Center accelerates 7-10yr review, CPT code filing within 18 months, Abbott/Mayo co-published study by Y2). Probability of all three = 25% = P_Bull. 1 extra year = ~11% PV drag (multiplicative discount). (6) Multiple held at 6x flat per user direction. (7) Style: scenario-weighted line uses #E2EFDA mint. Block A and B narratives at A109 fully live. | F10: RealOptions tab now Series A: Section 4 dual reads (active scenario $940M Base + scenario-weighted $1,286M cross-scenario), Section 7 sensitivity grid live, Section 5b pushback responses memo-quality. Tie-outs: B38=$1,286M, D97=$1,286M, F98=$1,697M ceiling, B96=$874M floor. Awaiting next direction.

Sheet Cover
B3: WHOOP Inc.
B4: Private Company Valuation
B5: Investment Committee Memo — Supporting Model
B8: Company: | C8: WHOOP Inc.
B9: Ticker: | C9: Private (Pre-IPO)
B10: Last Round: | C10: Series G — $575M at $10.1B post-money (Mar 31, 2026)
B11: Model Date: | C11: April 16, 2026
B12: Analyst: | C12: Landon Brice
B13: Fiscal Year: | C13: Calendar Year (Jan-Dec)
B14: Currency: | C14: USD ($M unless noted)
B17: Valuation Methods:
B18: 1. Intrinsic DCF (scenario-based + real options)
B19: 2. Trading Comps (three-bucket framework)
B20: 3. Precedent Transactions
B21: 4. Last-Round Implied ($10.1B)
B22: 5. Implied IPO Trading Range (back-solved)
B25: Color Convention:
B26: Hard-coded input
B27: Formula / calculation
B28: Cross-sheet link
B29: Needs verification / FLAGGED_GAP
B32: Source Files:
B33: Valuation Summary (live, scenario-driven)
B34: Active Scenario | C34: =Assumptions!$B$3 -> Base
B36: Base DCF — Enterprise Value | C36: =DCF!C32 -> 6601.9352
B37: + Cash | C37: =DCF!C37 -> 728.61763
B38: − Debt | C38: =DCF!C36 -> -10
B39: = Equity Value | C39: =DCF!C38 -> 7320.5528
B40: Per Share (FD) | C40: =DCF!C40 -> 17.855007
B42: Real Options (Expected) | C42: n/a
B43: Total Equity + Options | C43: n/a
B45: Series G Mark | C45: =DCF!C52 -> 10100
B46: Base DCF vs Series G | C46: =DCF!C53 -> -0.27519279
B47: DCF + Options vs Series G | C47: =DCF!C54 -> n/a
B48: Football Field (multi-method synthesis)
B49: Weighted Average EV | C49: ='Football Field'!D18*1000 -> 9086.8229
B50: Per Share (FD) | C50: ='Football Field'!G18 -> 23.845909
B51: vs Series G | C51: ='Football Field'!D20 -> -0.10031457
B53: Model Integrity (Checks tab)
B54: Passing | C54: =Checks!B19 -> 11
...

Sheet Memo
A1: WHOOP — Memo Visuals Tab
A2: Memo-ready visual deliverables. Live formulas — update as model refreshes. Section 1 = headline scenario table. Section 2 = DCF waterfall bridge. Section 3 = tornado (Base + ProbWeighted). Section 4 = Football Field. Section 5 = 2D sensitivity heatmap. Section 6 = Jensen triangulation.
A4: ="Headline: ProbWeighted Equity = $"&TEXT(DCF!C63,"#,##0")&"M | Series G mark = $"&TEXT(DCF!C52,"#,##0")&"M | Implied premium / (discount) = "&TEXT(DCF!C63/DCF!C52-1,"+0.0%;-0.0%") -> Headline: ProbWeighted Equity = $8,186M | Series G mark = $10,100M | Implied premium / (discount) = -19.0%
A6: 1. Scenario Output Table
A7: Live read from DCF triangulation. Color-banded by scenario. ProbWeighted highlighted as headline.
A9: Metric | B9: Bear | C9: Base | D9: Bull | E9: ProbWeighted
A10: Probability weight | B10: =Assumptions!C2 -> 0.2 | C10: =Assumptions!E2 -> 0.5 | D10: =Assumptions!G2 -> 0.3 | E10: =B10+C10+D10 -> 1
A11: DCF Equity ($M) | B11: =DCF!C60 -> 2496.75 | C11: =DCF!C61 -> 7320.55 | D11: =DCF!C62 -> 24657.67 | E11: =DCF!C63 -> 8185.67
A12: Equity + Real Options ($M) | B12: n/a | C12: n/a | D12: n/a | E12: n/a
A13: Implied $/share | B13: =B11/Assumptions!F54 -> 6.0896341 | C13: =C11/Assumptions!F54 -> 17.855 | D13: =D11/Assumptions!F54 -> 60.140659 | E13: =E11/Assumptions!F54 -> 19.965049
A14: vs Series G ($10.1B mark) | B14: =B11/DCF!$C$52-1 -> -0.75279703 | C14: =C11/DCF!$C$52-1 -> -0.27519307 | D14: =D11/DCF!$C$52-1 -> 1.4413535 | E14: =E11/DCF!$C$52-1 -> -0.18953762
A15: WACC % | B15: =Assumptions!C74 -> 0.12175651 | C15: =Assumptions!D74 -> 0.11587449 | D15: =Assumptions!E74 -> 0.11003837 | E15: =Assumptions!J74 -> 0.11530006
A18: 2. DCF Waterfall Bridge — How EV Becomes Equity
A19: Live from DCF Base scenario. Toggle B3 on Assumptions to see waterfall flex by scenario.
A21: Step | B21: Value ($M) | C21: Running Total ($M) | D21: Type | E21: Step | F21: Invisible base | G21: Build/Add | H21: Subtract | I21: Total
A22: PV of FCFs (2026-2033) | B22: =DCF!C30 -> 1769.3286 | C22: =B22 -> 1769.3286 | D22: Build | E22: =A22 -> PV of FCFs (2026-2033) | F22: =0 -> 0 | G22: =B22 -> 1769.3286 | H22: =0 -> 0 | I22: =0 -> 0
A23: PV of Terminal Value | B23: =DCF!C31 -> 4832.6066 | C23: =C22+B23 -> 6601.9352 | D23: Build | E23: =A23 -> PV of Terminal Value | F23: =C22 -> 1769.3286 | G23: =B23 -> 4832.6066 | H23: =0 -> 0 | I23: =0 -> 0
A24: Enterprise Value | B24: =DCF!C32 -> 6601.9352 | C24: =C23 -> 6601.9352 | D24: Total | E24: =A24 -> Enterprise Value | F24: =0 -> 0 | G24: =0 -> 0 | H24: =0 -> 0 | I24: =C24 -> 6601.9352
A25: Less: Debt | B25: =DCF!C36 -> -10 | C25: =C24+B25 -> 6591.9352 | D25: Subtract | E25: =A25 -> Less: Debt | F25: =C25 -> 6591.9352 | G25: =0 -> 0 | H25: =-B25 -> 10 | I25: =0 -> 0
A26: Plus: Cash | B26: =DCF!C37 -> 728.61763 | C26: =C25+B26 -> 7320.5528 | D26: Add | E26: =A26 -> Plus: Cash | F26: =C25 -> 6591.9352 | G26: =B26 -> 728.61763 | H26: =0 -> 0 | I26: =0 -> 0
A27: Equity Value (DCF Base) | B27: =DCF!C38 -> 7320.5528 | C27: =C26 -> 7320.5528 | D27: Total | E27: =A27 -> Equity Value (DCF Base) | F27: =0 -> 0 | G27: =0 -> 0 | H27: =0 -> 0 | I27: =C27 -> 7320.5528
A28: Plus: Real Options (Active) | B28: =DCF!C45 -> 940.08677 | C28: =C27+B28 -> 8260.6396 | D28: Add | E28: =A28 -> Plus: Real Options (Active) | F28: =C27 -> 7320.5528 | G28: =B28 -> 940.08677 | H28: =0 -> 0 | I28: =0 -> 0
A29: Equity + Real Options | B29: =C28 -> 8260.6396 | C29: =C28 -> 8260.6396 | D29: Total | E29: =A29 -> Equity + Real Options | F29: =0 -> 0 | G29: =0 -> 0 | H29: =0 -> 0 | I29: =C29 -> 8260.6396
A31: 3. Tornado — Driver Sensitivity (Base & ProbWeighted Baselines)
A32: Each driver flexed individually from baseline scenario to Bear/Bull values, holding all others at baseline. Drivers ranked by Bull-Bear equity spread. Static snapshot — refresh manually if model changes materially.
A34: Rank | B34: Driver | C34: Bear Equity ($M) | D34: Base Equity ($M) | E34: Bull Equity ($M) | F34: Bear Δ ($M) | G34: Bull Δ ($M) | I34: Rank | J34: Driver | K34: Bear Equity ($M) | L34: ProbWtd Equity ($M) | M34: Bull Equity ($M) | N34: Bear Δ ($M) | O34: Bull Δ ($M) | Q34: Driver | R34: Bear Δ | S34: Bull Δ | T34: Spread | V34: Driver | W34: Bear Δ | X34: Bull Δ | Y34: Spread
A35: 1 | B35: Member Growth (MG1-MG8) | C35: 4989 | D35: 7336 | E35: 8087 | F35: -2347 | G35: 751 | I35: 1 | J35: Member Growth (MG1-MG8) | K35: 5290 | L35: 8091 | M35: 8561 | N35: -2801 | O35: 470 | Q35: =B47 -> SBC IPO 2027 override | R35: =F47 -> -17 | S35: =G47 -> 17 | T35: =ABS(R36)+ABS(S36) -> 40 | V35: =J47 -> SBC IPO 2027 override | W35: =N47 -> -20 | X35: =O47 -> 15 | Y35: =ABS(W36)+ABS(X36) -> 41
A36: 2 | B36: Terminal EV/Rev Multiple | C36: 6931 | D36: 7336 | E36: 8147 | F36: -405 | G36: 811 | I36: 2 | J36: Terminal EV/Rev Multiple | K36: 7495 | L36: 8091 | M36: 8771 | N36: -596 | O36: 680 | Q36: =B46 -> SBC IPO 2028 override | R36: =F46 -> -20 | S36: =G46 -> 20 | T36: =ABS(R37)+ABS(S37) -> 144 | V36: =J46 -> SBC IPO 2028 override | W36: =N46 -> -23 | X36: =O46 -> 18 | Y36: =ABS(W37)+ABS(X37) -> 148
A37: 3 | B37: Bottoms-Up WACC | C37: 7729 | D37: 7336 | E37: 6980 | F37: 393 | G37: -356 | I37: 3 | J37: Bottoms-Up WACC | K37: 8483 | L37: 8091 | M37: 7657 | N37: 392 | O37: -434 | Q37: =B45 -> SBC % Rev (current) | R37: =F45 -> -72 | S37: =G45 -> 72 | T37: =ABS(R38)+ABS(S38) -> 150 | V37: =J45 -> SBC % Rev (current) | W37: =N45 -> -82 | X37: =O45 -> 66 | Y37: =ABS(W38)+ABS(X38) -> 177
A38: 4 | B38: R&D % Rev (terminal) | C38: 7701 | D38: 7336 | E38: 6971 | F38: 365 | G38: -365 | I38: 4 | J38: R&D % Rev (terminal) | K38: 8514 | L38: 8091 | M38: 7744 | N38: 423 | O38: -347 | Q38: =B44 -> Tax Rate | R38: =F44 -> -75 | S38: =G44 -> 75 | T38: =ABS(R39)+ABS(S39) -> 386 | V38: =J44 -> Tax Rate | W38: =N44 -> -98 | X38: =O44 -> 79 | Y38: =ABS(W39)+ABS(X39) -> 404
A39: 5 | B39: SBC % Rev (terminal) | C39: 7101 | D39: 7336 | E39: 7689 | F39: -235 | G39: 353 | I39: 5 | J39: SBC % Rev (terminal) | K39: 7780 | L39: 8091 | M39: 8401 | N39: -311 | O39: 310 | Q39: =B43 -> Y3+ Cohort Churn | R39: =F43 -> 0 | S39: =G43 -> 386 | T39: =ABS(R40)+ABS(S40) -> 436 | V39: =J43 -> Y3+ Cohort Churn | W39: =N43 -> -113 | X39: =O43 -> 291 | Y39: =ABS(W40)+ABS(X40) -> 456
A40: 6 | B40: G&A % Rev (terminal) | C40: 7093 | D40: 7336 | E40: 7579 | F40: -243 | G40: 243 | I40: 6 | J40: G&A % Rev (terminal) | K40: 7808 | L40: 8091 | M40: 8322 | N40: -283 | O40: 231 | Q40: =B42 -> CapEx % Rev | R40: =F42 -> -218 | S40: =G42 -> 218 | T40: =ABS(R41)+ABS(S41) -> 478 | V40: =J42 -> CapEx % Rev | W40: =N42 -> -251 | X40: =O42 -> 205 | Y40: =ABS(W41)+ABS(X41) -> 505
A41: 7 | B41: Terminal COGS % (C7d_end) | C41: 7097 | D41: 7336 | E41: 7575 | F41: -239 | G41: 239 | I41: 7 | J41: Terminal COGS % (C7d_end) | K41: 7813 | L41: 8091 | M41: 8318 | N41: -278 | O41: 227 | Q41: =B41 -> Terminal COGS % (C7d_end) | R41: =F41 -> -239 | S41: =G41 -> 239 | T41: =ABS(R42)+ABS(S42) -> 486 | V41: =J41 -> Terminal COGS % (C7d_end) | W41: =N41 -> -278 | X41: =O41 -> 227 | Y41: =ABS(W42)+ABS(X42) -> 514
A42: 8 | B42: CapEx % Rev | C42: 7118 | D42: 7336 | E42: 7554 | F42: -218 | G42: 218 | I42: 8 | J42: CapEx % Rev | K42: 7840 | L42: 8091 | M42: 8296 | N42: -251 | O42: 205 | Q42: =B40 -> G&A % Rev (terminal) | R42: =F40 -> -243 | S42: =G40 -> 243 | T42: =ABS(R43)+ABS(S43) -> 588 | V42: =J40 -> G&A % Rev (terminal) | W42: =N40 -> -283 | X42: =O40 -> 231 | Y42: =ABS(W43)+ABS(X43) -> 621
A43: 9 | B43: Y3+ Cohort Churn | C43: 7336 | D43: 7336 | E43: 7722 | F43: 0 | G43: 386 | I43: 9 | J43: Y3+ Cohort Churn | K43: 7978 | L43: 8091 | M43: 8382 | N43: -113 | O43: 291 | Q43: =B39 -> SBC % Rev (terminal) | R43: =F39 -> -235 | S43: =G39 -> 353 | T43: =ABS(R44)+ABS(S44) -> 730 | V43: =J39 -> SBC % Rev (terminal) | W43: =N39 -> -311 | X43: =O39 -> 310 | Y43: =ABS(W44)+ABS(X44) -> 770
A44: 10 | B44: Tax Rate | C44: 7261 | D44: 7336 | E44: 7411 | F44: -75 | G44: 75 | I44: 10 | J44: Tax Rate | K44: 7993 | L44: 8091 | M44: 8170 | N44: -98 | O44: 79 | Q44: =B38 -> R&D % Rev (terminal) | R44: =F38 -> 365 | S44: =G38 -> -365 | T44: =ABS(R45)+ABS(S45) -> 749 | V44: =J38 -> R&D % Rev (terminal) | W44: =N38 -> 423 | X44: =O38 -> -347 | Y44: =ABS(W45)+ABS(X45) -> 826
A45: 11 | B45: SBC % Rev (current) | C45: 7264 | D45: 7336 | E45: 7408 | F45: -72 | G45: 72 | I45: 11 | J45: SBC % Rev (current) | K45: 8009 | L45: 8091 | M45: 8157 | N45: -82 | O45: 66 | Q45: =B37 -> Bottoms-Up WACC | R45: =F37 -> 393 | S45: =G37 -> -356 | T45: =ABS(R46)+ABS(S46) -> 1216 | V45: =J37 -> Bottoms-Up WACC | W45: =N37 -> 392 | X45: =O37 -> -434 | Y45: =ABS(W46)+ABS(X46) -> 1276
A46: 12 | B46: SBC IPO 2028 override | C46: 7316 | D46: 7336 | E46: 7356 | F46: -20 | G46: 20 | I46: 12 | J46: SBC IPO 2028 override | K46: 8068 | L46: 8091 | M46: 8109 | N46: -23 | O46: 18 | Q46: =B36 -> Terminal EV/Rev Multiple | R46: =F36 -> -405 | S46: =G36 -> 811 | T46: =ABS(R47)+ABS(S47) -> 0 | V46: =J36 -> Terminal EV/Rev Multiple | W46: =N36 -> -596 | X46: =O36 -> 680 | Y46: =ABS(W47)+ABS(X47) -> 0
A47: 13 | B47: SBC IPO 2027 override | C47: 7319 | D47: 7336 | E47: 7353 | F47: -17 | G47: 17 | I47: 13 | J47: SBC IPO 2027 override | K47: 8071 | L47: 8091 | M47: 8106 | N47: -20 | O47: 15
A51: 4. Football Field — Multi-Method Valuation Synthesis
...

Sheet Assumptions
A1: WHOOP — Master Assumptions
A2: Probability Weights (ProbWeighted scenario): | B2: P_Bear | C2: 0.2 | D2: P_Base | E2: 0.5 | F2: P_Bull | G2: 0.3 | H2: Sum check: | I2: =C2+E2+G2 -> 1
A3: Scenario: | B3: Base | C3: Select Bear / Base / Bull / ProbWeighted — drives Active column F throughout the model. ProbWeighted = P_Bear×Bear + P_Base×Base + P_Bull×Bull on 16 high-leverage inputs (see row 2 weights, Section 13 doc at row 181).
A5: ID | B5: Assumption | C5: Bear | D5: Base | E5: Bull | F5: Active | G5: Tier | H5: Status | I5: Notes | J5: ProbWeighted
A7: Section 1: Revenue & Growth
A8: R3a | B8: 2025 Beginning Members (M) | C8: 1.5 | D8: 1.3 | E8: 1.1 | F8: =IF($B$3="Bear",C8,IF($B$3="Bull",E8,D8)) -> 1.3 | G8: Tier 3 | H8: High | I8: Back-solved to reconcile avg×ARPU ≈ $650M base. Bear slower decel; bull faster acquisition.
A9: R3b | B9: 2025 Ending Members (M) | C9: 2.3 | D9: 2.5 | E9: 2.7 | F9: =IF($B$3="Bear",C9,IF($B$3="Bull",E9,D9)) -> 2.5 | G9: Tier 1 | H9: Critical | I9: Series G press release: 2.5M+ paying members
A10: R3 | B10: 2025 Average Members (M) — DERIVED | C10: =(C8+C9)/2 -> 1.9 | D10: =(D8+D9)/2 -> 1.9 | E10: =(E8+E9)/2 -> 1.9 | F10: =IF($B$3="Bear",C10,IF($B$3="Bull",E10,D10)) -> 1.9 | G10: Derived | H10: Critical | I10: Per methodology: ARPU applies to AVERAGE members during period, NOT year-end.
A11: R4 | B11: 2025 Blended ARPU ($/yr) | C11: 270 | D11: =ARPU!D10 -> 274 | E11: 340 | F11: =IF($B$3="Bear",C11,IF($B$3="Bull",E11,D11)) -> 274 | G11: Tier 3 | H11: Critical | I11: Base linked to ARPU!D10 = $274 (year-specific bottoms-up: consumer 80% × $278 + Unite 20% × $260). 2026 steps to $307 (mature build w/ Labs + BP at 5% attach). Bear/Bull still hardcoded $ overrides — TODO: rebuild from tier-mix scenarios. See ARPU tab.
A12: R1 | B12: 2025 Recognized Revenue ($M) — DERIVED | C12: =C10*C11 -> 513 | D12: =D10*D11 -> 520.6 | E12: =E10*E11 -> 646 | F12: =IF($B$3="Bear",C12,IF($B$3="Bull",E12,D12)) -> 520.6 | G12: Derived | H12: Critical | I12: DERIVED: Avg Members × Blended ARPU. 2025 reconciles to $1.1B Series G run-rate as Dec exit-rate annualized, NOT full-year recognized. Gap = ramp through year (free-hardware pivot 9/2025). Memo material.
A13: R2 | B13: 2025 Bookings Run-Rate ($M) | C13: 1100 | D13: 1100 | E13: 1100 | F13: =IF($B$3="Bear",C13,IF($B$3="Bull",E13,D13)) -> 1100 | G13: Tier 1 | H13: Locked | I13: Series G press release; CEO statement (Dec 2025 exit-rate × 12). NOT full-year recognized — see I12 reconciliation note.
A14: R5 | B14: Subscription Revenue % | C14: 0.8 | D14: 0.85 | E14: 0.88 | F14: =IF($B$3="Bear",C14,IF($B$3="Bull",E14,D14)) -> 0.85 | G14: Tier 2 | H14: High | I14: Sacra/BMCT: ~80-88% range
A15: R6 | B15: 2025 YoY Subscription Growth | C15: 1.03 | D15: 1.03 | E15: 1.03 | F15: =IF($B$3="Bear",C15,IF($B$3="Bull",E15,D15)) -> 1.03 | G15: Tier 1 | H15: Locked | I15: Series G press release: 103%
A16: R7 | B16: Phase 1 Revenue Growth (2026-27) | C16: 0.5 | D16: 0.7 | E16: 0.9 | F16: =IF($B$3="Bear",C16,IF($B$3="Bull",E16,D16)) -> 0.7 | G16: Tier 3 | H16: Critical | I16: Peer trajectories; Series G deployment & WHOOP 5.0 cycle
A17: R8 | B17: Phase 2 Revenue Growth (2028-30) | C17: 0.15 | D17: 0.25 | E17: 0.4 | F17: =IF($B$3="Bear",C17,IF($B$3="Bull",E17,D17)) -> 0.25 | G17: Tier 3 | H17: Critical | I17: Deceleration shape: Dexcom (bull) / Netflix (base) / Peloton (bear)
A18: R9 | B18: Phase 3 Revenue Growth (2031-33) | C18: 0.05 | D18: 0.12 | E18: 0.2 | F18: =IF($B$3="Bear",C18,IF($B$3="Bull",E18,D18)) -> 0.12 | G18: Tier 3 | H18: High | I18: TAM ceiling; healthcare attach resolution
A19: R10a | B19: Year-1 Cohort Annual Churn | C19: 0.3 | D19: 0.22 | E19: 0.15 | F19: =IF($B$3="Bear",C19,IF($B$3="Bull",E19,D19)) -> 0.22 | G19: Tier 3 | H19: Critical | I19: Highest churn ("try and quit"). Will drive Members tab cohort engine.
A20: R10b | B20: Year-2 Cohort Annual Churn | C20: 0.18 | D20: 0.15 | E20: 0.1 | F20: =IF($B$3="Bear",C20,IF($B$3="Bull",E20,D20)) -> 0.15 | G20: Tier 3 | H20: Critical | I20: Stabilizing cohort
A21: R10c | B21: Year-3+ Cohort Annual Churn | C21: 0.12 | D21: 0.12 | E21: 0.05 | F21: =IF($B$3="Bear",C21,IF($B$3="Bull",E21,IF($B$3="ProbWeighted",J21,D21))) -> 0.12 | G21: Tier 3 | H21: Critical | I21: Retained core; very sticky power users | J21: =$C$2*C21+$E$2*D21+$G$2*E21 -> 0.099
A22: R12 | B22: B2B Unite Revenue % | C22: 0.12 | D22: 0.18 | E22: 0.25 | F22: =IF($B$3="Bear",C22,IF($B$3="Bull",E22,D22)) -> 0.18 | G22: Tier 2 | H22: Medium | I22: Sacra/BMCT: ~20% recurring revenue; growing rapidly
A23: R14 | B23: Advanced Labs Attach Rate | C23: 0.03 | D23: 0.1 | E23: 0.25 | F23: =IF($B$3="Bear",C23,IF($B$3="Bull",E23,D23)) -> 0.1 | G23: Tier 3 | H23: Critical | I23: BUCKET-3 THESIS VARIABLE. Bear/Base/Bull per methodology Sec 3. Single most important ARPU assumption — swings $80/member.
A24: R15 | B24: Labs Avg Test Price ($) | C24: 250 | D24: 300 | E24: 350 | F24: =IF($B$3="Bear",C24,IF($B$3="Bull",E24,D24)) -> 300 | G24: Tier 3 | H24: High | I24: WHOOP Advanced Labs site: $199-$599. Methodology base: $300.
A25: R16 | B25: Annual Price Inflation | C25: 0.02 | D25: 0.03 | E25: 0.04 | F25: =IF($B$3="Bear",C25,IF($B$3="Bull",E25,D25)) -> 0.03 | G25: Tier 3 | H25: Medium | I25: CPI + premium brand pricing power
A26: R18 | B26: 2026 Gross Adds (M) | C26: 1.5 | D26: 1.9 | E26: 2.3 | F26: =IF($B$3="Bear",C26,IF($B$3="Bull",E26,D26)) -> 1.9 | G26: Tier 3 | H26: Critical | I26: Methodology priors: 1.8-2.0M base. Members tab will use this; per-year gross adds modeled there. CAC × this = S&M consistency check.
A27: R19 | B27: Deferred Revenue Adjustment (% of bookings) | C27: -0.1 | D27: -0.08 | E27: -0.05 | F27: =IF($B$3="Bear",C27,IF($B$3="Bull",E27,D27)) -> -0.08 | G27: Tier 3 | H27: Medium | I27: Drag during growth (recognized < booked); ASC 606. Approaches 0 at steady state.
A29: Section 2: Cost Structure & Margins
A30: C1 | B30: Hardware BOM per Device ($) | C30: 100 | D30: 80 | E30: 60 | F30: =IF($B$3="Bear",C30,IF($B$3="Bull",E30,D30)) -> 80 | G30: Tier 3 | H30: Critical | I30: Est. $50-80 at scale; 2016 BOM was $250-300 per Contrary Research
A31: C2 | B31: Loaded Hardware Cost per Acquisition ($) | C31: 150 | D31: 120 | E31: 90 | F31: =IF($B$3="Bear",C31,IF($B$3="Bull",E31,D31)) -> 120 | G31: Tier 3 | H31: Critical | I31: C1 + assembly, ship, warranty, returns. Drives unit economics.
A32: C4 | B32: Subscription Delivery Cost (% of sub rev) | C32: 0.15 | D32: 0.1 | E32: 0.08 | F32: =IF($B$3="Bear",C32,IF($B$3="Bull",E32,D32)) -> 0.1 | G32: Tier 3 | H32: High | I32: Infra + support; AWS/GCP benchmarks; declining at scale
A33: C5 | B33: Subscription Gross Margin (standalone) | C33: 0.72 | D33: 0.78 | E33: 0.83 | F33: =IF($B$3="Bear",C33,IF($B$3="Bull",E33,D33)) -> 0.78 | G33: Tier 3 | H33: Critical | I33: Peer: pure SaaS ~80%, Dexcom ~64% (incl consumables). WHOOP higher quality recurring.
A34: C6 | B34: Hardware Gross Margin (standalone) | C34: -0.1 | D34: -0.02 | E34: 0.05 | F34: =IF($B$3="Bear",C34,IF($B$3="Bull",E34,D34)) -> -0.02 | G34: Tier 3 | H34: Critical | I34: Subsidized at acquisition; Peloton HW GM trajectory: -18% to +14%
A35: C7a | B35: Blended GM Phase 1 (2026-27) | C35: 0.56 | D35: 0.6 | E35: 0.64 | F35: =IF($B$3="Bear",C35,IF($B$3="Bull",E35,D35)) -> 0.6 | G35: Tier 3 | H35: High | I35: Phase 1 blended GM (legacy decomposed framework, pre-collapse to C7d). No longer drives the model post-ARPU simplification — retained for reference only.
A36: C7b | B36: Blended GM Phase 2 (2028-30) | C36: 0.63 | D36: 0.67 | E36: 0.72 | F36: =IF($B$3="Bear",C36,IF($B$3="Bull",E36,D36)) -> 0.67 | G36: Tier 3 | H36: High | I36: Margin expansion as growth decelerates
A37: C7c | B37: Blended GM Terminal | C37: 0.72 | D37: 0.76 | E37: 0.8 | F37: =IF($B$3="Bear",C37,IF($B$3="Bull",E37,D37)) -> 0.76 | G37: Tier 3 | H37: High | I37: Peer terminal: Dexcom 60%, Spotify 32%; software-heavy mix at scale
A38: C8a | B38: R&D % of Revenue (current) | C38: 0.25 | D38: 0.22 | E38: 0.2 | F38: =IF($B$3="Bear",C38,IF($B$3="Bull",E38,D38)) -> 0.22 | G38: Tier 3 | H38: High | I38: Peers: Dexcom 13%, Garmin 16%, growth SaaS 20-30%
A39: C8b | B39: R&D % of Revenue (terminal) | C39: 0.13 | D39: 0.16 | E39: 0.19 | F39: =IF($B$3="Bear",C39,IF($B$3="Bull",E39,IF($B$3="ProbWeighted",J39,D39))) -> 0.16 | G39: Tier 3 | H39: Medium | I39: Peer steady-state | J39: =$C$2*C39+$E$2*D39+$G$2*E39 -> 0.163
A40: C9 | B40: S&M % of Revenue (current) | C40: 0.35 | D40: 0.3 | E40: 0.25 | F40: =IF($B$3="Bear",C40,IF($B$3="Bull",E40,D40)) -> 0.3 | G40: Tier 3 | H40: Critical | I40: Peloton peak 28.4% FY22, current 16.9% FY25. Bear = stuck high.
A41: C9a | B41: Paid CAC per Gross Add ($) | C41: 220 | D41: 175 | E41: 130 | F41: =IF($B$3="Bear",C41,IF($B$3="Bull",E41,D41)) -> 175 | G41: Tier 3 | H41: Critical | I41: 30-50% of first-year ARPU. S&M consistency check on Checks tab.
A42: C9b | B42: Athlete/Brand Spend ($M/yr) | C42: 100 | D42: 60 | E42: 30 | F42: =IF($B$3="Bear",C42,IF($B$3="Bull",E42,D42)) -> 60 | G42: Tier 3 | H42: High | I42: Press, endorsement deals; non-paid S&M floor
A43: C9t | B43: x | C43: 0.2 | D43: 0.17 | E43: 0.15 | F43: =IF($B$3="Bear",C43,IF($B$3="Bull",E43,D43)) -> 0.17 | G43: Tier 3 | H43: High | I43: Peer steady-state: Garmin SG&A 14-19%
...

Sheet Member Thesis
A1: WHOOP — Member Trajectory Triangulation (Four-Lens Framework)
A2: Four independent lenses converge on a 2033 ending member range. Each lens uses a different methodology; convergence is emergent, not curve-fit. Median feeds Trajectory Build (Oura-shape calibrated). Triangulation distance vs live model = audit check (±15% target).
A4: 1. Member Anchors
H5: Bull 18.0M decomposition
A6: 2025E starting members (M) | B6: 2.5
A7: ARPU ($/yr) | B7: =Assumptions!F11 -> 274 | H7: Channel | I7: 2033 Members | J7: Anchor
A8: Series G post-money valuation ($M) | B8: 1100 | H8: Consumer-only ceiling | I8: 12.0M | J8: Median of Apple Watch / Oura / Garmin lenses (consumer-organic)
A9: Series G implied $/share ($) | B9: 24.63 | H9: Clinical channel pull | I9: 4.5M | J9: RPM-eligible Medicare population (~30M) × ~15% WHOOP capture rate
A10: DCF base $/share (live model) | B10: =DCF!C40 -> 17.855007 | H10: Employer health plans | I10: 1.5M | J10: Corporate wellness scaling; Aetna pilot trajectory
H11: Total Bull | I11: 18.0M | J11: Reflects healthcare-driven TAM expansion
A12: 2. Convergence Summary
A13: Each lens uses an independent methodology. Convergence is emergent, not curve-fit. Median feeds Trajectory Build. ✓ = within ±15% of median; ⚠ = 15-25%; ✗ = >25%. | M13: Methodology
M14: TAM 25M × 6%/yr growth × 30% terminal share. Apple-style category-defining product precedent.
A15: Lens | B15: 2033 End (M) | C15: Δ vs Median | D15: Status | M15: Peloton Connected Fitness subs IPO+10 hypothetical × free-hardware advantage × ARPU drag.
A16: Lens A — TAM × Terminal Share | B16: =B30 -> 11.953861 | C16: =B16/$B$20-1 -> 0.094960645 | D16: =IF(ABS(C16)<=0.15,"✓",IF(ABS(C16)<=0.25,"⚠","✗")) -> ✓ | M16: Median of three independently-derived comp endpoints (Apple Watch shape / Oura forward-extrap / Garmin timeline-compressed).
A17: Lens B — Peloton Stage-Shifted Comp | B17: =B43 -> 11.20932 | C17: =B17/$B$20-1 -> 0.026761539 | D17: =IF(ABS(C17)<=0.15,"✓",IF(ABS(C17)<=0.25,"⚠","✗")) -> ✓ | M17: Cumulative S&M $ ÷ weighted CAC, less churn drag. Capital-bounded floor.
A18: Lens C — Apple/Oura/Garmin Triangulation | B18: =B67 -> 10.625 | C18: =B18/$B$20-1 -> -0.026761539 | D18: =IF(ABS(C18)<=0.15,"✓",IF(ABS(C18)<=0.25,"⚠","✗")) -> ✓ | M18: COV across the four lenses; flags whether triangulation is tight enough to feed Trajectory Build.
A19: Lens D — SAM/SOM Bottoms-Up | B19: =B78 -> 8.379 | C19: =B19/$B$20-1 -> -0.2324927 | D19: =IF(ABS(C19)<=0.15,"✓",IF(ABS(C19)<=0.25,"⚠","✗")) -> ⚠
A20: → Median across lenses | B20: =MEDIAN(B16:B19) -> 10.91716 | C20: =STDEV(B16:B19)/B20 -> 0.14115473 | D20: =IF(C20<0.1,"✓ tight",IF(C20<0.2,"⚠ wide","✗ diverge")) -> ⚠ wide
A22: 3. Lens A — TAM × Terminal Share
A23: Lens character — aggressive, assumption-heavy
A24: Premium continuous physiological monitoring at $200-400/yr WTP. Apple-at-30%-smartphone-share precedent supports 25-45% terminal share for category-defining product. Highest output of the four lenses — most upside-leaning by construction.
A26: Input | B26: Value | C26: Note | D26: Source
A27: TAM 2025 (M) | B27: 25 | C27: Premium continuous monitoring; ~130M US adults × $200-400/yr WTP filter ≈ 20-30M globally. | D27: mHealth Intelligence (2023). Oura+WHOOP combined ~4.5M paying 2025 = ~18% penetration of WTP filter.
A28: TAM growth rate (%/yr) | B28: 0.06 | C28: Conservative vs broader wearable CAGR 12-16%. | D28: MarketsandMarkets ($84.5B→$176.8B, 15.9% CAGR). Grand View Research ($92.9B→$230B by 2033, 12.1% CAGR).
A29: Terminal share 2033 (%) | B29: 0.3 | C29: Apple precedent: 30% global smartphone share. WHOOP at 25-30% in defined WTP TAM defensible. | D29: IDC: Oura already >80% smart ring share (2024). Apple smartphone share precedent for category-defining products.
A30: → Implied 2033 ending (M) | B30: =B27*((1+B28)^8)*B29 -> 11.953861 | C30: = TAM 2025 × (1 + growth)⁸ × terminal share | D30: TAM 2033 = 25 × 1.06⁸ ≈ 39.8M.
A32: 4. Lens B — Peloton Stage-Shifted Comp
A33: Lens character — base, structural analogue
A34: WHOOP at 2.5M pre-IPO ≈ Peloton at IPO+2 (~2.6M CF subs end-2020). WHOOP 2033 ≈ Peloton IPO+10 hypothetical extrapolation, adjusted for free-hardware advantage and ARPU drag. | M34: Source
M35: Peloton 10-K FY2019.
A36: Input | B36: Value | C36: Note | M36: Peloton 10-K FY2021.
A37: Peloton CF subs at IPO (Sep 2019) | B37: 0.563 | C37: 10-K FY2019 disclosed Connected Fitness Subscribers. | M37: Peloton 10-K FY2023.
A38: Peloton CF subs IPO+2 (FY2021) | B38: 2.49 | C38: Peak; aligns roughly with WHOOP 2025 anchor of 2.5M. | M38: Spec: extrapolated curve.
A39: Peloton CF peak (FY2023) | B39: 3.08 | C39: Peloton stalled ~3M post-COVID unwind — not a clean 8yr extrapolation, useful floor. | M39: Industry data on hardware-cost elasticity in subscription conversion.
A40: Stage-shifted base case 8yr ahead (M) | B40: 10.7 | C40: Hypothetical Peloton trajectory absent COVID unwind: 4x stage-2 base. Industry S-curve anchored. | M40: Peloton ARPU/churn comp; WHOOP retention disclosure.
A41: Free-hardware acquisition advantage (×) | B41: 1.08 | C41: WHOOP $0 hw vs Peloton $2k bike unlocks step-fn in trial-to-paid; +5-10% sustained gross adds. | M41: = 10.7 × 1.08 × 0.97 = 11.21M.
A42: Lower ARPU drag (marketing capacity, ×) | B42: 0.97 | C42: WHOOP $307 ARPU vs Peloton $500: less CAC headroom but offset by lower churn (12% vs 24%).
A43: → Implied 2033 ending (M) | B43: =B40*B41*B42 -> 11.20932 | C43: = stage-shifted base × free-hw advantage × ARPU drag
A45: 5. Lens C — Comps Triangulation
...

Sheet Members
A1: WHOOP — Member Cohort Engine
A2: Members in millions; cohort engine drives revenue. 2025 beginning treated as Y3+ legacy block (simplification — see note).
B5: Units | C5: 2024 | D5: 2025 | E5: 2026 | F5: 2027 | G5: 2028 | H5: 2029 | I5: 2030 | J5: 2031 | K5: 2032 | L5: 2033
C6: Historical | D6: Historical | E6: Phase 1 | F6: Phase 1 | G6: Phase 2 | H6: Phase 2 | I6: Phase 2 | J6: Phase 3 | K6: Phase 3 | L6: Phase 3
A8: 1. Beginning Members (start of year)
A9: Beginning Members (total) | B9: M | C9: 0.7 | D9: =Assumptions!$F$8 -> 1.3 | E9: =D34 -> 2.5 | F9: =E34 -> 3.7225 | G9: =F34 -> 5.10727 | H9: =G34 -> 6.4045166 | I9: =H34 -> 7.5957567 | J9: =I34 -> 8.6363753 | K9: =J34 -> 9.5691039 | L9: =K34 -> 10.315494
A10: of which: Year-1 cohort | B10: M | C10: 0.5 | D10: 0 | E10: =D31 -> 1.356 | F10: =E31 -> 1.6581 | G10: =F31 -> 2.0290104 | H10: =G31 -> 2.1518196 | I10: =H31 -> 2.2224429 | J10: =I31 -> 2.2247063 | K10: =J31 -> 2.2435694 | L10: =K31 -> 2.1710976
A11: of which: Year-2 cohort | B11: M | C11: 0.15 | D11: 0 | E11: =D26 -> 0 | F11: =E26 -> 1.05768 | G11: =F26 -> 1.293318 | H11: =G26 -> 1.5826281 | I11: =H26 -> 1.6784193 | J11: =I26 -> 1.7335054 | K11: =J26 -> 1.7352709 | L11: =K26 -> 1.7499841
A12: of which: Year-3+ cohort | B12: M | C12: 0.05 | D12: =Assumptions!$F$8 -> 1.3 | E12: =D28 -> 1.144 | F12: =E28 -> 1.00672 | G12: =F28 -> 1.7849416 | H12: =G28 -> 2.6700689 | I12: =H28 -> 3.6948945 | J12: =I28 -> 4.6781636 | K12: =J28 -> 5.5902636 | L12: =K28 -> 6.3944122
A14: 2. Churn Rates (cohort-aged, from Assumptions)
A15: Year-1 churn rate | B15: % | C15: =Assumptions!$F$19 -> 0.22 | D15: =Assumptions!$F$19 -> 0.22 | E15: =Assumptions!$F$19 -> 0.22 | F15: =Assumptions!$F$19 -> 0.22 | G15: =Assumptions!$F$19 -> 0.22 | H15: =Assumptions!$F$19 -> 0.22 | I15: =Assumptions!$F$19 -> 0.22 | J15: =Assumptions!$F$19 -> 0.22 | ... L15: =Assumptions!$F$19 -> 0.22
A16: Year-2 churn rate | B16: % | C16: =Assumptions!$F$20 -> 0.15 | D16: =Assumptions!$F$20 -> 0.15 | E16: =Assumptions!$F$20 -> 0.15 | F16: =Assumptions!$F$20 -> 0.15 | G16: =Assumptions!$F$20 -> 0.15 | H16: =Assumptions!$F$20 -> 0.15 | I16: =Assumptions!$F$20 -> 0.15 | J16: =Assumptions!$F$20 -> 0.15 | ... L16: =Assumptions!$F$20 -> 0.15
A17: Year-3+ churn rate | B17: % | C17: =Assumptions!$F$21 -> 0.12 | D17: =Assumptions!$F$21 -> 0.12 | E17: =Assumptions!$F$21 -> 0.12 | F17: =Assumptions!$F$21 -> 0.12 | G17: =Assumptions!$F$21 -> 0.12 | H17: =Assumptions!$F$21 -> 0.12 | I17: =Assumptions!$F$21 -> 0.12 | J17: =Assumptions!$F$21 -> 0.12 | ... L17: =Assumptions!$F$21 -> 0.12
A19: 3. Churned Members
A20: Y1 churned | B20: M | C20: =C10*C15 -> 0.11 | D20: =D10*D15 -> 0 | E20: =E10*E15 -> 0.29832 | F20: =F10*F15 -> 0.364782 | G20: =G10*G15 -> 0.44638229 | H20: =H10*H15 -> 0.4734003 | I20: =I10*I15 -> 0.48893743 | J20: =J10*J15 -> 0.48943539 | ... L20: =L10*L15 -> 0.47764148
A21: Y2 churned | B21: M | C21: =C11*C16 -> 0.0225 | D21: =D11*D16 -> 0 | E21: =E11*E16 -> 0 | F21: =F11*F16 -> 0.158652 | G21: =G11*G16 -> 0.1939977 | H21: =H11*H16 -> 0.23739422 | I21: =I11*I16 -> 0.25176289 | J21: =J11*J16 -> 0.26002582 | ... L21: =L11*L16 -> 0.26249762
A22: Y3+ churned | B22: M | C22: =C12*C17 -> 0.006 | D22: =D12*D17 -> 0.156 | E22: =E12*E17 -> 0.13728 | F22: =F12*F17 -> 0.1208064 | G22: =G12*G17 -> 0.21419299 | H22: =H12*H17 -> 0.32040827 | I22: =I12*I17 -> 0.44338734 | J22: =J12*J17 -> 0.56137963 | ... L22: =L12*L17 -> 0.76732947
A23: Total churned | B23: M | C23: =SUM(C20:C22) -> 0.1385 | D23: =SUM(D20:D22) -> 0.156 | E23: =SUM(E20:E22) -> 0.4356 | F23: =SUM(F20:F22) -> 0.6442404 | G23: =SUM(G20:G22) -> 0.85457298 | H23: =SUM(H20:H22) -> 1.0312028 | I23: =SUM(I20:I22) -> 1.1840877 | J23: =SUM(J20:J22) -> 1.3108408 | ... L23: =SUM(L20:L22) -> 1.5074686
A25: 4. Surviving Members (end of year, before new adds)
A26: Y1 survivors | B26: M | C26: =C10-C20 -> 0.39 | D26: =D10-D20 -> 0 | E26: =E10-E20 -> 1.05768 | F26: =F10-F20 -> 1.293318 | G26: =G10-G20 -> 1.5826281 | H26: =H10-H20 -> 1.6784193 | I26: =I10-I20 -> 1.7335054 | J26: =J10-J20 -> 1.7352709 | ... L26: =L10-L20 -> 1.6934562
A27: Y2 survivors | B27: M | C27: =C11-C21 -> 0.1275 | D27: =D11-D21 -> 0 | E27: =E11-E21 -> 0 | F27: =F11-F21 -> 0.899028 | G27: =G11-G21 -> 1.0993203 | H27: =H11-H21 -> 1.3452339 | I27: =I11-I21 -> 1.4266564 | J27: =J11-J21 -> 1.4734796 | ... L27: =L11-L21 -> 1.4874865
A28: Y3+ end state (incl. Y2 graduates) | B28: M | C28: =C12-C22+C27 -> 0.1715 | D28: =D12-D22+D27 -> 1.144 | E28: =E12-E22+E27 -> 1.00672 | F28: =F12-F22+F27 -> 1.7849416 | G28: =G12-G22+G27 -> 2.6700689 | H28: =H12-H22+H27 -> 3.6948945 | I28: =I12-I22+I27 -> 4.6781636 | J28: =J12-J22+J27 -> 5.5902636 | ... L28: =L12-L22+L27 -> 7.1145693
A30: 5. New Members (Gross Adds — DERIVED via membership identity)
A31: Gross Adds (= Δ Ending + Total Churned) | B31: M | C31: 0.6 | D31: =Assumptions!$F$9-D28 -> 1.356 | E31: =E34-E9+E23 -> 1.6581 | F31: =F34-F9+F23 -> 2.0290104 | G31: =G34-G9+G23 -> 2.1518196 | H31: =H34-H9+H23 -> 2.2224429 | I31: =I34-I9+I23 -> 2.2247063 | J31: =J34-J9+J23 -> 2.2435694 | K31: =K34-K9+K23 -> 2.1710976 | L31: =L34-L9+L23 -> 2.1160827
A33: 6. Ending & Average Members
A34: Ending Members | B34: M | C34: =C26+C28+C31 -> 1.1615 | D34: =D26+D28+D31 -> 2.5 | E34: =MIN(D34*(1+Assumptions!$F$167),0.45*Assumptions!$F$122) -> 3.7225 | F34: =MIN(E34*(1+Assumptions!$F$168),0.45*Assumptions!$F$122) -> 5.10727 | G34: =MIN(F34*(1+Assumptions!$F$169),0.45*Assumptions!$F$122) -> 6.4045166 | H34: =MIN(G34*(1+Assumptions!$F$170),0.45*Assumptions!$F$122) -> 7.5957567 | I34: =MIN(H34*(1+Assumptions!$F$171),0.45*Assumptions!$F$122) -> 8.6363753 | J34: =MIN(I34*(1+Assumptions!$F$172),0.45*Assumptions!$F$122) -> 9.5691039 | K34: =MIN(J34*(1+Assumptions!$F$173),0.45*Assumptions!$F$122) -> 10.315494 | L34: =MIN(K34*(1+Assumptions!$F$174),0.45*Assumptions!$F$122) -> 10.924108
A35: Average Members | B35: M | C35: =(C9+C34)/2 -> 0.93075 | D35: =(D9+D34)/2 -> 1.9 | E35: =(E9+E34)/2 -> 3.11125 | F35: =(F9+F34)/2 -> 4.414885 | G35: =(G9+G34)/2 -> 5.7558933 | H35: =(H9+H34)/2 -> 7.0001366 | I35: =(I9+I34)/2 -> 8.116066 | J35: =(J9+J34)/2 -> 9.1027396 | ... L35: =(L9+L34)/2 -> 10.619801
A37: 7. Diagnostics (output, not input)
A38: Net Adds (Gross - Churned) | B38: M | C38: =C31-C23 -> 0.4615 | D38: =D31-D23 -> 1.2 | E38: =E31-E23 -> 1.2225 | F38: =F31-F23 -> 1.38477 | G38: =G31-G23 -> 1.2972466 | H38: =H31-H23 -> 1.1912401 | I38: =I31-I23 -> 1.0406187 | J38: =J31-J23 -> 0.93272854 | ... L38: =L31-L23 -> 0.60861414
A39: Net Member Growth % | B39: % | D39: =D34/C34-1 -> 1.1523892 | E39: =E34/D34-1 -> 0.489 | F39: =F34/E34-1 -> 0.372 | G39: =G34/F34-1 -> 0.254 | H39: =H34/G34-1 -> 0.186 | I39: =I34/H34-1 -> 0.137 | J39: =J34/I34-1 -> 0.108 | K39: =K34/J34-1 -> 0.078 | L39: =L34/K34-1 -> 0.059
A40: Blended Annual Churn Rate (output) | B40: % | C40: =IFERROR(C23/C9,0) -> 0.19785714 | D40: =IFERROR(D23/D9,0) -> 0.12 | E40: =IFERROR(E23/E9,0) -> 0.17424 | F40: =IFERROR(F23/F9,0) -> 0.1730666 | G40: =IFERROR(G23/G9,0) -> 0.16732481 | H40: =IFERROR(H23/H9,0) -> 0.16101181 | I40: =IFERROR(I23/I9,0) -> 0.15588805 | J40: =IFERROR(J23/J9,0) -> 0.15178136 | ... L40: =IFERROR(L23/L9,0) -> 0.14613634
A41: 2025 ending vs Assumptions R3b (consistency) | B41: % | D41: =D34/Assumptions!$F$9-1 -> 0
A44: 8. S&M Build (Variable + Brand decomposition; member-anchored)
A45: Framework: Total S&M = (Gross Adds × Variable CAC) + Brand $. P&L pulls Total. Brand split exposes true variable acquisition economics. | B45: # | C45: Hist | D45: Hist | E45: Adds→S&M | F45: Adds→S&M | G45: Rev→Adds | H45: Rev→Adds | I45: Rev→Adds | J45: Rev→Adds | K45: Rev→Adds | L45: Rev→Adds
A46: Total S&M $ (= Variable + Brand) [P&L feeder] | B46: $M | D46: 195 | E46: =E53+E54 -> 288.715 | F46: =F53+F54 -> 394.03074 | G46: =G53+G54 -> 463.04359 | H46: =H53+H54 -> 524.55937 | I46: =I53+I54 -> 575.33016 | J46: =J53+J54 -> 628.91598 | K46: =K53+K54 -> 666.90625 | L46: =L53+L54 -> 707.43056
A47: Variable CAC $ (paid acquisition only, excl. brand) | B47: $ | D47: 130 | E47: =Assumptions!$F$120 + (Assumptions!$F$121-Assumptions!$F$120)*(E$5-2026)/7 -> 150 | F47: =Assumptions!$F$120 + (Assumptions!$F$121-Assumptions!$F$120)*(F$5-2026)/7 -> 153.71429 | G47: =Assumptions!$F$120 + (Assumptions!$F$121-Assumptions!$F$120)*(G$5-2026)/7 -> 157.42857 | H47: =Assumptions!$F$120 + (Assumptions!$F$121-Assumptions!$F$120)*(H$5-2026)/7 -> 161.14286 | I47: =Assumptions!$F$120 + (Assumptions!$F$121-Assumptions!$F$120)*(I$5-2026)/7 -> 164.85714 | J47: =Assumptions!$F$120 + (Assumptions!$F$121-Assumptions!$F$120)*(J$5-2026)/7 -> 168.57143 | K47: =Assumptions!$F$120 + (Assumptions!$F$121-Assumptions!$F$120)*(K$5-2026)/7 -> 172.28571 | L47: =Assumptions!$F$120 + (Assumptions!$F$121-Assumptions!$F$120)*(L$5-2026)/7 -> 176
A48: Memo: Total S&M ÷ CAC (legacy diagnostic) | B48: M | D48: =D46/D47 -> 1.5 | E48: =E46/E47 -> 1.9247667 | F48: =F46/F47 -> 2.563397 | G48: =G46/G47 -> 2.9412932 | H48: =H46/H47 -> 3.2552443 | I48: =I46/I47 -> 3.489871 | J48: =J46/J47 -> 3.7308575 | K48: =K46/K47 -> 3.8709318 | L48: =L46/L47 -> 4.0194918
A49: TAM Penetration % (diagnostic — flag if >40%) | B49: % | D49: n/a | E49: =D34/Assumptions!$F$122 -> 0.1 | F49: =E34/Assumptions!$F$122 -> 0.1489 | G49: =F34/Assumptions!$F$122 -> 0.2042908 | H49: =G34/Assumptions!$F$122 -> 0.25618066 | I49: =H34/Assumptions!$F$122 -> 0.30383027 | J49: =I34/Assumptions!$F$122 -> 0.34545501 | K49: =J34/Assumptions!$F$122 -> 0.38276415 | L49: =K34/Assumptions!$F$122 -> 0.41261976
A50: Final Gross Adds (= row 31, derived) | B50: M | D50: =D48 -> 1.5 | E50: =E31 -> 1.6581 | F50: =F31 -> 2.0290104 | G50: =G31 -> 2.1518196 | H50: =H31 -> 2.2224429 | I50: =I31 -> 2.2247063 | J50: =J31 -> 2.2435694 | K50: =K31 -> 2.1710976 | L50: =L31 -> 2.1160827
A51: Implied S&M % of prior-yr revenue (diagnostic by phase) | B51: % | E51: =E46/'Revenue Build'!D20 -> 0.55458125 | F51: =F46/'Revenue Build'!E20 -> 0.44875305 | G51: =G46/'Revenue Build'!F20 -> 0.36080909 | H51: =H46/'Revenue Build'!G20 -> 0.3043825 | I51: =I46/'Revenue Build'!H20 -> 0.26650856 | J51: =J46/'Revenue Build'!I20 -> 0.24395536 | K51: =K46/'Revenue Build'!J20 -> 0.22393334 | L51: =L46/'Revenue Build'!K20 -> 0.21114746
...

Sheet ARPU
A1: ARPU — Single-Line Blended Driver (collapsed from 5-component build)
A2: Active driver: ARPU tab bottoms-up build. 2025 driver = D32 (year-specific implied: partial Labs, no BP). 2026 driver = D33 (mature build: full Labs + BP at 5% attach). 2027+ grows at R4g. Assumptions!F11 reads from D10. Consistency check at row 38 verifies Members × ARPU ≈ Methodology rev anchor.
A5: Year | B5: Unit | C5: 2024 | D5: 2025 | E5: 2026 | F5: 2027 | G5: 2028 | H5: 2029 | I5: 2030 | J5: 2031 | K5: 2032 | L5: 2033
A7: Blended ARPU (driver)
A8: 2025 Anchor (Assumptions R4) | B8: $/yr | D8: =D20 -> 274
A9: Annual growth rate (Assumptions R4g) | B9: % | D9: =Assumptions!$F$149 -> 0.03
A10: Blended ARPU | B10: $/yr | C10: 0 | D10: =D8 -> 274 | E10: =D10*(1+$D$9) -> 282.22 | F10: =E10*(1+$D$9) -> 290.6866 | G10: =F10*(1+$D$9) -> 299.4072 | H10: =G10*(1+$D$9) -> 308.38941 | I10: =H10*(1+$D$9) -> 317.6411 | J10: =I10*(1+$D$9) -> 327.17033 | K10: =J10*(1+$D$9) -> 336.98544 | L10: =K10*(1+$D$9) -> 347.095
A13: ARPU Justification
A14: Bottom-up reconciliation showing how blended ARPU reflects consumer + B2B mix. Numbers below are reference; active driver is Section 1 R4 above.
A16: Consumer per-member ARPU components:
A17: Subscription tier-weighted average | B17: $/yr | D17: =258 -> 258 | E17: Tier mix 30/45/25 × $199/$239/$359 = $257; +$1.68 monthly premium
A18: Labs ARPU now estimation | B18: $/yr | D18: 15
A19: Accessories ARPU | B19: $/yr | D19: 1
A20: Consumer ARPU (2025) | B20: $/yr | D20: =SUM(D17:D19) -> 274
A22: B2B Unite per-seat:
A23: Per-seat employer-rate ARPU | B23: $/yr | D23: 260 | E23: B2B health platforms with bundled hardware: $200-350; standalone software: $100-180. Estimate $260 mid-range.
A25: Mix assumption (% of paying members):
A26: Consumer share | B26: % | D26: 0.8 | E26: BMCT estimate: Unite ~20% of recurring revenue
A27: Unite share | B27: % | D27: 0.2
A28: Mix sum check | D28: =D26+D27 -> 1 | E28: Must = 100%
A30: Component | B30: Contribution | C30: Anchor / Justification
A31: Inflation baseline | B31: 0.03 | C31: CPI+ baseline; consistent with Base
A32: Tier-mix shift to Peak/Life | B32: 0.01 | C32: Healthcare-positioning brand effect drives consumer trade-up; Spotify Family/Premium analog
A33: Labs / BP-Healthspan attach growth | B33: 0.01 | C33: Premium feature monetization; clinical anchor justifies adoption (BP launched Jan 2026)
A34: B2B Unite share growth | B34: 0.003 | C34: Enterprise health platform scales from 20% → 30% of base; per-seat pricing 4-7x consumer
A35: Payer-paid revenue uplift | B35: 0.007 | C35: Direct healthcare reimbursement contribution; weighted across eligible-member share × payer ARPU lift
A36: Total Bull | B36: 0.06
A38: Consistency Check: Members × ARPU = Revenue
A39: 2025 Avg Members × Blended ARPU | B39: $M | D39: =Assumptions!D10*D20 -> 520.6
A45: Scenario ARPU Build — Asymmetric Growth Discipline
A46: Bear/Base anchored to inflation only; Bull lifts only because healthcare reimbursement materializes (ARPU = consequence of scenario, not independent dial).
A48: Scenario | B48: Growth | C48: 2025 ARPU | D48: 2033 ARPU | E48: $/Month '33 | F48: Δ vs CPI
A49: Bear | B49: =Assumptions!C149 -> 0.025 | C49: =ARPU!D8 -> 274 | D49: =C49*(1+B49)^8 -> 333.84239 | E49: =D49/12 -> 27.820199 | F49: =B49-3% -> -0.005
A50: Base | B50: =Assumptions!D149 -> 0.03 | C50: =ARPU!D8 -> 274 | D50: =C50*(1+B50)^8 -> 347.095 | E50: =D50/12 -> 28.924584 | F50: =B50-3% -> 0
A51: Bull | B51: =Assumptions!E149 -> 0.06 | C51: =ARPU!D8 -> 274 | D51: =C51*(1+B51)^8 -> 436.71437 | E51: =D51/12 -> 36.392864 | F51: =B51-3% -> 0.03
A54: Bull Decomposition — 6.0% = Sum of Five Anchored Mechanisms
A55: Bull ARPU growth is the CONSEQUENCE of healthcare reimbursement materialization, not an independent dial. Each component anchored to a commercial mechanism.
A57: Component | B57: Contribution | C57: Justification
A58: Inflation baseline | B58: =B31 -> 0.03 | C58: CPI+ baseline; consistent with Base case anchor
A59: Tier-mix shift to Peak / Life | B59: =B32 -> 0.01 | C59: Healthcare-positioning brand effect drives consumer trade-up (Spotify Family/Premium analog)
...

Sheet Revenue Build
A1: WHOOP — Revenue Build-Up
A2: $M unless noted; Calendar Year
B5: Units | C5: 2024 | D5: 2025 | E5: 2026 | F5: 2027 | G5: 2028 | H5: 2029 | I5: 2030 | J5: 2031 | K5: 2032 | L5: 2033
C6: Historical | D6: Historical | E6: Phase 1 | F6: Phase 1 | G6: Phase 2 | H6: Phase 2 | I6: Phase 2 | J6: Phase 3 | K6: Phase 3 | L6: Phase 3
A8: 1. Member Economics (linked from Members tab)
A9: Beginning Members | B9: M | C9: =Members!C9 -> 0.7 | D9: =Members!D9 -> 1.3 | E9: =Members!E9 -> 2.5 | F9: =Members!F9 -> 3.7225 | G9: =Members!G9 -> 5.10727 | H9: =Members!H9 -> 6.4045166 | I9: =Members!I9 -> 7.5957567 | J9: =Members!J9 -> 8.6363753 | ... L9: =Members!L9 -> 10.315494
A10: Gross Adds | B10: M | C10: =Members!C31 -> 0.6 | D10: =Members!D31 -> 1.356 | E10: =Members!E31 -> 1.6581 | F10: =Members!F31 -> 2.0290104 | G10: =Members!G31 -> 2.1518196 | H10: =Members!H31 -> 2.2224429 | I10: =Members!I31 -> 2.2247063 | J10: =Members!J31 -> 2.2435694 | ... L10: =Members!L31 -> 2.1160827
A11: Churned Members | B11: M | C11: =Members!C23 -> 0.1385 | D11: =Members!D23 -> 0.156 | E11: =Members!E23 -> 0.4356 | F11: =Members!F23 -> 0.6442404 | G11: =Members!G23 -> 0.85457298 | H11: =Members!H23 -> 1.0312028 | I11: =Members!I23 -> 1.1840877 | J11: =Members!J23 -> 1.3108408 | ... L11: =Members!L23 -> 1.5074686
A12: Ending Members | B12: M | C12: =Members!C34 -> 1.1615 | D12: =Members!D34 -> 2.5 | E12: =Members!E34 -> 3.7225 | F12: =Members!F34 -> 5.10727 | G12: =Members!G34 -> 6.4045166 | H12: =Members!H34 -> 7.5957567 | I12: =Members!I34 -> 8.6363753 | J12: =Members!J34 -> 9.5691039 | ... L12: =Members!L34 -> 10.924108
A13: Avg Members | B13: M | C13: =Members!C35 -> 0.93075 | D13: =Members!D35 -> 1.9 | E13: =Members!E35 -> 3.11125 | F13: =Members!F35 -> 4.414885 | G13: =Members!G35 -> 5.7558933 | H13: =Members!H35 -> 7.0001366 | I13: =Members!I35 -> 8.116066 | J13: =Members!J35 -> 9.1027396 | ... L13: =Members!L35 -> 10.619801
A14: Blended Annual Churn (output) | B14: % | C14: =IFERROR(Members!C23/Members!C9, 0) -> 0.19785714 | D14: =IFERROR(Members!D23/Members!D9, 0) -> 0.12 | E14: =IFERROR(Members!E23/Members!E9, 0) -> 0.17424 | F14: =IFERROR(Members!F23/Members!F9, 0) -> 0.1730666 | G14: =IFERROR(Members!G23/Members!G9, 0) -> 0.16732481 | H14: =IFERROR(Members!H23/Members!H9, 0) -> 0.16101181 | I14: =IFERROR(Members!I23/Members!I9, 0) -> 0.15588805 | J14: =IFERROR(Members!J23/Members!J9, 0) -> 0.15178136 | ... L14: =IFERROR(Members!L23/Members!L9, 0) -> 0.14613634
A16: 2. ARPU (linked from ARPU tab)
A17: Blended ARPU | B17: $/yr | C17: =ARPU!C10 -> 0 | D17: =ARPU!D10 -> 274 | E17: =ARPU!E10 -> 282.22 | F17: =ARPU!F10 -> 290.6866 | G17: =ARPU!G10 -> 299.4072 | H17: =ARPU!H10 -> 308.38941 | I17: =ARPU!I10 -> 317.6411 | J17: =ARPU!J10 -> 327.17033 | ... L17: =ARPU!L10 -> 347.095
A19: 3. Revenue Build
A20: Recognized Revenue (Total) | B20: $M | C20: =C13*C17 -> 0 | D20: =D13*D17 -> 520.6 | E20: =E13*E17 -> 878.05698 | F20: =F13*F17 -> 1283.3479 | G20: =G13*G17 -> 1723.3559 | H20: =H13*H17 -> 2158.768 | I20: =I13*I17 -> 2577.9961 | J20: =J13*J17 -> 2978.1463 | ... L20: =L13*L17 -> 3686.0799
A21: Memo: Δ Deferred Rev Balance (flows to NWC, not P&L) | B21: $M | C21: =C20*Assumptions!$F$27 -> 0 | D21: =D20*Assumptions!$F$27 -> -41.648 | E21: =E20*Assumptions!$F$27 -> -70.244558 | F21: =F20*Assumptions!$F$27 -> -102.66783 | G21: =G20*Assumptions!$F$27 -> -137.86847 | H21: =H20*Assumptions!$F$27 -> -172.70144 | I21: =I20*Assumptions!$F$27 -> -206.23969 | J21: =J20*Assumptions!$F$27 -> -238.2517 | ... L21: =L20*Assumptions!$F$27 -> -294.88639
A22: YoY Revenue Growth | B22: % | D22: =IFERROR(D20/C20-1,0) -> 0 | E22: =E20/D20-1 -> 0.686625 | F22: =F20/E20-1 -> 0.46157703 | G22: =G20/F20-1 -> 0.34285946 | H22: =H20/G20-1 -> 0.25265365 | I22: =I20/H20-1 -> 0.19419783 | J22: =J20/I20-1 -> 0.15521754 | K22: =K20/J20-1 -> 0.12499844 | L22: =L20/K20-1 -> 0.10018771
A24: 4. Bookings Reconciliation
A25: Implied Bookings (End × ARPU) | B25: $M | C25: =C12*C17 -> 0 | D25: =D12*D17 -> 685 | E25: =E12*E17 -> 1050.5639 | F25: =F12*F17 -> 1484.615 | G25: =G12*G17 -> 1917.5584 | H25: =H12*H17 -> 2342.4509 | I25: =I12*I17 -> 2743.2677 | J25: =J12*J17 -> 3130.7269 | ... L25: =L12*L17 -> 3791.7033
A26: Bookings/Revenue Ratio (memo: Ending × ARPU vs Avg × ARPU) | B26: x | C26: =IFERROR(C25/C20, 0) -> 0 | D26: =IFERROR(D25/D20, 0) -> 1.3157895 | E26: =IFERROR(E25/E20, 0) -> 1.1964644 | F26: =IFERROR(F25/F20, 0) -> 1.1568297 | G26: =IFERROR(G25/G20, 0) -> 1.1126886 | H26: =IFERROR(H25/H20, 0) -> 1.0850869 | I26: =IFERROR(I25/I20, 0) -> 1.0641086 | J26: =IFERROR(J25/J20, 0) -> 1.0512334 | ... L26: =IFERROR(L25/L20, 0) -> 1.0286547
A27: 2025 Recognized vs Assumptions F12 (consistency) | B27: % | D27: =D20/Assumptions!$F$12-1 -> 0

Sheet P&L
A1: WHOOP — Projected Income Statement
A2: $M; Calendar Year; Scenario per Assumptions toggle
A3: Calibration items: see notes on F31 (2027 dip), L23 (S&M architecture). Margin tapers and NOL wired; refer to CalibrationLog for status.
B5: Units | C5: 2024 | D5: 2025 | E5: 2026 | F5: 2027 | G5: 2028 | H5: 2029 | I5: 2030 | J5: 2031 | K5: 2032 | L5: 2033
A7: Revenue
A8: Total Revenue | B8: $M | C8: ='Revenue Build'!C20 -> 0 | D8: ='Revenue Build'!D20 -> 520.6 | E8: ='Revenue Build'!E20 -> 878.05698 | F8: ='Revenue Build'!F20 -> 1283.3479 | G8: ='Revenue Build'!G20 -> 1723.3559 | H8: ='Revenue Build'!H20 -> 2158.768 | I8: ='Revenue Build'!I20 -> 2577.9961 | J8: ='Revenue Build'!J20 -> 2978.1463 | ... L8: ='Revenue Build'!L20 -> 3686.0799 | M8: ← From Revenue Build tab
A9: YoY Growth | B9: % | D9: =IFERROR(D8/C8-1,0) -> 0 | E9: =E8/D8-1 -> 0.686625 | F9: =F8/E8-1 -> 0.46157703 | G9: =G8/F8-1 -> 0.34285946 | H9: =H8/G8-1 -> 0.25265365 | I9: =I8/H8-1 -> 0.19419783 | J9: =J8/I8-1 -> 0.15521754 | K9: =K8/J8-1 -> 0.12499844 | L9: =L8/K8-1 -> 0.10018771
A11: Cost of Revenue
